2024-08-01 19:17:18,289 - INFO - Adding job tentatively -- it will be properly scheduled when the scheduler starts
2024-08-01 19:17:18,289 - INFO - Added job "run_procedure_sequence" to job store "default"
2024-08-01 19:17:18,289 - INFO - Scheduler started
2024-08-01 19:17:20,542 - INFO - Adding job tentatively -- it will be properly scheduled when the scheduler starts
2024-08-01 19:17:20,542 - INFO - Added job "run_procedure_sequence" to job store "default"
2024-08-01 19:17:20,542 - INFO - Scheduler started
2024-08-01 19:17:20,561 - INFO - Watching for file changes with StatReloader
2024-08-01 19:17:39,457 - WARNING - Not Found: /ml_models/ml-report/images/favicon.ico
2024-08-01 19:25:47,027 - INFO - Adding job tentatively -- it will be properly scheduled when the scheduler starts
2024-08-01 19:25:47,028 - INFO - Added job "run_procedure_sequence" to job store "default"
2024-08-01 19:25:47,028 - INFO - Scheduler started
2024-08-01 19:25:49,478 - INFO - Adding job tentatively -- it will be properly scheduled when the scheduler starts
2024-08-01 19:25:49,478 - INFO - Added job "run_procedure_sequence" to job store "default"
2024-08-01 19:25:49,478 - INFO - Scheduler started
2024-08-01 19:25:49,498 - INFO - Watching for file changes with StatReloader
2024-08-01 19:25:59,055 - ERROR - Internal Server Error: /ml_models/ml-report/
Traceback (most recent call last):
  File "C:\Users\sunny\anaconda3\envs\myenv311test\Lib\site-packages\django\core\handlers\exception.py", line 56, in inner
    response = get_response(request)
               ^^^^^^^^^^^^^^^^^^^^^
  File "C:\Users\sunny\anaconda3\envs\myenv311test\Lib\site-packages\django\core\handlers\base.py", line 197, in _get_response
    response = wrapped_callback(request, *callback_args, **callback_kwargs)
               ^^^^^^^^^^^^^^^^^^^^^^^^^^^^^^^^^^^^^^^^^^^^^^^^^^^^^^^^^^^^
  File "C:\Users\sunny\Desktop\Development\python\TradePro\ml_models\views.py", line 465, in ml_report2
    pred_var_pos, pred_var_neg = variability_analysis(model_ticker, 0.1)
                                 ^^^^^^^^^^^^^^^^^^^^^^^^^^^^^^^^^^^^^^^
  File "C:\Users\sunny\Desktop\Development\python\TradePro\ml_models\utils\trade_model.py", line 473, in variability_analysis
    X_live_variability = dp.prediction_variability(sensitivity_adjustment)
                         ^^^^^^^^^^^^^^^^^^^^^^^^^^^^^^^^^^^^^^^^^^^^^^^^^
  File "C:\Users\sunny\Desktop\Development\python\TradePro\ml_models\utils\price_processing.py", line 694, in prediction_variability
    variability_df_pos = self.stats_df_gen(variability_df,2)
                         ^^^^^^^^^^^^^^^^^^^^^^^^^^^^^^^^^^^
  File "C:\Users\sunny\Desktop\Development\python\TradePro\ml_models\utils\price_processing.py", line 587, in stats_df_gen
    merged_df.to_csv(r"C:\Users\sunny\Desktop\Development\before_df-1.csv", index=False)
  File "C:\Users\sunny\anaconda3\envs\myenv311test\Lib\site-packages\pandas\core\generic.py", line 3466, in to_csv
    return DataFrameRenderer(formatter).to_csv(
           ^^^^^^^^^^^^^^^^^^^^^^^^^^^^^^^^^^^^
  File "C:\Users\sunny\anaconda3\envs\myenv311test\Lib\site-packages\pandas\io\formats\format.py", line 1105, in to_csv
    csv_formatter.save()
  File "C:\Users\sunny\anaconda3\envs\myenv311test\Lib\site-packages\pandas\io\formats\csvs.py", line 237, in save
    with get_handle(
         ^^^^^^^^^^^
  File "C:\Users\sunny\anaconda3\envs\myenv311test\Lib\site-packages\pandas\io\common.py", line 702, in get_handle
    handle = open(
             ^^^^^
PermissionError: [Errno 13] Permission denied: 'C:\\Users\\sunny\\Desktop\\Development\\before_df-1.csv'
2024-08-01 19:26:00,008 - INFO - Running job "run_procedure_sequence (trigger: interval[0:05:00], next run at: 2024-08-01 19:26:00 BST)" (scheduled at 2024-08-01 19:26:00+01:00)
2024-08-01 19:26:00,008 - INFO - Running job "run_procedure_sequence (trigger: interval[0:05:00], next run at: 2024-08-01 19:26:00 BST)" (scheduled at 2024-08-01 19:26:00+01:00)
2024-08-01 19:26:00,198 - INFO - The input start time: 2024-08-01 18:00:00
2024-08-01 19:26:00,198 - INFO - The input start time: 2024-08-01 18:00:00
2024-08-01 19:26:15,558 - ERROR - Job "run_procedure_sequence (trigger: interval[0:05:00], next run at: 2024-08-01 19:31:00 BST)" raised an exception
Traceback (most recent call last):
  File "C:\Users\sunny\anaconda3\envs\myenv311test\Lib\site-packages\apscheduler\executors\base.py", line 125, in run_job
    retval = job.func(*job.args, **job.kwargs)
             ^^^^^^^^^^^^^^^^^^^^^^^^^^^^^^^^^
  File "C:\Users\sunny\Desktop\Development\python\TradePro\prices\updater.py", line 74, in run_procedure_sequence
    comparison_comment, general_ticker_info, send_email_enabled = run_model_predictions(ticker)
                                                                  ^^^^^^^^^^^^^^^^^^^^^^^^^^^^^
  File "C:\Users\sunny\Desktop\Development\python\TradePro\ml_models\utils\trade_model.py", line 420, in run_model_predictions
    pred_reverse_1h_v5, pred_continue_1h_v5, pred_historical_1h_v5, _ = standard_analysis(model_ticker, "1h_v5")
                                                                        ^^^^^^^^^^^^^^^^^^^^^^^^^^^^^^^^^^^^^^^^
  File "C:\Users\sunny\Desktop\Development\python\TradePro\ml_models\utils\trade_model.py", line 214, in standard_analysis
    X_live_reverse = dp.scenario_reverse()
                     ^^^^^^^^^^^^^^^^^^^^^
  File "C:\Users\sunny\Desktop\Development\python\TradePro\ml_models\utils\price_processing.py", line 614, in scenario_reverse
    reverse_df_2pips = self.stats_df_gen(df, 2)
                       ^^^^^^^^^^^^^^^^^^^^^^^^
  File "C:\Users\sunny\Desktop\Development\python\TradePro\ml_models\utils\price_processing.py", line 587, in stats_df_gen
    merged_df.to_csv(r"C:\Users\sunny\Desktop\Development\before_df-1.csv", index=False)
  File "C:\Users\sunny\anaconda3\envs\myenv311test\Lib\site-packages\pandas\core\generic.py", line 3466, in to_csv
    return DataFrameRenderer(formatter).to_csv(
           ^^^^^^^^^^^^^^^^^^^^^^^^^^^^^^^^^^^^
  File "C:\Users\sunny\anaconda3\envs\myenv311test\Lib\site-packages\pandas\io\formats\format.py", line 1105, in to_csv
    csv_formatter.save()
  File "C:\Users\sunny\anaconda3\envs\myenv311test\Lib\site-packages\pandas\io\formats\csvs.py", line 237, in save
    with get_handle(
         ^^^^^^^^^^^
  File "C:\Users\sunny\anaconda3\envs\myenv311test\Lib\site-packages\pandas\io\common.py", line 702, in get_handle
    handle = open(
             ^^^^^
PermissionError: [Errno 13] Permission denied: 'C:\\Users\\sunny\\Desktop\\Development\\before_df-1.csv'
2024-08-01 19:26:15,864 - ERROR - Job "run_procedure_sequence (trigger: interval[0:05:00], next run at: 2024-08-01 19:31:00 BST)" raised an exception
Traceback (most recent call last):
  File "C:\Users\sunny\anaconda3\envs\myenv311test\Lib\site-packages\apscheduler\executors\base.py", line 125, in run_job
    retval = job.func(*job.args, **job.kwargs)
             ^^^^^^^^^^^^^^^^^^^^^^^^^^^^^^^^^
  File "C:\Users\sunny\Desktop\Development\python\TradePro\prices\updater.py", line 74, in run_procedure_sequence
    comparison_comment, general_ticker_info, send_email_enabled = run_model_predictions(ticker)
                                                                  ^^^^^^^^^^^^^^^^^^^^^^^^^^^^^
  File "C:\Users\sunny\Desktop\Development\python\TradePro\ml_models\utils\trade_model.py", line 420, in run_model_predictions
    pred_reverse_1h_v5, pred_continue_1h_v5, pred_historical_1h_v5, _ = standard_analysis(model_ticker, "1h_v5")
                                                                        ^^^^^^^^^^^^^^^^^^^^^^^^^^^^^^^^^^^^^^^^
  File "C:\Users\sunny\Desktop\Development\python\TradePro\ml_models\utils\trade_model.py", line 214, in standard_analysis
    X_live_reverse = dp.scenario_reverse()
                     ^^^^^^^^^^^^^^^^^^^^^
  File "C:\Users\sunny\Desktop\Development\python\TradePro\ml_models\utils\price_processing.py", line 614, in scenario_reverse
    reverse_df_2pips = self.stats_df_gen(df, 2)
                       ^^^^^^^^^^^^^^^^^^^^^^^^
  File "C:\Users\sunny\Desktop\Development\python\TradePro\ml_models\utils\price_processing.py", line 587, in stats_df_gen
    merged_df.to_csv(r"C:\Users\sunny\Desktop\Development\before_df-1.csv", index=False)
  File "C:\Users\sunny\anaconda3\envs\myenv311test\Lib\site-packages\pandas\core\generic.py", line 3466, in to_csv
    return DataFrameRenderer(formatter).to_csv(
           ^^^^^^^^^^^^^^^^^^^^^^^^^^^^^^^^^^^^
  File "C:\Users\sunny\anaconda3\envs\myenv311test\Lib\site-packages\pandas\io\formats\format.py", line 1105, in to_csv
    csv_formatter.save()
  File "C:\Users\sunny\anaconda3\envs\myenv311test\Lib\site-packages\pandas\io\formats\csvs.py", line 237, in save
    with get_handle(
         ^^^^^^^^^^^
  File "C:\Users\sunny\anaconda3\envs\myenv311test\Lib\site-packages\pandas\io\common.py", line 702, in get_handle
    handle = open(
             ^^^^^
PermissionError: [Errno 13] Permission denied: 'C:\\Users\\sunny\\Desktop\\Development\\before_df-1.csv'
2024-08-01 19:26:55,383 - INFO - Adding job tentatively -- it will be properly scheduled when the scheduler starts
2024-08-01 19:26:55,384 - INFO - Added job "run_procedure_sequence" to job store "default"
2024-08-01 19:26:55,384 - INFO - Scheduler started
2024-08-01 19:26:57,633 - INFO - Adding job tentatively -- it will be properly scheduled when the scheduler starts
2024-08-01 19:26:57,633 - INFO - Added job "run_procedure_sequence" to job store "default"
2024-08-01 19:26:57,633 - INFO - Scheduler started
2024-08-01 19:26:57,656 - INFO - Watching for file changes with StatReloader
2024-08-01 19:43:23,360 - INFO - Adding job tentatively -- it will be properly scheduled when the scheduler starts
2024-08-01 19:43:23,360 - INFO - Added job "run_procedure_sequence" to job store "default"
2024-08-01 19:43:23,360 - INFO - Scheduler started
2024-08-01 19:43:25,616 - INFO - Adding job tentatively -- it will be properly scheduled when the scheduler starts
2024-08-01 19:43:25,617 - INFO - Added job "run_procedure_sequence" to job store "default"
2024-08-01 19:43:25,617 - INFO - Scheduler started
2024-08-01 19:43:25,634 - INFO - Watching for file changes with StatReloader
2024-08-01 19:43:33,063 - WARNING - Not Found: /tickers/images/favicon.ico
2024-08-01 19:43:38,753 - WARNING - Not Found: /prices/get-IG-prices/images/favicon.ico
2024-08-01 19:44:04,607 - INFO - The input start time: 2024-07-29 13:00:00+00:00
2024-08-01 19:44:10,946 - WARNING - Not Found: /tickers/ticker/9f53d106-491e-43bc-8f19-f91352ee4426/images/favicon.ico
2024-08-01 19:44:19,873 - ERROR - Internal Server Error: /ml_models/ml-report/
Traceback (most recent call last):
  File "C:\Users\sunny\anaconda3\envs\myenv311test\Lib\site-packages\django\core\handlers\exception.py", line 56, in inner
    response = get_response(request)
               ^^^^^^^^^^^^^^^^^^^^^
  File "C:\Users\sunny\anaconda3\envs\myenv311test\Lib\site-packages\django\core\handlers\base.py", line 197, in _get_response
    response = wrapped_callback(request, *callback_args, **callback_kwargs)
               ^^^^^^^^^^^^^^^^^^^^^^^^^^^^^^^^^^^^^^^^^^^^^^^^^^^^^^^^^^^^
  File "C:\Users\sunny\Desktop\Development\python\TradePro\ml_models\views.py", line 465, in ml_report2
    pred_var_pos, pred_var_neg = variability_analysis(model_ticker, 0.1)
                                 ^^^^^^^^^^^^^^^^^^^^^^^^^^^^^^^^^^^^^^^
  File "C:\Users\sunny\Desktop\Development\python\TradePro\ml_models\utils\trade_model.py", line 473, in variability_analysis
    X_live_variability = dp.prediction_variability(sensitivity_adjustment)
                         ^^^^^^^^^^^^^^^^^^^^^^^^^^^^^^^^^^^^^^^^^^^^^^^^^
  File "C:\Users\sunny\Desktop\Development\python\TradePro\ml_models\utils\price_processing.py", line 694, in prediction_variability
    variability_df_pos = self.stats_df_gen(variability_df,2)
                         ^^^^^^^^^^^^^^^^^^^^^^^^^^^^^^^^^^^
  File "C:\Users\sunny\Desktop\Development\python\TradePro\ml_models\utils\price_processing.py", line 584, in stats_df_gen
    df.to_csv(r"C:\Users\sunny\Desktop\Development\df-1.csv", index=False)
  File "C:\Users\sunny\anaconda3\envs\myenv311test\Lib\site-packages\pandas\core\generic.py", line 3466, in to_csv
    return DataFrameRenderer(formatter).to_csv(
           ^^^^^^^^^^^^^^^^^^^^^^^^^^^^^^^^^^^^
  File "C:\Users\sunny\anaconda3\envs\myenv311test\Lib\site-packages\pandas\io\formats\format.py", line 1105, in to_csv
    csv_formatter.save()
  File "C:\Users\sunny\anaconda3\envs\myenv311test\Lib\site-packages\pandas\io\formats\csvs.py", line 237, in save
    with get_handle(
         ^^^^^^^^^^^
  File "C:\Users\sunny\anaconda3\envs\myenv311test\Lib\site-packages\pandas\io\common.py", line 702, in get_handle
    handle = open(
             ^^^^^
PermissionError: [Errno 13] Permission denied: 'C:\\Users\\sunny\\Desktop\\Development\\df-1.csv'
