2024-08-01 19:17:18,289 - INFO - Adding job tentatively -- it will be properly scheduled when the scheduler starts
2024-08-01 19:17:18,289 - INFO - Added job "run_procedure_sequence" to job store "default"
2024-08-01 19:17:18,289 - INFO - Scheduler started
2024-08-01 19:17:20,542 - INFO - Adding job tentatively -- it will be properly scheduled when the scheduler starts
2024-08-01 19:17:20,542 - INFO - Added job "run_procedure_sequence" to job store "default"
2024-08-01 19:17:20,542 - INFO - Scheduler started
2024-08-01 19:17:20,561 - INFO - Watching for file changes with StatReloader
2024-08-01 19:17:39,457 - WARNING - Not Found: /ml_models/ml-report/images/favicon.ico
2024-08-01 19:25:47,027 - INFO - Adding job tentatively -- it will be properly scheduled when the scheduler starts
2024-08-01 19:25:47,028 - INFO - Added job "run_procedure_sequence" to job store "default"
2024-08-01 19:25:47,028 - INFO - Scheduler started
2024-08-01 19:25:49,478 - INFO - Adding job tentatively -- it will be properly scheduled when the scheduler starts
2024-08-01 19:25:49,478 - INFO - Added job "run_procedure_sequence" to job store "default"
2024-08-01 19:25:49,478 - INFO - Scheduler started
2024-08-01 19:25:49,498 - INFO - Watching for file changes with StatReloader
2024-08-01 19:25:59,055 - ERROR - Internal Server Error: /ml_models/ml-report/
Traceback (most recent call last):
  File "C:\Users\sunny\anaconda3\envs\myenv311test\Lib\site-packages\django\core\handlers\exception.py", line 56, in inner
    response = get_response(request)
               ^^^^^^^^^^^^^^^^^^^^^
  File "C:\Users\sunny\anaconda3\envs\myenv311test\Lib\site-packages\django\core\handlers\base.py", line 197, in _get_response
    response = wrapped_callback(request, *callback_args, **callback_kwargs)
               ^^^^^^^^^^^^^^^^^^^^^^^^^^^^^^^^^^^^^^^^^^^^^^^^^^^^^^^^^^^^
  File "C:\Users\sunny\Desktop\Development\python\TradePro\ml_models\views.py", line 465, in ml_report2
    pred_var_pos, pred_var_neg = variability_analysis(model_ticker, 0.1)
                                 ^^^^^^^^^^^^^^^^^^^^^^^^^^^^^^^^^^^^^^^
  File "C:\Users\sunny\Desktop\Development\python\TradePro\ml_models\utils\trade_model.py", line 473, in variability_analysis
    X_live_variability = dp.prediction_variability(sensitivity_adjustment)
                         ^^^^^^^^^^^^^^^^^^^^^^^^^^^^^^^^^^^^^^^^^^^^^^^^^
  File "C:\Users\sunny\Desktop\Development\python\TradePro\ml_models\utils\price_processing.py", line 694, in prediction_variability
    variability_df_pos = self.stats_df_gen(variability_df,2)
                         ^^^^^^^^^^^^^^^^^^^^^^^^^^^^^^^^^^^
  File "C:\Users\sunny\Desktop\Development\python\TradePro\ml_models\utils\price_processing.py", line 587, in stats_df_gen
    merged_df.to_csv(r"C:\Users\sunny\Desktop\Development\before_df-1.csv", index=False)
  File "C:\Users\sunny\anaconda3\envs\myenv311test\Lib\site-packages\pandas\core\generic.py", line 3466, in to_csv
    return DataFrameRenderer(formatter).to_csv(
           ^^^^^^^^^^^^^^^^^^^^^^^^^^^^^^^^^^^^
  File "C:\Users\sunny\anaconda3\envs\myenv311test\Lib\site-packages\pandas\io\formats\format.py", line 1105, in to_csv
    csv_formatter.save()
  File "C:\Users\sunny\anaconda3\envs\myenv311test\Lib\site-packages\pandas\io\formats\csvs.py", line 237, in save
    with get_handle(
         ^^^^^^^^^^^
  File "C:\Users\sunny\anaconda3\envs\myenv311test\Lib\site-packages\pandas\io\common.py", line 702, in get_handle
    handle = open(
             ^^^^^
PermissionError: [Errno 13] Permission denied: 'C:\\Users\\sunny\\Desktop\\Development\\before_df-1.csv'
2024-08-01 19:26:00,008 - INFO - Running job "run_procedure_sequence (trigger: interval[0:05:00], next run at: 2024-08-01 19:26:00 BST)" (scheduled at 2024-08-01 19:26:00+01:00)
2024-08-01 19:26:00,008 - INFO - Running job "run_procedure_sequence (trigger: interval[0:05:00], next run at: 2024-08-01 19:26:00 BST)" (scheduled at 2024-08-01 19:26:00+01:00)
2024-08-01 19:26:00,198 - INFO - The input start time: 2024-08-01 18:00:00
2024-08-01 19:26:00,198 - INFO - The input start time: 2024-08-01 18:00:00
2024-08-01 19:26:15,558 - ERROR - Job "run_procedure_sequence (trigger: interval[0:05:00], next run at: 2024-08-01 19:31:00 BST)" raised an exception
Traceback (most recent call last):
  File "C:\Users\sunny\anaconda3\envs\myenv311test\Lib\site-packages\apscheduler\executors\base.py", line 125, in run_job
    retval = job.func(*job.args, **job.kwargs)
             ^^^^^^^^^^^^^^^^^^^^^^^^^^^^^^^^^
  File "C:\Users\sunny\Desktop\Development\python\TradePro\prices\updater.py", line 74, in run_procedure_sequence
    comparison_comment, general_ticker_info, send_email_enabled = run_model_predictions(ticker)
                                                                  ^^^^^^^^^^^^^^^^^^^^^^^^^^^^^
  File "C:\Users\sunny\Desktop\Development\python\TradePro\ml_models\utils\trade_model.py", line 420, in run_model_predictions
    pred_reverse_1h_v5, pred_continue_1h_v5, pred_historical_1h_v5, _ = standard_analysis(model_ticker, "1h_v5")
                                                                        ^^^^^^^^^^^^^^^^^^^^^^^^^^^^^^^^^^^^^^^^
  File "C:\Users\sunny\Desktop\Development\python\TradePro\ml_models\utils\trade_model.py", line 214, in standard_analysis
    X_live_reverse = dp.scenario_reverse()
                     ^^^^^^^^^^^^^^^^^^^^^
  File "C:\Users\sunny\Desktop\Development\python\TradePro\ml_models\utils\price_processing.py", line 614, in scenario_reverse
    reverse_df_2pips = self.stats_df_gen(df, 2)
                       ^^^^^^^^^^^^^^^^^^^^^^^^
  File "C:\Users\sunny\Desktop\Development\python\TradePro\ml_models\utils\price_processing.py", line 587, in stats_df_gen
    merged_df.to_csv(r"C:\Users\sunny\Desktop\Development\before_df-1.csv", index=False)
  File "C:\Users\sunny\anaconda3\envs\myenv311test\Lib\site-packages\pandas\core\generic.py", line 3466, in to_csv
    return DataFrameRenderer(formatter).to_csv(
           ^^^^^^^^^^^^^^^^^^^^^^^^^^^^^^^^^^^^
  File "C:\Users\sunny\anaconda3\envs\myenv311test\Lib\site-packages\pandas\io\formats\format.py", line 1105, in to_csv
    csv_formatter.save()
  File "C:\Users\sunny\anaconda3\envs\myenv311test\Lib\site-packages\pandas\io\formats\csvs.py", line 237, in save
    with get_handle(
         ^^^^^^^^^^^
  File "C:\Users\sunny\anaconda3\envs\myenv311test\Lib\site-packages\pandas\io\common.py", line 702, in get_handle
    handle = open(
             ^^^^^
PermissionError: [Errno 13] Permission denied: 'C:\\Users\\sunny\\Desktop\\Development\\before_df-1.csv'
2024-08-01 19:26:15,864 - ERROR - Job "run_procedure_sequence (trigger: interval[0:05:00], next run at: 2024-08-01 19:31:00 BST)" raised an exception
Traceback (most recent call last):
  File "C:\Users\sunny\anaconda3\envs\myenv311test\Lib\site-packages\apscheduler\executors\base.py", line 125, in run_job
    retval = job.func(*job.args, **job.kwargs)
             ^^^^^^^^^^^^^^^^^^^^^^^^^^^^^^^^^
  File "C:\Users\sunny\Desktop\Development\python\TradePro\prices\updater.py", line 74, in run_procedure_sequence
    comparison_comment, general_ticker_info, send_email_enabled = run_model_predictions(ticker)
                                                                  ^^^^^^^^^^^^^^^^^^^^^^^^^^^^^
  File "C:\Users\sunny\Desktop\Development\python\TradePro\ml_models\utils\trade_model.py", line 420, in run_model_predictions
    pred_reverse_1h_v5, pred_continue_1h_v5, pred_historical_1h_v5, _ = standard_analysis(model_ticker, "1h_v5")
                                                                        ^^^^^^^^^^^^^^^^^^^^^^^^^^^^^^^^^^^^^^^^
  File "C:\Users\sunny\Desktop\Development\python\TradePro\ml_models\utils\trade_model.py", line 214, in standard_analysis
    X_live_reverse = dp.scenario_reverse()
                     ^^^^^^^^^^^^^^^^^^^^^
  File "C:\Users\sunny\Desktop\Development\python\TradePro\ml_models\utils\price_processing.py", line 614, in scenario_reverse
    reverse_df_2pips = self.stats_df_gen(df, 2)
                       ^^^^^^^^^^^^^^^^^^^^^^^^
  File "C:\Users\sunny\Desktop\Development\python\TradePro\ml_models\utils\price_processing.py", line 587, in stats_df_gen
    merged_df.to_csv(r"C:\Users\sunny\Desktop\Development\before_df-1.csv", index=False)
  File "C:\Users\sunny\anaconda3\envs\myenv311test\Lib\site-packages\pandas\core\generic.py", line 3466, in to_csv
    return DataFrameRenderer(formatter).to_csv(
           ^^^^^^^^^^^^^^^^^^^^^^^^^^^^^^^^^^^^
  File "C:\Users\sunny\anaconda3\envs\myenv311test\Lib\site-packages\pandas\io\formats\format.py", line 1105, in to_csv
    csv_formatter.save()
  File "C:\Users\sunny\anaconda3\envs\myenv311test\Lib\site-packages\pandas\io\formats\csvs.py", line 237, in save
    with get_handle(
         ^^^^^^^^^^^
  File "C:\Users\sunny\anaconda3\envs\myenv311test\Lib\site-packages\pandas\io\common.py", line 702, in get_handle
    handle = open(
             ^^^^^
PermissionError: [Errno 13] Permission denied: 'C:\\Users\\sunny\\Desktop\\Development\\before_df-1.csv'
2024-08-01 19:26:55,383 - INFO - Adding job tentatively -- it will be properly scheduled when the scheduler starts
2024-08-01 19:26:55,384 - INFO - Added job "run_procedure_sequence" to job store "default"
2024-08-01 19:26:55,384 - INFO - Scheduler started
2024-08-01 19:26:57,633 - INFO - Adding job tentatively -- it will be properly scheduled when the scheduler starts
2024-08-01 19:26:57,633 - INFO - Added job "run_procedure_sequence" to job store "default"
2024-08-01 19:26:57,633 - INFO - Scheduler started
2024-08-01 19:26:57,656 - INFO - Watching for file changes with StatReloader
2024-08-01 19:43:23,360 - INFO - Adding job tentatively -- it will be properly scheduled when the scheduler starts
2024-08-01 19:43:23,360 - INFO - Added job "run_procedure_sequence" to job store "default"
2024-08-01 19:43:23,360 - INFO - Scheduler started
2024-08-01 19:43:25,616 - INFO - Adding job tentatively -- it will be properly scheduled when the scheduler starts
2024-08-01 19:43:25,617 - INFO - Added job "run_procedure_sequence" to job store "default"
2024-08-01 19:43:25,617 - INFO - Scheduler started
2024-08-01 19:43:25,634 - INFO - Watching for file changes with StatReloader
2024-08-01 19:43:33,063 - WARNING - Not Found: /tickers/images/favicon.ico
2024-08-01 19:43:38,753 - WARNING - Not Found: /prices/get-IG-prices/images/favicon.ico
2024-08-01 19:44:04,607 - INFO - The input start time: 2024-07-29 13:00:00+00:00
2024-08-01 19:44:10,946 - WARNING - Not Found: /tickers/ticker/9f53d106-491e-43bc-8f19-f91352ee4426/images/favicon.ico
2024-08-01 19:44:19,873 - ERROR - Internal Server Error: /ml_models/ml-report/
Traceback (most recent call last):
  File "C:\Users\sunny\anaconda3\envs\myenv311test\Lib\site-packages\django\core\handlers\exception.py", line 56, in inner
    response = get_response(request)
               ^^^^^^^^^^^^^^^^^^^^^
  File "C:\Users\sunny\anaconda3\envs\myenv311test\Lib\site-packages\django\core\handlers\base.py", line 197, in _get_response
    response = wrapped_callback(request, *callback_args, **callback_kwargs)
               ^^^^^^^^^^^^^^^^^^^^^^^^^^^^^^^^^^^^^^^^^^^^^^^^^^^^^^^^^^^^
  File "C:\Users\sunny\Desktop\Development\python\TradePro\ml_models\views.py", line 465, in ml_report2
    pred_var_pos, pred_var_neg = variability_analysis(model_ticker, 0.1)
                                 ^^^^^^^^^^^^^^^^^^^^^^^^^^^^^^^^^^^^^^^
  File "C:\Users\sunny\Desktop\Development\python\TradePro\ml_models\utils\trade_model.py", line 473, in variability_analysis
    X_live_variability = dp.prediction_variability(sensitivity_adjustment)
                         ^^^^^^^^^^^^^^^^^^^^^^^^^^^^^^^^^^^^^^^^^^^^^^^^^
  File "C:\Users\sunny\Desktop\Development\python\TradePro\ml_models\utils\price_processing.py", line 694, in prediction_variability
    variability_df_pos = self.stats_df_gen(variability_df,2)
                         ^^^^^^^^^^^^^^^^^^^^^^^^^^^^^^^^^^^
  File "C:\Users\sunny\Desktop\Development\python\TradePro\ml_models\utils\price_processing.py", line 584, in stats_df_gen
    df.to_csv(r"C:\Users\sunny\Desktop\Development\df-1.csv", index=False)
  File "C:\Users\sunny\anaconda3\envs\myenv311test\Lib\site-packages\pandas\core\generic.py", line 3466, in to_csv
    return DataFrameRenderer(formatter).to_csv(
           ^^^^^^^^^^^^^^^^^^^^^^^^^^^^^^^^^^^^
  File "C:\Users\sunny\anaconda3\envs\myenv311test\Lib\site-packages\pandas\io\formats\format.py", line 1105, in to_csv
    csv_formatter.save()
  File "C:\Users\sunny\anaconda3\envs\myenv311test\Lib\site-packages\pandas\io\formats\csvs.py", line 237, in save
    with get_handle(
         ^^^^^^^^^^^
  File "C:\Users\sunny\anaconda3\envs\myenv311test\Lib\site-packages\pandas\io\common.py", line 702, in get_handle
    handle = open(
             ^^^^^
PermissionError: [Errno 13] Permission denied: 'C:\\Users\\sunny\\Desktop\\Development\\df-1.csv'
2024-08-01 19:51:48,096 - INFO - Adding job tentatively -- it will be properly scheduled when the scheduler starts
2024-08-01 19:51:48,097 - INFO - Added job "run_procedure_sequence" to job store "default"
2024-08-01 19:51:48,097 - INFO - Scheduler started
2024-08-01 19:51:50,411 - INFO - Adding job tentatively -- it will be properly scheduled when the scheduler starts
2024-08-01 19:51:50,411 - INFO - Added job "run_procedure_sequence" to job store "default"
2024-08-01 19:51:50,411 - INFO - Scheduler started
2024-08-01 19:51:50,430 - INFO - Watching for file changes with StatReloader
2024-08-01 19:58:11,271 - INFO - Adding job tentatively -- it will be properly scheduled when the scheduler starts
2024-08-01 19:58:11,271 - INFO - Added job "run_procedure_sequence" to job store "default"
2024-08-01 19:58:11,271 - INFO - Scheduler started
2024-08-01 19:58:13,417 - INFO - Adding job tentatively -- it will be properly scheduled when the scheduler starts
2024-08-01 19:58:13,417 - INFO - Added job "run_procedure_sequence" to job store "default"
2024-08-01 19:58:13,417 - INFO - Scheduler started
2024-08-01 19:58:13,435 - INFO - Watching for file changes with StatReloader
2024-08-01 20:02:32,172 - INFO - Adding job tentatively -- it will be properly scheduled when the scheduler starts
2024-08-01 20:02:32,172 - INFO - Added job "run_procedure_sequence" to job store "default"
2024-08-01 20:02:32,172 - INFO - Scheduler started
2024-08-01 20:02:34,365 - INFO - Adding job tentatively -- it will be properly scheduled when the scheduler starts
2024-08-01 20:02:34,365 - INFO - Added job "run_procedure_sequence" to job store "default"
2024-08-01 20:02:34,365 - INFO - Scheduler started
2024-08-01 20:02:34,385 - INFO - Watching for file changes with StatReloader
2024-08-01 20:02:42,145 - WARNING - Not Found: /news/get-news/images/favicon.ico
2024-08-01 20:08:08,065 - INFO - Adding job tentatively -- it will be properly scheduled when the scheduler starts
2024-08-01 20:08:08,065 - INFO - Added job "run_procedure_sequence" to job store "default"
2024-08-01 20:08:08,065 - INFO - Scheduler started
2024-08-01 20:08:10,180 - INFO - Adding job tentatively -- it will be properly scheduled when the scheduler starts
2024-08-01 20:08:10,180 - INFO - Added job "run_procedure_sequence" to job store "default"
2024-08-01 20:08:10,180 - INFO - Scheduler started
2024-08-01 20:08:10,199 - INFO - Watching for file changes with StatReloader
2024-08-01 20:11:09,344 - INFO - Adding job tentatively -- it will be properly scheduled when the scheduler starts
2024-08-01 20:11:09,344 - INFO - Added job "run_procedure_sequence" to job store "default"
2024-08-01 20:11:09,344 - INFO - Scheduler started
2024-08-01 20:11:11,589 - INFO - Adding job tentatively -- it will be properly scheduled when the scheduler starts
2024-08-01 20:11:11,589 - INFO - Added job "run_procedure_sequence" to job store "default"
2024-08-01 20:11:11,589 - INFO - Scheduler started
2024-08-01 20:11:11,608 - INFO - Watching for file changes with StatReloader
2024-08-01 20:11:18,105 - ERROR - Internal Server Error: /news/get-news/
Traceback (most recent call last):
  File "C:\Users\sunny\anaconda3\envs\myenv311test\Lib\site-packages\django\core\handlers\exception.py", line 56, in inner
    response = get_response(request)
               ^^^^^^^^^^^^^^^^^^^^^
  File "C:\Users\sunny\anaconda3\envs\myenv311test\Lib\site-packages\django\core\handlers\base.py", line 197, in _get_response
    response = wrapped_callback(request, *callback_args, **callback_kwargs)
               ^^^^^^^^^^^^^^^^^^^^^^^^^^^^^^^^^^^^^^^^^^^^^^^^^^^^^^^^^^^^
  File "C:\Users\sunny\Desktop\Development\python\TradePro\news\views.py", line 106, in get_news
    return render(request, 'news/get_news.html', {'news_data': news_data, 'form': form})
           ^^^^^^^^^^^^^^^^^^^^^^^^^^^^^^^^^^^^^^^^^^^^^^^^^^^^^^^^^^^^^^^^^^^^^^^^^^^^^
  File "C:\Users\sunny\anaconda3\envs\myenv311test\Lib\site-packages\django\shortcuts.py", line 24, in render
    content = loader.render_to_string(template_name, context, request, using=using)
              ^^^^^^^^^^^^^^^^^^^^^^^^^^^^^^^^^^^^^^^^^^^^^^^^^^^^^^^^^^^^^^^^^^^^^
  File "C:\Users\sunny\anaconda3\envs\myenv311test\Lib\site-packages\django\template\loader.py", line 62, in render_to_string
    return template.render(context, request)
           ^^^^^^^^^^^^^^^^^^^^^^^^^^^^^^^^^
  File "C:\Users\sunny\anaconda3\envs\myenv311test\Lib\site-packages\django\template\backends\django.py", line 61, in render
    return self.template.render(context)
           ^^^^^^^^^^^^^^^^^^^^^^^^^^^^^
  File "C:\Users\sunny\anaconda3\envs\myenv311test\Lib\site-packages\django\template\base.py", line 175, in render
    return self._render(context)
           ^^^^^^^^^^^^^^^^^^^^^
  File "C:\Users\sunny\anaconda3\envs\myenv311test\Lib\site-packages\django\template\base.py", line 167, in _render
    return self.nodelist.render(context)
           ^^^^^^^^^^^^^^^^^^^^^^^^^^^^^
  File "C:\Users\sunny\anaconda3\envs\myenv311test\Lib\site-packages\django\template\base.py", line 1005, in render
    return SafeString("".join([node.render_annotated(context) for node in self]))
                              ^^^^^^^^^^^^^^^^^^^^^^^^^^^^^^^^^^^^^^^^^^^^^^^^^
  File "C:\Users\sunny\anaconda3\envs\myenv311test\Lib\site-packages\django\template\base.py", line 1005, in <listcomp>
    return SafeString("".join([node.render_annotated(context) for node in self]))
                               ^^^^^^^^^^^^^^^^^^^^^^^^^^^^^^
  File "C:\Users\sunny\anaconda3\envs\myenv311test\Lib\site-packages\django\template\base.py", line 966, in render_annotated
    return self.render(context)
           ^^^^^^^^^^^^^^^^^^^^
  File "C:\Users\sunny\anaconda3\envs\myenv311test\Lib\site-packages\django\template\loader_tags.py", line 157, in render
    return compiled_parent._render(context)
           ^^^^^^^^^^^^^^^^^^^^^^^^^^^^^^^^
  File "C:\Users\sunny\anaconda3\envs\myenv311test\Lib\site-packages\django\template\base.py", line 167, in _render
    return self.nodelist.render(context)
           ^^^^^^^^^^^^^^^^^^^^^^^^^^^^^
  File "C:\Users\sunny\anaconda3\envs\myenv311test\Lib\site-packages\django\template\base.py", line 1005, in render
    return SafeString("".join([node.render_annotated(context) for node in self]))
                              ^^^^^^^^^^^^^^^^^^^^^^^^^^^^^^^^^^^^^^^^^^^^^^^^^
  File "C:\Users\sunny\anaconda3\envs\myenv311test\Lib\site-packages\django\template\base.py", line 1005, in <listcomp>
    return SafeString("".join([node.render_annotated(context) for node in self]))
                               ^^^^^^^^^^^^^^^^^^^^^^^^^^^^^^
  File "C:\Users\sunny\anaconda3\envs\myenv311test\Lib\site-packages\django\template\base.py", line 966, in render_annotated
    return self.render(context)
           ^^^^^^^^^^^^^^^^^^^^
  File "C:\Users\sunny\anaconda3\envs\myenv311test\Lib\site-packages\django\template\loader_tags.py", line 63, in render
    result = block.nodelist.render(context)
             ^^^^^^^^^^^^^^^^^^^^^^^^^^^^^^
  File "C:\Users\sunny\anaconda3\envs\myenv311test\Lib\site-packages\django\template\base.py", line 1005, in render
    return SafeString("".join([node.render_annotated(context) for node in self]))
                              ^^^^^^^^^^^^^^^^^^^^^^^^^^^^^^^^^^^^^^^^^^^^^^^^^
  File "C:\Users\sunny\anaconda3\envs\myenv311test\Lib\site-packages\django\template\base.py", line 1005, in <listcomp>
    return SafeString("".join([node.render_annotated(context) for node in self]))
                               ^^^^^^^^^^^^^^^^^^^^^^^^^^^^^^
  File "C:\Users\sunny\anaconda3\envs\myenv311test\Lib\site-packages\django\template\base.py", line 966, in render_annotated
    return self.render(context)
           ^^^^^^^^^^^^^^^^^^^^
  File "C:\Users\sunny\anaconda3\envs\myenv311test\Lib\site-packages\django\template\defaulttags.py", line 471, in render
    url = reverse(view_name, args=args, kwargs=kwargs, current_app=current_app)
          ^^^^^^^^^^^^^^^^^^^^^^^^^^^^^^^^^^^^^^^^^^^^^^^^^^^^^^^^^^^^^^^^^^^^^
  File "C:\Users\sunny\anaconda3\envs\myenv311test\Lib\site-packages\django\urls\base.py", line 88, in reverse
    return resolver._reverse_with_prefix(view, prefix, *args, **kwargs)
           ^^^^^^^^^^^^^^^^^^^^^^^^^^^^^^^^^^^^^^^^^^^^^^^^^^^^^^^^^^^^
  File "C:\Users\sunny\anaconda3\envs\myenv311test\Lib\site-packages\django\urls\resolvers.py", line 828, in _reverse_with_prefix
    raise NoReverseMatch(msg)
django.urls.exceptions.NoReverseMatch: Reverse for 'news/upload-news.html' not found. 'news/upload-news.html' is not a valid view function or pattern name.
2024-08-01 20:12:49,585 - INFO - Adding job tentatively -- it will be properly scheduled when the scheduler starts
2024-08-01 20:12:49,586 - INFO - Added job "run_procedure_sequence" to job store "default"
2024-08-01 20:12:49,586 - INFO - Scheduler started
2024-08-01 20:12:51,766 - INFO - Adding job tentatively -- it will be properly scheduled when the scheduler starts
2024-08-01 20:12:51,766 - INFO - Added job "run_procedure_sequence" to job store "default"
2024-08-01 20:12:51,766 - INFO - Scheduler started
2024-08-01 20:12:51,783 - INFO - Watching for file changes with StatReloader
2024-08-01 20:12:57,633 - WARNING - Not Found: /news/upload-news/images/favicon.ico
2024-08-01 20:14:04,644 - INFO - Adding job tentatively -- it will be properly scheduled when the scheduler starts
2024-08-01 20:14:04,644 - INFO - Added job "run_procedure_sequence" to job store "default"
2024-08-01 20:14:04,644 - INFO - Scheduler started
2024-08-01 20:14:06,835 - INFO - Adding job tentatively -- it will be properly scheduled when the scheduler starts
2024-08-01 20:14:06,836 - INFO - Added job "run_procedure_sequence" to job store "default"
2024-08-01 20:14:06,836 - INFO - Scheduler started
2024-08-01 20:14:06,854 - INFO - Watching for file changes with StatReloader
2024-08-01 20:49:52,259 - INFO - Adding job tentatively -- it will be properly scheduled when the scheduler starts
2024-08-01 20:49:52,259 - INFO - Added job "run_procedure_sequence" to job store "default"
2024-08-01 20:49:52,259 - INFO - Scheduler started
2024-08-01 20:49:54,743 - INFO - Adding job tentatively -- it will be properly scheduled when the scheduler starts
2024-08-01 20:49:54,743 - INFO - Added job "run_procedure_sequence" to job store "default"
2024-08-01 20:49:54,743 - INFO - Scheduler started
2024-08-01 20:49:54,764 - INFO - Watching for file changes with StatReloader
2024-08-01 22:05:58,329 - INFO - Adding job tentatively -- it will be properly scheduled when the scheduler starts
2024-08-01 22:05:58,330 - INFO - Added job "run_procedure_sequence" to job store "default"
2024-08-01 22:05:58,330 - INFO - Scheduler started
2024-08-01 22:06:00,003 - INFO - Running job "run_procedure_sequence (trigger: interval[0:05:00], next run at: 2024-08-01 22:06:00 BST)" (scheduled at 2024-08-01 22:06:00+01:00)
2024-08-01 22:06:00,142 - INFO - The input start time: 2024-08-01 21:00:00
2024-08-01 22:06:00,705 - INFO - Adding job tentatively -- it will be properly scheduled when the scheduler starts
2024-08-01 22:06:00,705 - INFO - Added job "run_procedure_sequence" to job store "default"
2024-08-01 22:06:00,705 - INFO - Scheduler started
2024-08-01 22:06:00,722 - INFO - Watching for file changes with StatReloader
2024-08-01 22:06:15,864 - INFO - Job "run_procedure_sequence (trigger: interval[0:05:00], next run at: 2024-08-01 22:11:00 BST)" executed successfully
2024-08-01 22:06:40,105 - ERROR - Internal Server Error: /ml_models/ml-news-model/
Traceback (most recent call last):
  File "C:\Users\sunny\anaconda3\envs\myenv311test\Lib\site-packages\django\core\handlers\exception.py", line 56, in inner
    response = get_response(request)
               ^^^^^^^^^^^^^^^^^^^^^
  File "C:\Users\sunny\anaconda3\envs\myenv311test\Lib\site-packages\django\core\handlers\base.py", line 197, in _get_response
    response = wrapped_callback(request, *callback_args, **callback_kwargs)
               ^^^^^^^^^^^^^^^^^^^^^^^^^^^^^^^^^^^^^^^^^^^^^^^^^^^^^^^^^^^^
  File "C:\Users\sunny\Desktop\Development\python\TradePro\ml_models\views.py", line 681, in ml_news_model
    return render(request, context)
           ^^^^^^^^^^^^^^^^^^^^^^^^
  File "C:\Users\sunny\anaconda3\envs\myenv311test\Lib\site-packages\django\shortcuts.py", line 24, in render
    content = loader.render_to_string(template_name, context, request, using=using)
              ^^^^^^^^^^^^^^^^^^^^^^^^^^^^^^^^^^^^^^^^^^^^^^^^^^^^^^^^^^^^^^^^^^^^^
  File "C:\Users\sunny\anaconda3\envs\myenv311test\Lib\site-packages\django\template\loader.py", line 61, in render_to_string
    template = get_template(template_name, using=using)
               ^^^^^^^^^^^^^^^^^^^^^^^^^^^^^^^^^^^^^^^^
  File "C:\Users\sunny\anaconda3\envs\myenv311test\Lib\site-packages\django\template\loader.py", line 15, in get_template
    return engine.get_template(template_name)
           ^^^^^^^^^^^^^^^^^^^^^^^^^^^^^^^^^^
  File "C:\Users\sunny\anaconda3\envs\myenv311test\Lib\site-packages\django\template\backends\django.py", line 33, in get_template
    return Template(self.engine.get_template(template_name), self)
                    ^^^^^^^^^^^^^^^^^^^^^^^^^^^^^^^^^^^^^^^
  File "C:\Users\sunny\anaconda3\envs\myenv311test\Lib\site-packages\django\template\engine.py", line 175, in get_template
    template, origin = self.find_template(template_name)
                       ^^^^^^^^^^^^^^^^^^^^^^^^^^^^^^^^^
  File "C:\Users\sunny\anaconda3\envs\myenv311test\Lib\site-packages\django\template\engine.py", line 157, in find_template
    template = loader.get_template(name, skip=skip)
               ^^^^^^^^^^^^^^^^^^^^^^^^^^^^^^^^^^^^
  File "C:\Users\sunny\anaconda3\envs\myenv311test\Lib\site-packages\django\template\loaders\cached.py", line 57, in get_template
    template = super().get_template(template_name, skip)
               ^^^^^^^^^^^^^^^^^^^^^^^^^^^^^^^^^^^^^^^^^
  File "C:\Users\sunny\anaconda3\envs\myenv311test\Lib\site-packages\django\template\loaders\base.py", line 17, in get_template
    for origin in self.get_template_sources(template_name):
  File "C:\Users\sunny\anaconda3\envs\myenv311test\Lib\site-packages\django\template\loaders\cached.py", line 70, in get_template_sources
    yield from loader.get_template_sources(template_name)
  File "C:\Users\sunny\anaconda3\envs\myenv311test\Lib\site-packages\django\template\loaders\filesystem.py", line 35, in get_template_sources
    name = safe_join(template_dir, template_name)
           ^^^^^^^^^^^^^^^^^^^^^^^^^^^^^^^^^^^^^^
  File "C:\Users\sunny\anaconda3\envs\myenv311test\Lib\site-packages\django\utils\_os.py", line 17, in safe_join
    final_path = abspath(join(base, *paths))
                         ^^^^^^^^^^^^^^^^^^
  File "<frozen ntpath>", line 147, in join
  File "<frozen genericpath>", line 152, in _check_arg_types
TypeError: join() argument must be str, bytes, or os.PathLike object, not 'dict'
2024-08-01 22:13:33,238 - INFO - Adding job tentatively -- it will be properly scheduled when the scheduler starts
2024-08-01 22:13:33,238 - INFO - Added job "run_procedure_sequence" to job store "default"
2024-08-01 22:13:33,238 - INFO - Scheduler started
2024-08-01 22:13:35,569 - INFO - Adding job tentatively -- it will be properly scheduled when the scheduler starts
2024-08-01 22:13:35,569 - INFO - Added job "run_procedure_sequence" to job store "default"
2024-08-01 22:13:35,569 - INFO - Scheduler started
2024-08-01 22:13:35,588 - INFO - Watching for file changes with StatReloader
2024-08-01 22:13:50,055 - ERROR - Internal Server Error: /ml_models/ml-news-model/
Traceback (most recent call last):
  File "C:\Users\sunny\anaconda3\envs\myenv311test\Lib\site-packages\django\core\handlers\exception.py", line 56, in inner
    response = get_response(request)
               ^^^^^^^^^^^^^^^^^^^^^
  File "C:\Users\sunny\anaconda3\envs\myenv311test\Lib\site-packages\django\core\handlers\base.py", line 197, in _get_response
    response = wrapped_callback(request, *callback_args, **callback_kwargs)
               ^^^^^^^^^^^^^^^^^^^^^^^^^^^^^^^^^^^^^^^^^^^^^^^^^^^^^^^^^^^^
  File "C:\Users\sunny\Desktop\Development\python\TradePro\ml_models\views.py", line 681, in ml_news_model
    return render(request, context)
           ^^^^^^^^^^^^^^^^^^^^^^^^
  File "C:\Users\sunny\anaconda3\envs\myenv311test\Lib\site-packages\django\shortcuts.py", line 24, in render
    content = loader.render_to_string(template_name, context, request, using=using)
              ^^^^^^^^^^^^^^^^^^^^^^^^^^^^^^^^^^^^^^^^^^^^^^^^^^^^^^^^^^^^^^^^^^^^^
  File "C:\Users\sunny\anaconda3\envs\myenv311test\Lib\site-packages\django\template\loader.py", line 61, in render_to_string
    template = get_template(template_name, using=using)
               ^^^^^^^^^^^^^^^^^^^^^^^^^^^^^^^^^^^^^^^^
  File "C:\Users\sunny\anaconda3\envs\myenv311test\Lib\site-packages\django\template\loader.py", line 15, in get_template
    return engine.get_template(template_name)
           ^^^^^^^^^^^^^^^^^^^^^^^^^^^^^^^^^^
  File "C:\Users\sunny\anaconda3\envs\myenv311test\Lib\site-packages\django\template\backends\django.py", line 33, in get_template
    return Template(self.engine.get_template(template_name), self)
                    ^^^^^^^^^^^^^^^^^^^^^^^^^^^^^^^^^^^^^^^
  File "C:\Users\sunny\anaconda3\envs\myenv311test\Lib\site-packages\django\template\engine.py", line 175, in get_template
    template, origin = self.find_template(template_name)
                       ^^^^^^^^^^^^^^^^^^^^^^^^^^^^^^^^^
  File "C:\Users\sunny\anaconda3\envs\myenv311test\Lib\site-packages\django\template\engine.py", line 157, in find_template
    template = loader.get_template(name, skip=skip)
               ^^^^^^^^^^^^^^^^^^^^^^^^^^^^^^^^^^^^
  File "C:\Users\sunny\anaconda3\envs\myenv311test\Lib\site-packages\django\template\loaders\cached.py", line 57, in get_template
    template = super().get_template(template_name, skip)
               ^^^^^^^^^^^^^^^^^^^^^^^^^^^^^^^^^^^^^^^^^
  File "C:\Users\sunny\anaconda3\envs\myenv311test\Lib\site-packages\django\template\loaders\base.py", line 17, in get_template
    for origin in self.get_template_sources(template_name):
  File "C:\Users\sunny\anaconda3\envs\myenv311test\Lib\site-packages\django\template\loaders\cached.py", line 70, in get_template_sources
    yield from loader.get_template_sources(template_name)
  File "C:\Users\sunny\anaconda3\envs\myenv311test\Lib\site-packages\django\template\loaders\filesystem.py", line 35, in get_template_sources
    name = safe_join(template_dir, template_name)
           ^^^^^^^^^^^^^^^^^^^^^^^^^^^^^^^^^^^^^^
  File "C:\Users\sunny\anaconda3\envs\myenv311test\Lib\site-packages\django\utils\_os.py", line 17, in safe_join
    final_path = abspath(join(base, *paths))
                         ^^^^^^^^^^^^^^^^^^
  File "<frozen ntpath>", line 147, in join
  File "<frozen genericpath>", line 152, in _check_arg_types
TypeError: join() argument must be str, bytes, or os.PathLike object, not 'dict'
2024-08-01 22:15:07,566 - INFO - Adding job tentatively -- it will be properly scheduled when the scheduler starts
2024-08-01 22:15:07,566 - INFO - Added job "run_procedure_sequence" to job store "default"
2024-08-01 22:15:07,566 - INFO - Scheduler started
2024-08-01 22:15:09,962 - INFO - Adding job tentatively -- it will be properly scheduled when the scheduler starts
2024-08-01 22:15:09,962 - INFO - Added job "run_procedure_sequence" to job store "default"
2024-08-01 22:15:09,962 - INFO - Scheduler started
2024-08-01 22:15:09,983 - INFO - Watching for file changes with StatReloader
2024-08-01 22:23:20,171 - INFO - Adding job tentatively -- it will be properly scheduled when the scheduler starts
2024-08-01 22:23:20,172 - INFO - Added job "run_procedure_sequence" to job store "default"
2024-08-01 22:23:20,172 - INFO - Scheduler started
2024-08-01 22:23:22,442 - INFO - Adding job tentatively -- it will be properly scheduled when the scheduler starts
2024-08-01 22:23:22,443 - INFO - Added job "run_procedure_sequence" to job store "default"
2024-08-01 22:23:22,443 - INFO - Scheduler started
2024-08-01 22:23:22,461 - INFO - Watching for file changes with StatReloader
2024-08-01 22:23:35,595 - WARNING - Not Found: /ml_models/ml-news-model/images/favicon.ico
2024-08-01 22:23:39,025 - ERROR - Internal Server Error: /ml_models/ml-news-model/
Traceback (most recent call last):
  File "C:\Users\sunny\anaconda3\envs\myenv311test\Lib\site-packages\django\core\handlers\exception.py", line 56, in inner
    response = get_response(request)
               ^^^^^^^^^^^^^^^^^^^^^
  File "C:\Users\sunny\anaconda3\envs\myenv311test\Lib\site-packages\django\core\handlers\base.py", line 197, in _get_response
    response = wrapped_callback(request, *callback_args, **callback_kwargs)
               ^^^^^^^^^^^^^^^^^^^^^^^^^^^^^^^^^^^^^^^^^^^^^^^^^^^^^^^^^^^^
  File "C:\Users\sunny\Desktop\Development\python\TradePro\ml_models\views.py", line 660, in ml_news_model
    news_pred_results = news_model_run(ticker_input, user_input, model_version)
                        ^^^^^^^^^^^^^^^^^^^^^^^^^^^^^^^^^^^^^^^^^^^^^^^^^^^^^^^
  File "C:\Users\sunny\Desktop\Development\python\TradePro\ml_models\utils\news_model.py", line 73, in news_model_run
    model_prediction = model_pipeline.predict(X_live_subset)
                       ^^^^^^^^^^^^^^^^^^^^^^^^^^^^^^^^^^^^^
  File "C:\Users\sunny\anaconda3\envs\myenv311test\Lib\site-packages\sklearn\pipeline.py", line 515, in predict
    return self.steps[-1][1].predict(Xt, **predict_params)
           ^^^^^^^^^^^^^^^^^^^^^^^^^^^^^^^^^^^^^^^^^^^^^^^
  File "C:\Users\sunny\anaconda3\envs\myenv311test\Lib\site-packages\sklearn\ensemble\_gb.py", line 1293, in predict
    raw_predictions = self.decision_function(X)
                      ^^^^^^^^^^^^^^^^^^^^^^^^^
  File "C:\Users\sunny\anaconda3\envs\myenv311test\Lib\site-packages\sklearn\ensemble\_gb.py", line 1246, in decision_function
    X = self._validate_data(
        ^^^^^^^^^^^^^^^^^^^^
  File "C:\Users\sunny\anaconda3\envs\myenv311test\Lib\site-packages\sklearn\base.py", line 605, in _validate_data
    out = check_array(X, input_name="X", **check_params)
          ^^^^^^^^^^^^^^^^^^^^^^^^^^^^^^^^^^^^^^^^^^^^^^
  File "C:\Users\sunny\anaconda3\envs\myenv311test\Lib\site-packages\sklearn\utils\validation.py", line 957, in check_array
    _assert_all_finite(
  File "C:\Users\sunny\anaconda3\envs\myenv311test\Lib\site-packages\sklearn\utils\validation.py", line 122, in _assert_all_finite
    _assert_all_finite_element_wise(
  File "C:\Users\sunny\anaconda3\envs\myenv311test\Lib\site-packages\sklearn\utils\validation.py", line 171, in _assert_all_finite_element_wise
    raise ValueError(msg_err)
ValueError: Input X contains NaN.
GradientBoostingClassifier does not accept missing values encoded as NaN natively. For supervised learning, you might want to consider sklearn.ensemble.HistGradientBoostingClassifier and Regressor which accept missing values encoded as NaNs natively. Alternatively, it is possible to preprocess the data, for instance by using an imputer transformer in a pipeline or drop samples with missing values. See https://scikit-learn.org/stable/modules/impute.html You can find a list of all estimators that handle NaN values at the following page: https://scikit-learn.org/stable/modules/impute.html#estimators-that-handle-nan-values
2024-08-01 22:26:10,072 - INFO - Adding job tentatively -- it will be properly scheduled when the scheduler starts
2024-08-01 22:26:10,073 - INFO - Added job "run_procedure_sequence" to job store "default"
2024-08-01 22:26:10,073 - INFO - Scheduler started
2024-08-01 22:26:12,472 - INFO - Adding job tentatively -- it will be properly scheduled when the scheduler starts
2024-08-01 22:26:12,472 - INFO - Added job "run_procedure_sequence" to job store "default"
2024-08-01 22:26:12,472 - INFO - Scheduler started
2024-08-01 22:26:12,493 - INFO - Watching for file changes with StatReloader
2024-08-01 22:31:15,185 - INFO - Adding job tentatively -- it will be properly scheduled when the scheduler starts
2024-08-01 22:31:15,185 - INFO - Added job "run_procedure_sequence" to job store "default"
2024-08-01 22:31:15,185 - INFO - Scheduler started
2024-08-01 22:31:17,402 - INFO - Adding job tentatively -- it will be properly scheduled when the scheduler starts
2024-08-01 22:31:17,403 - INFO - Added job "run_procedure_sequence" to job store "default"
2024-08-01 22:31:17,403 - INFO - Scheduler started
2024-08-01 22:31:17,421 - INFO - Watching for file changes with StatReloader
2024-08-01 22:36:00,010 - INFO - Running job "run_procedure_sequence (trigger: interval[0:05:00], next run at: 2024-08-01 22:41:00 BST)" (scheduled at 2024-08-01 22:36:00+01:00)
2024-08-01 22:36:00,011 - INFO - Running job "run_procedure_sequence (trigger: interval[0:05:00], next run at: 2024-08-01 22:36:00 BST)" (scheduled at 2024-08-01 22:36:00+01:00)
2024-08-01 22:36:00,171 - INFO - The input start time: 2024-08-01 21:00:00
2024-08-01 22:36:00,171 - INFO - The input start time: 2024-08-01 21:00:00
2024-08-01 22:36:22,626 - INFO - Job "run_procedure_sequence (trigger: interval[0:05:00], next run at: 2024-08-01 22:41:00 BST)" executed successfully
2024-08-01 22:36:25,280 - INFO - Job "run_procedure_sequence (trigger: interval[0:05:00], next run at: 2024-08-01 22:41:00 BST)" executed successfully
2024-08-03 07:49:59,165 - INFO - Adding job tentatively -- it will be properly scheduled when the scheduler starts
2024-08-03 07:49:59,165 - INFO - Added job "run_procedure_sequence" to job store "default"
2024-08-03 07:49:59,165 - INFO - Scheduler started
2024-08-03 07:50:01,466 - INFO - Adding job tentatively -- it will be properly scheduled when the scheduler starts
2024-08-03 07:50:01,467 - INFO - Added job "run_procedure_sequence" to job store "default"
2024-08-03 07:50:01,467 - INFO - Scheduler started
2024-08-03 07:50:01,484 - INFO - Watching for file changes with StatReloader
2024-08-03 07:50:03,363 - WARNING - Not Found: /images/favicon.ico
2024-08-03 07:50:05,121 - WARNING - Not Found: /news/get-news/images/favicon.ico
2024-08-03 07:50:06,455 - WARNING - Not Found: /news/upload-news/images/favicon.ico
2024-08-03 07:51:00,010 - INFO - Running job "run_procedure_sequence (trigger: interval[0:05:00], next run at: 2024-08-03 07:51:00 BST)" (scheduled at 2024-08-03 07:51:00+01:00)
2024-08-03 07:51:00,011 - INFO - Running job "run_procedure_sequence (trigger: interval[0:05:00], next run at: 2024-08-03 07:51:00 BST)" (scheduled at 2024-08-03 07:51:00+01:00)
2024-08-03 07:51:00,246 - INFO - The input start time: 2024-08-03 06:00:00
2024-08-03 07:51:00,246 - INFO - The input start time: 2024-08-03 06:00:00
2024-08-03 07:51:21,108 - INFO - Job "run_procedure_sequence (trigger: interval[0:05:00], next run at: 2024-08-03 07:56:00 BST)" executed successfully
2024-08-03 07:51:22,786 - INFO - Job "run_procedure_sequence (trigger: interval[0:05:00], next run at: 2024-08-03 07:56:00 BST)" executed successfully
2024-08-03 12:45:19,521 - INFO - Adding job tentatively -- it will be properly scheduled when the scheduler starts
2024-08-03 12:45:19,522 - INFO - Added job "run_procedure_sequence" to job store "default"
2024-08-03 12:45:19,522 - INFO - Scheduler started
2024-08-03 12:45:21,858 - INFO - Adding job tentatively -- it will be properly scheduled when the scheduler starts
2024-08-03 12:45:21,858 - INFO - Added job "run_procedure_sequence" to job store "default"
2024-08-03 12:45:21,858 - INFO - Scheduler started
2024-08-03 12:45:21,882 - INFO - Watching for file changes with StatReloader
2024-08-03 12:45:24,340 - WARNING - Not Found: /images/favicon.ico
2024-08-03 12:45:26,410 - WARNING - Not Found: /ml_models/about/images/favicon.ico
2024-08-03 12:45:30,850 - WARNING - Not Found: /login/images/favicon.ico
2024-08-03 12:45:46,140 - WARNING - Not Found: /account/images/favicon.ico
2024-08-03 12:45:48,677 - WARNING - Not Found: /profile/images/favicon.ico
2024-08-03 12:45:52,692 - WARNING - Not Found: /ml_models/ml-variability/images/favicon.ico
2024-08-03 12:45:53,769 - WARNING - Not Found: /users-list/images/favicon.ico
2024-08-03 12:46:00,014 - INFO - Running job "run_procedure_sequence (trigger: interval[0:05:00], next run at: 2024-08-03 12:46:00 BST)" (scheduled at 2024-08-03 12:46:00+01:00)
2024-08-03 12:46:00,014 - INFO - Running job "run_procedure_sequence (trigger: interval[0:05:00], next run at: 2024-08-03 12:46:00 BST)" (scheduled at 2024-08-03 12:46:00+01:00)
2024-08-03 12:46:00,244 - INFO - The input start time: 2024-08-03 11:00:00
2024-08-03 12:46:00,244 - INFO - The input start time: 2024-08-03 11:00:00
2024-08-03 12:46:22,037 - INFO - Job "run_procedure_sequence (trigger: interval[0:05:00], next run at: 2024-08-03 12:51:00 BST)" executed successfully
2024-08-03 12:46:23,132 - INFO - Job "run_procedure_sequence (trigger: interval[0:05:00], next run at: 2024-08-03 12:51:00 BST)" executed successfully
2024-08-03 13:00:21,296 - INFO - Adding job tentatively -- it will be properly scheduled when the scheduler starts
2024-08-03 13:00:21,296 - INFO - Added job "run_procedure_sequence" to job store "default"
2024-08-03 13:00:21,296 - INFO - Scheduler started
2024-08-03 13:00:23,681 - INFO - Adding job tentatively -- it will be properly scheduled when the scheduler starts
2024-08-03 13:00:23,681 - INFO - Added job "run_procedure_sequence" to job store "default"
2024-08-03 13:00:23,681 - INFO - Scheduler started
2024-08-03 13:00:23,700 - INFO - Watching for file changes with StatReloader
2024-08-03 13:00:36,411 - WARNING - Not Found: /tickers/images/favicon.ico
2024-08-03 13:01:00,015 - INFO - Running job "run_procedure_sequence (trigger: interval[0:05:00], next run at: 2024-08-03 13:01:00 BST)" (scheduled at 2024-08-03 13:01:00+01:00)
2024-08-03 13:01:00,015 - INFO - Running job "run_procedure_sequence (trigger: interval[0:05:00], next run at: 2024-08-03 13:01:00 BST)" (scheduled at 2024-08-03 13:01:00+01:00)
2024-08-03 13:01:00,168 - INFO - The input start time: 2024-08-03 12:00:00
2024-08-03 13:01:00,170 - INFO - The input start time: 2024-08-03 12:00:00
2024-08-03 13:01:01,792 - ERROR - Job "run_procedure_sequence (trigger: interval[0:05:00], next run at: 2024-08-03 13:06:00 BST)" raised an exception
Traceback (most recent call last):
  File "C:\Users\sunny\anaconda3\envs\myenv311test\Lib\site-packages\apscheduler\executors\base.py", line 125, in run_job
    retval = job.func(*job.args, **job.kwargs)
             ^^^^^^^^^^^^^^^^^^^^^^^^^^^^^^^^^
  File "C:\Users\sunny\Desktop\Development\python\TradePro\prices\updater.py", line 73, in run_procedure_sequence
    run_IG(ticker)
  File "C:\Users\sunny\Desktop\Development\python\TradePro\prices\IG_session\run_IG.py", line 165, in run_IG
    ig_service.create_session()
  File "C:\Users\sunny\Desktop\Development\python\TradePro\prices\IG_session\ig_service.py", line 393, in create_session
    self._set_headers(response.headers, True)
  File "C:\Users\sunny\Desktop\Development\python\TradePro\prices\IG_session\ig_service.py", line 450, in _set_headers
    self.CLIENT_TOKEN = response_headers['CST']
                        ~~~~~~~~~~~~~~~~^^^^^^^
  File "C:\Users\sunny\anaconda3\envs\myenv311test\Lib\site-packages\requests\structures.py", line 52, in __getitem__
    return self._store[key.lower()][1]
           ~~~~~~~~~~~^^^^^^^^^^^^^
KeyError: 'cst'
2024-08-03 13:01:01,792 - ERROR - Job "run_procedure_sequence (trigger: interval[0:05:00], next run at: 2024-08-03 13:06:00 BST)" raised an exception
Traceback (most recent call last):
  File "C:\Users\sunny\anaconda3\envs\myenv311test\Lib\site-packages\apscheduler\executors\base.py", line 125, in run_job
    retval = job.func(*job.args, **job.kwargs)
             ^^^^^^^^^^^^^^^^^^^^^^^^^^^^^^^^^
  File "C:\Users\sunny\Desktop\Development\python\TradePro\prices\updater.py", line 73, in run_procedure_sequence
    run_IG(ticker)
  File "C:\Users\sunny\Desktop\Development\python\TradePro\prices\IG_session\run_IG.py", line 165, in run_IG
    ig_service.create_session()
  File "C:\Users\sunny\Desktop\Development\python\TradePro\prices\IG_session\ig_service.py", line 393, in create_session
    self._set_headers(response.headers, True)
  File "C:\Users\sunny\Desktop\Development\python\TradePro\prices\IG_session\ig_service.py", line 450, in _set_headers
    self.CLIENT_TOKEN = response_headers['CST']
                        ~~~~~~~~~~~~~~~~^^^^^^^
  File "C:\Users\sunny\anaconda3\envs\myenv311test\Lib\site-packages\requests\structures.py", line 52, in __getitem__
    return self._store[key.lower()][1]
           ~~~~~~~~~~~^^^^^^^^^^^^^
KeyError: 'cst'
2024-08-03 13:01:06,138 - WARNING - Not Found: /users/backend-control
2024-08-03 13:01:06,188 - WARNING - Not Found: /favicon.ico
2024-08-03 13:02:26,884 - INFO - Adding job tentatively -- it will be properly scheduled when the scheduler starts
2024-08-03 13:02:26,885 - INFO - Added job "run_procedure_sequence" to job store "default"
2024-08-03 13:02:26,885 - INFO - Scheduler started
2024-08-03 13:02:28,997 - INFO - Adding job tentatively -- it will be properly scheduled when the scheduler starts
2024-08-03 13:02:28,998 - INFO - Added job "run_procedure_sequence" to job store "default"
2024-08-03 13:02:28,998 - INFO - Scheduler started
2024-08-03 13:02:29,018 - INFO - Watching for file changes with StatReloader
2024-08-03 13:03:16,913 - ERROR - Internal Server Error: /ml_models/delete-file/logfile.log/
Traceback (most recent call last):
  File "C:\Users\sunny\anaconda3\envs\myenv311test\Lib\site-packages\django\core\handlers\exception.py", line 56, in inner
    response = get_response(request)
               ^^^^^^^^^^^^^^^^^^^^^
  File "C:\Users\sunny\anaconda3\envs\myenv311test\Lib\site-packages\django\core\handlers\base.py", line 197, in _get_response
    response = wrapped_callback(request, *callback_args, **callback_kwargs)
               ^^^^^^^^^^^^^^^^^^^^^^^^^^^^^^^^^^^^^^^^^^^^^^^^^^^^^^^^^^^^
  File "C:\Users\sunny\Desktop\Development\python\TradePro\ml_models\views.py", line 732, in delete_file
    os.remove(file_path)
PermissionError: [WinError 32] The process cannot access the file because it is being used by another process: 'C:\\Users\\sunny\\Desktop\\Development\\python\\TradePro\\media\\model_results\\logfile.log'
2024-08-03 13:03:26,510 - WARNING - Not Found: /ml_models/notes/images/favicon.ico
2024-08-03 13:06:00,012 - INFO - Running job "run_procedure_sequence (trigger: interval[0:05:00], next run at: 2024-08-03 13:06:00 BST)" (scheduled at 2024-08-03 13:06:00+01:00)
2024-08-03 13:06:00,012 - INFO - Running job "run_procedure_sequence (trigger: interval[0:05:00], next run at: 2024-08-03 13:06:00 BST)" (scheduled at 2024-08-03 13:06:00+01:00)
2024-08-03 13:06:00,155 - INFO - The input start time: 2024-08-03 12:00:00
2024-08-03 13:06:00,155 - INFO - The input start time: 2024-08-03 12:00:00
2024-08-03 13:06:00,981 - ERROR - Job "run_procedure_sequence (trigger: interval[0:05:00], next run at: 2024-08-03 13:11:00 BST)" raised an exception
Traceback (most recent call last):
  File "C:\Users\sunny\anaconda3\envs\myenv311test\Lib\site-packages\apscheduler\executors\base.py", line 125, in run_job
    retval = job.func(*job.args, **job.kwargs)
             ^^^^^^^^^^^^^^^^^^^^^^^^^^^^^^^^^
  File "C:\Users\sunny\Desktop\Development\python\TradePro\prices\updater.py", line 73, in run_procedure_sequence
    run_IG(ticker)
  File "C:\Users\sunny\Desktop\Development\python\TradePro\prices\IG_session\run_IG.py", line 165, in run_IG
    ig_service.create_session()
  File "C:\Users\sunny\Desktop\Development\python\TradePro\prices\IG_session\ig_service.py", line 393, in create_session
    self._set_headers(response.headers, True)
  File "C:\Users\sunny\Desktop\Development\python\TradePro\prices\IG_session\ig_service.py", line 450, in _set_headers
    self.CLIENT_TOKEN = response_headers['CST']
                        ~~~~~~~~~~~~~~~~^^^^^^^
  File "C:\Users\sunny\anaconda3\envs\myenv311test\Lib\site-packages\requests\structures.py", line 52, in __getitem__
    return self._store[key.lower()][1]
           ~~~~~~~~~~~^^^^^^^^^^^^^
KeyError: 'cst'
2024-08-03 13:06:00,982 - ERROR - Job "run_procedure_sequence (trigger: interval[0:05:00], next run at: 2024-08-03 13:11:00 BST)" raised an exception
Traceback (most recent call last):
  File "C:\Users\sunny\anaconda3\envs\myenv311test\Lib\site-packages\apscheduler\executors\base.py", line 125, in run_job
    retval = job.func(*job.args, **job.kwargs)
             ^^^^^^^^^^^^^^^^^^^^^^^^^^^^^^^^^
  File "C:\Users\sunny\Desktop\Development\python\TradePro\prices\updater.py", line 73, in run_procedure_sequence
    run_IG(ticker)
  File "C:\Users\sunny\Desktop\Development\python\TradePro\prices\IG_session\run_IG.py", line 165, in run_IG
    ig_service.create_session()
  File "C:\Users\sunny\Desktop\Development\python\TradePro\prices\IG_session\ig_service.py", line 393, in create_session
    self._set_headers(response.headers, True)
  File "C:\Users\sunny\Desktop\Development\python\TradePro\prices\IG_session\ig_service.py", line 450, in _set_headers
    self.CLIENT_TOKEN = response_headers['CST']
                        ~~~~~~~~~~~~~~~~^^^^^^^
  File "C:\Users\sunny\anaconda3\envs\myenv311test\Lib\site-packages\requests\structures.py", line 52, in __getitem__
    return self._store[key.lower()][1]
           ~~~~~~~~~~~^^^^^^^^^^^^^
KeyError: 'cst'
2024-08-03 13:06:12,119 - WARNING - Not Found: /backend-control/images/favicon.ico
2024-08-03 13:15:24,333 - INFO - Adding job tentatively -- it will be properly scheduled when the scheduler starts
2024-08-03 13:15:24,334 - INFO - Added job "run_procedure_sequence" to job store "default"
2024-08-03 13:15:24,334 - INFO - Scheduler started
2024-08-03 13:15:26,500 - INFO - Adding job tentatively -- it will be properly scheduled when the scheduler starts
2024-08-03 13:15:26,500 - INFO - Added job "run_procedure_sequence" to job store "default"
2024-08-03 13:15:26,500 - INFO - Scheduler started
2024-08-03 13:15:26,519 - INFO - Watching for file changes with StatReloader
2024-08-03 13:16:00,007 - INFO - Running job "run_procedure_sequence (trigger: interval[0:05:00], next run at: 2024-08-03 13:16:00 BST)" (scheduled at 2024-08-03 13:16:00+01:00)
2024-08-03 13:16:00,007 - INFO - Running job "run_procedure_sequence (trigger: interval[0:05:00], next run at: 2024-08-03 13:21:00 BST)" (scheduled at 2024-08-03 13:16:00+01:00)
2024-08-03 13:16:00,198 - INFO - The input start time: 2024-08-03 12:00:00
2024-08-03 13:16:00,202 - INFO - The input start time: 2024-08-03 12:00:00
2024-08-03 13:16:18,250 - INFO - Job "run_procedure_sequence (trigger: interval[0:05:00], next run at: 2024-08-03 13:21:00 BST)" executed successfully
2024-08-03 13:16:19,353 - INFO - Job "run_procedure_sequence (trigger: interval[0:05:00], next run at: 2024-08-03 13:21:00 BST)" executed successfully
2024-08-03 13:17:15,458 - WARNING - Not Found: /ml_models/ml-report/images/favicon.ico
2024-08-03 13:20:52,088 - WARNING - Not Found: /news/get-news/images/favicon.ico
2024-08-03 13:21:00,004 - INFO - Running job "run_procedure_sequence (trigger: interval[0:05:00], next run at: 2024-08-03 13:26:00 BST)" (scheduled at 2024-08-03 13:21:00+01:00)
2024-08-03 13:21:00,005 - INFO - The input start time: 2024-08-03 12:00:00
2024-08-03 13:21:00,055 - INFO - Running job "run_procedure_sequence (trigger: interval[0:05:00], next run at: 2024-08-03 13:26:00 BST)" (scheduled at 2024-08-03 13:21:00+01:00)
2024-08-03 13:21:00,077 - INFO - The input start time: 2024-08-03 12:00:00
2024-08-03 13:21:17,868 - INFO - Job "run_procedure_sequence (trigger: interval[0:05:00], next run at: 2024-08-03 13:26:00 BST)" executed successfully
2024-08-03 13:21:26,714 - INFO - Job "run_procedure_sequence (trigger: interval[0:05:00], next run at: 2024-08-03 13:26:00 BST)" executed successfully
2024-08-03 13:26:33,248 - INFO - Adding job tentatively -- it will be properly scheduled when the scheduler starts
2024-08-03 13:26:33,249 - INFO - Added job "run_procedure_sequence" to job store "default"
2024-08-03 13:26:33,249 - INFO - Scheduler started
2024-08-03 13:26:35,642 - INFO - Adding job tentatively -- it will be properly scheduled when the scheduler starts
2024-08-03 13:26:35,643 - INFO - Added job "run_procedure_sequence" to job store "default"
2024-08-03 13:26:35,643 - INFO - Scheduler started
2024-08-03 13:26:35,663 - INFO - Watching for file changes with StatReloader
2024-08-03 13:27:01,356 - WARNING - Not Found: /news/upload-news/images/favicon.ico
2024-08-03 13:31:06,725 - INFO - Adding job tentatively -- it will be properly scheduled when the scheduler starts
2024-08-03 13:31:06,725 - INFO - Added job "run_procedure_sequence" to job store "default"
2024-08-03 13:31:06,725 - INFO - Scheduler started
2024-08-03 13:31:08,983 - INFO - Adding job tentatively -- it will be properly scheduled when the scheduler starts
2024-08-03 13:31:08,983 - INFO - Added job "run_procedure_sequence" to job store "default"
2024-08-03 13:31:08,983 - INFO - Scheduler started
2024-08-03 13:31:09,001 - INFO - Watching for file changes with StatReloader
2024-08-03 13:59:57,258 - INFO - Adding job tentatively -- it will be properly scheduled when the scheduler starts
2024-08-03 13:59:57,259 - INFO - Added job "run_procedure_sequence" to job store "default"
2024-08-03 13:59:57,259 - INFO - Scheduler started
2024-08-03 13:59:59,589 - INFO - Adding job tentatively -- it will be properly scheduled when the scheduler starts
2024-08-03 13:59:59,589 - INFO - Added job "run_procedure_sequence" to job store "default"
2024-08-03 13:59:59,589 - INFO - Scheduler started
2024-08-03 13:59:59,609 - INFO - Watching for file changes with StatReloader
2024-08-03 14:00:10,347 - ERROR - Internal Server Error: /news/upload-news/
Traceback (most recent call last):
  File "C:\Users\sunny\anaconda3\envs\myenv311test\Lib\site-packages\django\core\handlers\exception.py", line 56, in inner
    response = get_response(request)
               ^^^^^^^^^^^^^^^^^^^^^
  File "C:\Users\sunny\anaconda3\envs\myenv311test\Lib\site-packages\django\core\handlers\base.py", line 197, in _get_response
    response = wrapped_callback(request, *callback_args, **callback_kwargs)
               ^^^^^^^^^^^^^^^^^^^^^^^^^^^^^^^^^^^^^^^^^^^^^^^^^^^^^^^^^^^^
  File "C:\Users\sunny\Desktop\Development\python\TradePro\news\views.py", line 30, in upload_news
    df = pd.read_csv(file)
         ^^
NameError: name 'pd' is not defined
2024-08-03 14:00:24,194 - INFO - C:\Users\sunny\Desktop\Development\python\TradePro\news\views.py changed, reloading.
2024-08-03 14:00:27,725 - INFO - Adding job tentatively -- it will be properly scheduled when the scheduler starts
2024-08-03 14:00:27,725 - INFO - Added job "run_procedure_sequence" to job store "default"
2024-08-03 14:00:27,725 - INFO - Scheduler started
2024-08-03 14:00:27,756 - INFO - Watching for file changes with StatReloader
2024-08-03 14:01:00,011 - INFO - Running job "run_procedure_sequence (trigger: interval[0:05:00], next run at: 2024-08-03 14:01:00 BST)" (scheduled at 2024-08-03 14:01:00+01:00)
2024-08-03 14:01:00,011 - INFO - Running job "run_procedure_sequence (trigger: interval[0:05:00], next run at: 2024-08-03 14:06:00 BST)" (scheduled at 2024-08-03 14:01:00+01:00)
2024-08-03 14:01:00,212 - INFO - The input start time: 2024-08-03 13:00:00
2024-08-03 14:01:00,213 - INFO - The input start time: 2024-08-03 13:00:00
2024-08-03 14:01:01,487 - ERROR - Job "run_procedure_sequence (trigger: interval[0:05:00], next run at: 2024-08-03 14:06:00 BST)" raised an exception
Traceback (most recent call last):
  File "C:\Users\sunny\anaconda3\envs\myenv311test\Lib\site-packages\apscheduler\executors\base.py", line 125, in run_job
    retval = job.func(*job.args, **job.kwargs)
             ^^^^^^^^^^^^^^^^^^^^^^^^^^^^^^^^^
  File "C:\Users\sunny\Desktop\Development\python\TradePro\prices\updater.py", line 73, in run_procedure_sequence
    run_IG(ticker)
  File "C:\Users\sunny\Desktop\Development\python\TradePro\prices\IG_session\run_IG.py", line 165, in run_IG
    ig_service.create_session()
  File "C:\Users\sunny\Desktop\Development\python\TradePro\prices\IG_session\ig_service.py", line 393, in create_session
    self._set_headers(response.headers, True)
  File "C:\Users\sunny\Desktop\Development\python\TradePro\prices\IG_session\ig_service.py", line 450, in _set_headers
    self.CLIENT_TOKEN = response_headers['CST']
                        ~~~~~~~~~~~~~~~~^^^^^^^
  File "C:\Users\sunny\anaconda3\envs\myenv311test\Lib\site-packages\requests\structures.py", line 52, in __getitem__
    return self._store[key.lower()][1]
           ~~~~~~~~~~~^^^^^^^^^^^^^
KeyError: 'cst'
2024-08-03 14:01:33,464 - INFO - Job "run_procedure_sequence (trigger: interval[0:05:00], next run at: 2024-08-03 14:06:00 BST)" executed successfully
2024-08-03 14:06:00,016 - INFO - Running job "run_procedure_sequence (trigger: interval[0:05:00], next run at: 2024-08-03 14:11:00 BST)" (scheduled at 2024-08-03 14:06:00+01:00)
2024-08-03 14:06:00,016 - INFO - Running job "run_procedure_sequence (trigger: interval[0:05:00], next run at: 2024-08-03 14:11:00 BST)" (scheduled at 2024-08-03 14:06:00+01:00)
2024-08-03 14:06:00,021 - INFO - The input start time: 2024-08-03 13:00:00
2024-08-03 14:06:00,021 - INFO - The input start time: 2024-08-03 13:00:00
2024-08-03 14:06:00,644 - ERROR - Job "run_procedure_sequence (trigger: interval[0:05:00], next run at: 2024-08-03 14:11:00 BST)" raised an exception
Traceback (most recent call last):
  File "C:\Users\sunny\anaconda3\envs\myenv311test\Lib\site-packages\apscheduler\executors\base.py", line 125, in run_job
    retval = job.func(*job.args, **job.kwargs)
             ^^^^^^^^^^^^^^^^^^^^^^^^^^^^^^^^^
  File "C:\Users\sunny\Desktop\Development\python\TradePro\prices\updater.py", line 73, in run_procedure_sequence
    run_IG(ticker)
  File "C:\Users\sunny\Desktop\Development\python\TradePro\prices\IG_session\run_IG.py", line 165, in run_IG
    ig_service.create_session()
  File "C:\Users\sunny\Desktop\Development\python\TradePro\prices\IG_session\ig_service.py", line 393, in create_session
    self._set_headers(response.headers, True)
  File "C:\Users\sunny\Desktop\Development\python\TradePro\prices\IG_session\ig_service.py", line 450, in _set_headers
    self.CLIENT_TOKEN = response_headers['CST']
                        ~~~~~~~~~~~~~~~~^^^^^^^
  File "C:\Users\sunny\anaconda3\envs\myenv311test\Lib\site-packages\requests\structures.py", line 52, in __getitem__
    return self._store[key.lower()][1]
           ~~~~~~~~~~~^^^^^^^^^^^^^
KeyError: 'cst'
2024-08-03 14:06:15,381 - INFO - Job "run_procedure_sequence (trigger: interval[0:05:00], next run at: 2024-08-03 14:11:00 BST)" executed successfully
2024-08-03 14:11:00,002 - INFO - Running job "run_procedure_sequence (trigger: interval[0:05:00], next run at: 2024-08-03 14:16:00 BST)" (scheduled at 2024-08-03 14:11:00+01:00)
2024-08-03 14:11:00,002 - INFO - Running job "run_procedure_sequence (trigger: interval[0:05:00], next run at: 2024-08-03 14:16:00 BST)" (scheduled at 2024-08-03 14:11:00+01:00)
2024-08-03 14:11:00,008 - INFO - The input start time: 2024-08-03 13:00:00
2024-08-03 14:11:00,009 - INFO - The input start time: 2024-08-03 13:00:00
2024-08-03 14:11:01,296 - ERROR - Job "run_procedure_sequence (trigger: interval[0:05:00], next run at: 2024-08-03 14:16:00 BST)" raised an exception
Traceback (most recent call last):
  File "C:\Users\sunny\anaconda3\envs\myenv311test\Lib\site-packages\apscheduler\executors\base.py", line 125, in run_job
    retval = job.func(*job.args, **job.kwargs)
             ^^^^^^^^^^^^^^^^^^^^^^^^^^^^^^^^^
  File "C:\Users\sunny\Desktop\Development\python\TradePro\prices\updater.py", line 73, in run_procedure_sequence
    run_IG(ticker)
  File "C:\Users\sunny\Desktop\Development\python\TradePro\prices\IG_session\run_IG.py", line 165, in run_IG
    ig_service.create_session()
  File "C:\Users\sunny\Desktop\Development\python\TradePro\prices\IG_session\ig_service.py", line 393, in create_session
    self._set_headers(response.headers, True)
  File "C:\Users\sunny\Desktop\Development\python\TradePro\prices\IG_session\ig_service.py", line 450, in _set_headers
    self.CLIENT_TOKEN = response_headers['CST']
                        ~~~~~~~~~~~~~~~~^^^^^^^
  File "C:\Users\sunny\anaconda3\envs\myenv311test\Lib\site-packages\requests\structures.py", line 52, in __getitem__
    return self._store[key.lower()][1]
           ~~~~~~~~~~~^^^^^^^^^^^^^
KeyError: 'cst'
2024-08-03 14:11:18,380 - INFO - Job "run_procedure_sequence (trigger: interval[0:05:00], next run at: 2024-08-03 14:16:00 BST)" executed successfully
2024-08-03 14:16:48,957 - INFO - Adding job tentatively -- it will be properly scheduled when the scheduler starts
2024-08-03 14:16:48,957 - INFO - Added job "run_procedure_sequence" to job store "default"
2024-08-03 14:16:48,957 - INFO - Scheduler started
2024-08-03 14:16:51,383 - INFO - Adding job tentatively -- it will be properly scheduled when the scheduler starts
2024-08-03 14:16:51,384 - INFO - Added job "run_procedure_sequence" to job store "default"
2024-08-03 14:16:51,384 - INFO - Scheduler started
2024-08-03 14:16:51,404 - INFO - Watching for file changes with StatReloader
2024-08-03 14:21:09,870 - INFO - Adding job tentatively -- it will be properly scheduled when the scheduler starts
2024-08-03 14:21:09,870 - INFO - Added job "run_procedure_sequence" to job store "default"
2024-08-03 14:21:09,870 - INFO - Scheduler started
2024-08-03 14:21:12,263 - INFO - Adding job tentatively -- it will be properly scheduled when the scheduler starts
2024-08-03 14:21:12,263 - INFO - Added job "run_procedure_sequence" to job store "default"
2024-08-03 14:21:12,263 - INFO - Scheduler started
2024-08-03 14:21:12,285 - INFO - Watching for file changes with StatReloader
2024-08-03 14:21:26,718 - WARNING - Not Found: /ml_models/model-accuracy/images/favicon.ico
2024-08-03 14:25:31,284 - INFO - Adding job tentatively -- it will be properly scheduled when the scheduler starts
2024-08-03 14:25:31,284 - INFO - Added job "run_procedure_sequence" to job store "default"
2024-08-03 14:25:31,284 - INFO - Scheduler started
2024-08-03 14:25:33,591 - INFO - Adding job tentatively -- it will be properly scheduled when the scheduler starts
2024-08-03 14:25:33,591 - INFO - Added job "run_procedure_sequence" to job store "default"
2024-08-03 14:25:33,591 - INFO - Scheduler started
2024-08-03 14:25:33,613 - INFO - Watching for file changes with StatReloader
2024-08-03 14:26:00,007 - INFO - Running job "run_procedure_sequence (trigger: interval[0:05:00], next run at: 2024-08-03 14:26:00 BST)" (scheduled at 2024-08-03 14:26:00+01:00)
2024-08-03 14:26:00,007 - INFO - Running job "run_procedure_sequence (trigger: interval[0:05:00], next run at: 2024-08-03 14:31:00 BST)" (scheduled at 2024-08-03 14:26:00+01:00)
2024-08-03 14:26:00,252 - INFO - The input start time: 2024-08-03 13:00:00
2024-08-03 14:26:00,252 - INFO - The input start time: 2024-08-03 13:00:00
2024-08-03 14:26:01,229 - ERROR - Job "run_procedure_sequence (trigger: interval[0:05:00], next run at: 2024-08-03 14:31:00 BST)" raised an exception
Traceback (most recent call last):
  File "C:\Users\sunny\anaconda3\envs\myenv311test\Lib\site-packages\apscheduler\executors\base.py", line 125, in run_job
    retval = job.func(*job.args, **job.kwargs)
             ^^^^^^^^^^^^^^^^^^^^^^^^^^^^^^^^^
  File "C:\Users\sunny\Desktop\Development\python\TradePro\prices\updater.py", line 73, in run_procedure_sequence
    run_IG(ticker)
  File "C:\Users\sunny\Desktop\Development\python\TradePro\prices\IG_session\run_IG.py", line 165, in run_IG
    ig_service.create_session()
  File "C:\Users\sunny\Desktop\Development\python\TradePro\prices\IG_session\ig_service.py", line 393, in create_session
    self._set_headers(response.headers, True)
  File "C:\Users\sunny\Desktop\Development\python\TradePro\prices\IG_session\ig_service.py", line 450, in _set_headers
    self.CLIENT_TOKEN = response_headers['CST']
                        ~~~~~~~~~~~~~~~~^^^^^^^
  File "C:\Users\sunny\anaconda3\envs\myenv311test\Lib\site-packages\requests\structures.py", line 52, in __getitem__
    return self._store[key.lower()][1]
           ~~~~~~~~~~~^^^^^^^^^^^^^
KeyError: 'cst'
2024-08-03 14:26:29,709 - INFO - Job "run_procedure_sequence (trigger: interval[0:05:00], next run at: 2024-08-03 14:31:00 BST)" executed successfully
