
2024-03-22 23:26:35,721 - INFO - Starting scheduler
2024-03-22 23:26:35,721 - INFO - Updater date and time: 2024-03-22 23:26:35.721071
2024-03-22 23:26:35,721 - INFO - Adding job tentatively -- it will be properly scheduled when the scheduler starts
2024-03-22 23:26:35,721 - INFO - Added job "run_procedure_sequence" to job store "default"
2024-03-22 23:26:35,721 - INFO - Scheduler started
2024-03-22 23:26:35,721 - INFO - Ending scheduler
2024-03-22 23:26:37,535 - INFO - Starting scheduler
2024-03-22 23:26:37,536 - INFO - Updater date and time: 2024-03-22 23:26:37.536117
2024-03-22 23:26:37,537 - INFO - Adding job tentatively -- it will be properly scheduled when the scheduler starts
2024-03-22 23:26:37,537 - INFO - Added job "run_procedure_sequence" to job store "default"
2024-03-22 23:26:37,537 - INFO - Scheduler started
2024-03-22 23:26:37,539 - INFO - Ending scheduler
2024-03-22 23:26:37,559 - INFO - Watching for file changes with StatReloader
2024-03-22 23:29:27,933 - INFO - Watching for file changes with StatReloader
2024-03-23 07:45:46,315 - INFO - Starting scheduler
2024-03-23 07:45:46,315 - INFO - Updater date and time: 2024-03-23 07:45:46.315788
2024-03-23 07:45:46,315 - INFO - Adding job tentatively -- it will be properly scheduled when the scheduler starts
2024-03-23 07:45:46,315 - INFO - Added job "run_procedure_sequence" to job store "default"
2024-03-23 07:45:46,315 - INFO - Scheduler started
2024-03-23 07:45:46,331 - INFO - Ending scheduler
2024-03-23 07:45:48,060 - INFO - Starting scheduler
2024-03-23 07:45:48,060 - INFO - Updater date and time: 2024-03-23 07:45:48.060993
2024-03-23 07:45:48,060 - INFO - Adding job tentatively -- it will be properly scheduled when the scheduler starts
2024-03-23 07:45:48,060 - INFO - Added job "run_procedure_sequence" to job store "default"
2024-03-23 07:45:48,060 - INFO - Scheduler started
2024-03-23 07:45:48,060 - INFO - Ending scheduler
2024-03-23 07:45:48,079 - INFO - Watching for file changes with StatReloader
2024-03-23 07:45:54,649 - WARNING - Not Found: /images/favicon.ico
2024-03-23 07:45:56,346 - WARNING - Not Found: /tickers/images/favicon.ico
2024-03-23 07:45:59,658 - WARNING - Not Found: /prices/upload-prices/images/favicon.ico
2024-03-23 07:46:00,009 - INFO - Running job "run_procedure_sequence (trigger: interval[0:05:00], next run at: 2024-03-23 07:46:00 GMT)" (scheduled at 2024-03-23 07:46:00+00:00)
2024-03-23 07:46:00,010 - INFO - Inside the procedure sequence
2024-03-23 07:46:00,676 - ERROR - Job "run_procedure_sequence (trigger: interval[0:05:00], next run at: 2024-03-23 07:51:00 GMT)" raised an exception
Traceback (most recent call last):
  File "C:\Users\sunny\anaconda3\envs\myenv311test\Lib\site-packages\apscheduler\executors\base.py", line 125, in run_job
    retval = job.func(*job.args, **job.kwargs)
             ^^^^^^^^^^^^^^^^^^^^^^^^^^^^^^^^^
  File "C:\Users\sunny\Desktop\Development\python\TradePro\prices\updater.py", line 54, in run_procedure_sequence
    run_IG(ticker)
  File "C:\Users\sunny\Desktop\Development\python\TradePro\prices\IG_session\run_IG.py", line 144, in run_IG
    ig_service.create_session()
  File "C:\Users\sunny\Desktop\Development\python\TradePro\prices\IG_session\ig_service.py", line 393, in create_session
    self._set_headers(response.headers, True)
  File "C:\Users\sunny\Desktop\Development\python\TradePro\prices\IG_session\ig_service.py", line 450, in _set_headers
    self.CLIENT_TOKEN = response_headers['CST']
                        ~~~~~~~~~~~~~~~~^^^^^^^
  File "C:\Users\sunny\anaconda3\envs\myenv311test\Lib\site-packages\requests\structures.py", line 52, in __getitem__
    return self._store[key.lower()][1]
           ~~~~~~~~~~~^^^^^^^^^^^^^
KeyError: 'cst'
2024-03-23 07:46:11,273 - INFO - Job "run_procedure_sequence (trigger: interval[0:05:00], next run at: 2024-03-23 07:51:00 GMT)" executed successfully
2024-03-23 07:48:55,144 - WARNING - Not Found: /tickers/ticker/aa433766-dd42-44c3-a075-fb7a2421c22a/images/favicon.ico
2024-03-23 07:54:42,341 - INFO - Starting scheduler
2024-03-23 07:54:42,341 - INFO - Updater date and time: 2024-03-23 07:54:42.341248
2024-03-23 07:54:42,346 - INFO - Adding job tentatively -- it will be properly scheduled when the scheduler starts
2024-03-23 07:54:42,346 - INFO - Added job "run_procedure_sequence" to job store "default"
2024-03-23 07:54:42,346 - INFO - Scheduler started
2024-03-23 07:54:42,347 - INFO - Ending scheduler
2024-03-23 07:54:44,087 - INFO - Starting scheduler
2024-03-23 07:54:44,087 - INFO - Updater date and time: 2024-03-23 07:54:44.087933
2024-03-23 07:54:44,087 - INFO - Adding job tentatively -- it will be properly scheduled when the scheduler starts
2024-03-23 07:54:44,087 - INFO - Added job "run_procedure_sequence" to job store "default"
2024-03-23 07:54:44,087 - INFO - Scheduler started
2024-03-23 07:54:44,087 - INFO - Ending scheduler
2024-03-23 07:54:44,120 - INFO - Watching for file changes with StatReloader
2024-03-23 07:55:49,465 - INFO - Starting scheduler
2024-03-23 07:55:49,466 - INFO - Updater date and time: 2024-03-23 07:55:49.466766
2024-03-23 07:55:49,467 - INFO - Adding job tentatively -- it will be properly scheduled when the scheduler starts
2024-03-23 07:55:49,467 - INFO - Added job "run_procedure_sequence" to job store "default"
2024-03-23 07:55:49,467 - INFO - Scheduler started
2024-03-23 07:55:49,468 - INFO - Ending scheduler
2024-03-23 07:55:51,134 - INFO - Starting scheduler
2024-03-23 07:55:51,134 - INFO - Updater date and time: 2024-03-23 07:55:51.134352
2024-03-23 07:55:51,134 - INFO - Adding job tentatively -- it will be properly scheduled when the scheduler starts
2024-03-23 07:55:51,134 - INFO - Added job "run_procedure_sequence" to job store "default"
2024-03-23 07:55:51,134 - INFO - Scheduler started
2024-03-23 07:55:51,134 - INFO - Ending scheduler
2024-03-23 07:55:51,158 - INFO - Watching for file changes with StatReloader
2024-03-23 07:56:00,002 - INFO - Running job "run_procedure_sequence (trigger: interval[0:05:00], next run at: 2024-03-23 07:56:00 GMT)" (scheduled at 2024-03-23 07:56:00+00:00)
2024-03-23 07:56:00,002 - INFO - Inside the procedure sequence
2024-03-23 07:56:00,017 - INFO - Running job "run_procedure_sequence (trigger: interval[0:05:00], next run at: 2024-03-23 08:01:00 GMT)" (scheduled at 2024-03-23 07:56:00+00:00)
2024-03-23 07:56:00,018 - INFO - Inside the procedure sequence
2024-03-23 07:56:00,601 - ERROR - Job "run_procedure_sequence (trigger: interval[0:05:00], next run at: 2024-03-23 08:01:00 GMT)" raised an exception
Traceback (most recent call last):
  File "C:\Users\sunny\anaconda3\envs\myenv311test\Lib\site-packages\apscheduler\executors\base.py", line 125, in run_job
    retval = job.func(*job.args, **job.kwargs)
             ^^^^^^^^^^^^^^^^^^^^^^^^^^^^^^^^^
  File "C:\Users\sunny\Desktop\Development\python\TradePro\prices\updater.py", line 54, in run_procedure_sequence
    run_IG(ticker)
  File "C:\Users\sunny\Desktop\Development\python\TradePro\prices\IG_session\run_IG.py", line 144, in run_IG
    ig_service.create_session()
  File "C:\Users\sunny\Desktop\Development\python\TradePro\prices\IG_session\ig_service.py", line 393, in create_session
    self._set_headers(response.headers, True)
  File "C:\Users\sunny\Desktop\Development\python\TradePro\prices\IG_session\ig_service.py", line 450, in _set_headers
    self.CLIENT_TOKEN = response_headers['CST']
                        ~~~~~~~~~~~~~~~~^^^^^^^
  File "C:\Users\sunny\anaconda3\envs\myenv311test\Lib\site-packages\requests\structures.py", line 52, in __getitem__
    return self._store[key.lower()][1]
           ~~~~~~~~~~~^^^^^^^^^^^^^
KeyError: 'cst'
2024-03-23 07:56:12,697 - INFO - Job "run_procedure_sequence (trigger: interval[0:05:00], next run at: 2024-03-23 08:01:00 GMT)" executed successfully
2024-03-23 07:57:17,741 - INFO - Starting scheduler
2024-03-23 07:57:17,741 - INFO - Updater date and time: 2024-03-23 07:57:17.741809
2024-03-23 07:57:17,741 - INFO - Adding job tentatively -- it will be properly scheduled when the scheduler starts
2024-03-23 07:57:17,741 - INFO - Added job "run_procedure_sequence" to job store "default"
2024-03-23 07:57:17,741 - INFO - Scheduler started
2024-03-23 07:57:17,741 - INFO - Ending scheduler
2024-03-23 07:57:19,462 - INFO - Starting scheduler
2024-03-23 07:57:19,462 - INFO - Updater date and time: 2024-03-23 07:57:19.462209
2024-03-23 07:57:19,462 - INFO - Adding job tentatively -- it will be properly scheduled when the scheduler starts
2024-03-23 07:57:19,462 - INFO - Added job "run_procedure_sequence" to job store "default"
2024-03-23 07:57:19,462 - INFO - Scheduler started
2024-03-23 07:57:19,462 - INFO - Ending scheduler
2024-03-23 07:57:19,485 - INFO - Watching for file changes with StatReloader
2024-03-23 07:57:27,032 - WARNING - Not Found: /ml_models/ml-report/images/favicon.ico
2024-03-23 07:57:30,126 - ERROR - Internal Server Error: /ml_models/ml-report/
Traceback (most recent call last):
  File "C:\Users\sunny\anaconda3\envs\myenv311test\Lib\site-packages\django\core\handlers\exception.py", line 55, in inner
    response = get_response(request)
               ^^^^^^^^^^^^^^^^^^^^^
  File "C:\Users\sunny\anaconda3\envs\myenv311test\Lib\site-packages\django\core\handlers\base.py", line 197, in _get_response
    response = wrapped_callback(request, *callback_args, **callback_kwargs)
               ^^^^^^^^^^^^^^^^^^^^^^^^^^^^^^^^^^^^^^^^^^^^^^^^^^^^^^^^^^^^
  File "C:\Users\sunny\Desktop\Development\python\TradePro\ml_models\views.py", line 179, in ml_report
    pred_historical_v4 = read_prediction_from_json(model_ticker, f'USDJPY_pred_historical_v4.json')
                         ^^^^^^^^^^^^^^^^^^^^^^^^^^^^^^^^^^^^^^^^^^^^^^^^^^^^^^^^^^^^^^^^^^^^^^^^^^
  File "C:\Users\sunny\Desktop\Development\python\TradePro\ml_models\utils\access_results.py", line 55, in read_prediction_from_json
    with open(absolute_path, 'r') as file:
         ^^^^^^^^^^^^^^^^^^^^^^^^
FileNotFoundError: [Errno 2] No such file or directory: 'C:\\Users\\sunny\\Desktop\\Development\\python\\TradePro\\media\\model_results\\EURUSD\\USDJPY_pred_historical_v4.json'
2024-03-23 07:57:30,233 - WARNING - Not Found: /favicon.ico
2024-03-23 07:57:44,777 - WARNING - Not Found: /ml_models/ml-predictions/images/favicon.ico
2024-03-23 07:58:46,344 - INFO - Starting scheduler
2024-03-23 07:58:46,344 - INFO - Updater date and time: 2024-03-23 07:58:46.344722
2024-03-23 07:58:46,344 - INFO - Adding job tentatively -- it will be properly scheduled when the scheduler starts
2024-03-23 07:58:46,344 - INFO - Added job "run_procedure_sequence" to job store "default"
2024-03-23 07:58:46,344 - INFO - Scheduler started
2024-03-23 07:58:46,344 - INFO - Ending scheduler
2024-03-23 07:58:48,057 - INFO - Starting scheduler
2024-03-23 07:58:48,057 - INFO - Updater date and time: 2024-03-23 07:58:48.057983
2024-03-23 07:58:48,057 - INFO - Adding job tentatively -- it will be properly scheduled when the scheduler starts
2024-03-23 07:58:48,057 - INFO - Added job "run_procedure_sequence" to job store "default"
2024-03-23 07:58:48,057 - INFO - Scheduler started
2024-03-23 07:58:48,057 - INFO - Ending scheduler
2024-03-23 07:58:48,079 - INFO - Watching for file changes with StatReloader
2024-03-23 07:59:18,970 - WARNING - Not Found: /prices/update-price/3d790007-08f2-4072-bc15-4f47b8b48c7f/images/favicon.ico
2024-03-23 08:00:02,967 - ERROR - Internal Server Error: /ml_models/ml-report/
Traceback (most recent call last):
  File "C:\Users\sunny\anaconda3\envs\myenv311test\Lib\site-packages\django\core\handlers\exception.py", line 55, in inner
    response = get_response(request)
               ^^^^^^^^^^^^^^^^^^^^^
  File "C:\Users\sunny\anaconda3\envs\myenv311test\Lib\site-packages\django\core\handlers\base.py", line 197, in _get_response
    response = wrapped_callback(request, *callback_args, **callback_kwargs)
               ^^^^^^^^^^^^^^^^^^^^^^^^^^^^^^^^^^^^^^^^^^^^^^^^^^^^^^^^^^^^
  File "C:\Users\sunny\Desktop\Development\python\TradePro\ml_models\views.py", line 179, in ml_report
    pred_historical_v4 = read_prediction_from_json(model_ticker, f'USDJPY_pred_historical_v4.json')
                         ^^^^^^^^^^^^^^^^^^^^^^^^^^^^^^^^^^^^^^^^^^^^^^^^^^^^^^^^^^^^^^^^^^^^^^^^^^
  File "C:\Users\sunny\Desktop\Development\python\TradePro\ml_models\utils\access_results.py", line 55, in read_prediction_from_json
    with open(absolute_path, 'r') as file:
         ^^^^^^^^^^^^^^^^^^^^^^^^
FileNotFoundError: [Errno 2] No such file or directory: 'C:\\Users\\sunny\\Desktop\\Development\\python\\TradePro\\media\\model_results\\EURUSD\\USDJPY_pred_historical_v4.json'
2024-03-23 08:03:09,396 - INFO - Starting scheduler
2024-03-23 08:03:09,397 - INFO - Updater date and time: 2024-03-23 08:03:09.396530
2024-03-23 08:03:09,398 - INFO - Adding job tentatively -- it will be properly scheduled when the scheduler starts
2024-03-23 08:03:09,398 - INFO - Added job "run_procedure_sequence" to job store "default"
2024-03-23 08:03:09,398 - INFO - Scheduler started
2024-03-23 08:03:09,399 - INFO - Ending scheduler
2024-03-23 08:03:11,203 - INFO - Starting scheduler
2024-03-23 08:03:11,205 - INFO - Updater date and time: 2024-03-23 08:03:11.205176
2024-03-23 08:03:11,206 - INFO - Adding job tentatively -- it will be properly scheduled when the scheduler starts
2024-03-23 08:03:11,206 - INFO - Added job "run_procedure_sequence" to job store "default"
2024-03-23 08:03:11,206 - INFO - Scheduler started
2024-03-23 08:03:11,207 - INFO - Ending scheduler
2024-03-23 08:03:11,220 - INFO - Watching for file changes with StatReloader
2024-03-23 08:03:25,154 - ERROR - Internal Server Error: /ml_models/ml-report/
Traceback (most recent call last):
  File "C:\Users\sunny\anaconda3\envs\myenv311test\Lib\site-packages\pandas\core\indexes\base.py", line 3791, in get_loc
    return self._engine.get_loc(casted_key)
           ^^^^^^^^^^^^^^^^^^^^^^^^^^^^^^^^
  File "index.pyx", line 152, in pandas._libs.index.IndexEngine.get_loc
  File "index.pyx", line 181, in pandas._libs.index.IndexEngine.get_loc
  File "pandas\_libs\hashtable_class_helper.pxi", line 7080, in pandas._libs.hashtable.PyObjectHashTable.get_item
  File "pandas\_libs\hashtable_class_helper.pxi", line 7088, in pandas._libs.hashtable.PyObjectHashTable.get_item
KeyError: 'pl_open_f1_hr'

The above exception was the direct cause of the following exception:

Traceback (most recent call last):
  File "C:\Users\sunny\anaconda3\envs\myenv311test\Lib\site-packages\django\core\handlers\exception.py", line 55, in inner
    response = get_response(request)
               ^^^^^^^^^^^^^^^^^^^^^
  File "C:\Users\sunny\anaconda3\envs\myenv311test\Lib\site-packages\django\core\handlers\base.py", line 197, in _get_response
    response = wrapped_callback(request, *callback_args, **callback_kwargs)
               ^^^^^^^^^^^^^^^^^^^^^^^^^^^^^^^^^^^^^^^^^^^^^^^^^^^^^^^^^^^^
  File "C:\Users\sunny\Desktop\Development\python\TradePro\ml_models\views.py", line 292, in ml_report
    pred_var_pos, pred_var_neg = variability_analysis(model_ticker, 0.1)
                                 ^^^^^^^^^^^^^^^^^^^^^^^^^^^^^^^^^^^^^^^
  File "C:\Users\sunny\Desktop\Development\python\TradePro\ml_models\utils\predictive_analysis.py", line 374, in variability_analysis
    X_live_variability = dp.prediction_variability(sensitivity_adjustment)
                         ^^^^^^^^^^^^^^^^^^^^^^^^^^^^^^^^^^^^^^^^^^^^^^^^^
  File "C:\Users\sunny\Desktop\Development\python\TradePro\ml_models\trained_models\EURUSD\pl_predictions\1h_v5\data_processing.py", line 565, in prediction_variability
    variability_df_pos = stats_df_gen(variability_df,2)
                         ^^^^^^^^^^^^^^^^^^^^^^^^^^^^^^
  File "C:\Users\sunny\Desktop\Development\python\TradePro\ml_models\trained_models\EURUSD\pl_predictions\1h_v5\data_processing.py", line 426, in stats_df_gen
    df['pl_open_f1_hr'] = df['pl_open_f1_hr'].ffill()
                          ~~^^^^^^^^^^^^^^^^^
  File "C:\Users\sunny\anaconda3\envs\myenv311test\Lib\site-packages\pandas\core\frame.py", line 3893, in __getitem__
    indexer = self.columns.get_loc(key)
              ^^^^^^^^^^^^^^^^^^^^^^^^^
  File "C:\Users\sunny\anaconda3\envs\myenv311test\Lib\site-packages\pandas\core\indexes\base.py", line 3798, in get_loc
    raise KeyError(key) from err
KeyError: 'pl_open_f1_hr'
2024-03-23 09:24:12,689 - INFO - Starting scheduler
2024-03-23 09:24:12,689 - INFO - Updater date and time: 2024-03-23 09:24:12.689442
2024-03-23 09:24:12,705 - INFO - Adding job tentatively -- it will be properly scheduled when the scheduler starts
2024-03-23 09:24:12,705 - INFO - Added job "run_procedure_sequence" to job store "default"
2024-03-23 09:24:12,705 - INFO - Scheduler started
2024-03-23 09:24:12,705 - INFO - Ending scheduler
2024-03-23 09:24:14,569 - INFO - Starting scheduler
2024-03-23 09:24:14,570 - INFO - Updater date and time: 2024-03-23 09:24:14.570416
2024-03-23 09:24:14,570 - INFO - Adding job tentatively -- it will be properly scheduled when the scheduler starts
2024-03-23 09:24:14,570 - INFO - Added job "run_procedure_sequence" to job store "default"
2024-03-23 09:24:14,570 - INFO - Scheduler started
2024-03-23 09:24:14,570 - INFO - Ending scheduler
2024-03-23 09:24:14,589 - INFO - Watching for file changes with StatReloader
2024-03-23 09:25:26,294 - WARNING - Not Found: /tickers/ticker/9f53d106-491e-43bc-8f19-f91352ee4426/images/favicon.ico
2024-03-23 09:26:00,002 - INFO - Running job "run_procedure_sequence (trigger: interval[0:05:00], next run at: 2024-03-23 09:26:00 GMT)" (scheduled at 2024-03-23 09:26:00+00:00)
2024-03-23 09:26:00,002 - INFO - Inside the procedure sequence
2024-03-23 09:26:00,032 - INFO - Running job "run_procedure_sequence (trigger: interval[0:05:00], next run at: 2024-03-23 09:26:00 GMT)" (scheduled at 2024-03-23 09:26:00+00:00)
2024-03-23 09:26:00,026 - ERROR - Job "run_procedure_sequence (trigger: interval[0:05:00], next run at: 2024-03-23 09:31:00 GMT)" raised an exception
Traceback (most recent call last):
  File "C:\Users\sunny\anaconda3\envs\myenv311test\Lib\site-packages\urllib3\connection.py", line 203, in _new_conn
    sock = connection.create_connection(
           ^^^^^^^^^^^^^^^^^^^^^^^^^^^^^
  File "C:\Users\sunny\anaconda3\envs\myenv311test\Lib\site-packages\urllib3\util\connection.py", line 60, in create_connection
    for res in socket.getaddrinfo(host, port, family, socket.SOCK_STREAM):
               ^^^^^^^^^^^^^^^^^^^^^^^^^^^^^^^^^^^^^^^^^^^^^^^^^^^^^^^^^^
  File "C:\Users\sunny\anaconda3\envs\myenv311test\Lib\socket.py", line 962, in getaddrinfo
    for res in _socket.getaddrinfo(host, port, family, type, proto, flags):
               ^^^^^^^^^^^^^^^^^^^^^^^^^^^^^^^^^^^^^^^^^^^^^^^^^^^^^^^^^^^
socket.gaierror: [Errno 11001] getaddrinfo failed

The above exception was the direct cause of the following exception:

Traceback (most recent call last):
  File "C:\Users\sunny\anaconda3\envs\myenv311test\Lib\site-packages\urllib3\connectionpool.py", line 790, in urlopen
    response = self._make_request(
               ^^^^^^^^^^^^^^^^^^^
  File "C:\Users\sunny\anaconda3\envs\myenv311test\Lib\site-packages\urllib3\connectionpool.py", line 491, in _make_request
    raise new_e
  File "C:\Users\sunny\anaconda3\envs\myenv311test\Lib\site-packages\urllib3\connectionpool.py", line 467, in _make_request
    self._validate_conn(conn)
  File "C:\Users\sunny\anaconda3\envs\myenv311test\Lib\site-packages\urllib3\connectionpool.py", line 1096, in _validate_conn
    conn.connect()
  File "C:\Users\sunny\anaconda3\envs\myenv311test\Lib\site-packages\urllib3\connection.py", line 611, in connect
    self.sock = sock = self._new_conn()
                       ^^^^^^^^^^^^^^^^
  File "C:\Users\sunny\anaconda3\envs\myenv311test\Lib\site-packages\urllib3\connection.py", line 210, in _new_conn
    raise NameResolutionError(self.host, self, e) from e
urllib3.exceptions.NameResolutionError: <urllib3.connection.HTTPSConnection object at 0x000001F59587F290>: Failed to resolve 'api.ig.com' ([Errno 11001] getaddrinfo failed)

The above exception was the direct cause of the following exception:

Traceback (most recent call last):
  File "C:\Users\sunny\anaconda3\envs\myenv311test\Lib\site-packages\requests\adapters.py", line 486, in send
    resp = conn.urlopen(
           ^^^^^^^^^^^^^
  File "C:\Users\sunny\anaconda3\envs\myenv311test\Lib\site-packages\urllib3\connectionpool.py", line 844, in urlopen
    retries = retries.increment(
              ^^^^^^^^^^^^^^^^^^
  File "C:\Users\sunny\anaconda3\envs\myenv311test\Lib\site-packages\urllib3\util\retry.py", line 515, in increment
    raise MaxRetryError(_pool, url, reason) from reason  # type: ignore[arg-type]
    ^^^^^^^^^^^^^^^^^^^^^^^^^^^^^^^^^^^^^^^^^^^^^^^^^^^
urllib3.exceptions.MaxRetryError: HTTPSConnectionPool(host='api.ig.com', port=443): Max retries exceeded with url: /gateway/deal/session (Caused by NameResolutionError("<urllib3.connection.HTTPSConnection object at 0x000001F59587F290>: Failed to resolve 'api.ig.com' ([Errno 11001] getaddrinfo failed)"))

During handling of the above exception, another exception occurred:

Traceback (most recent call last):
  File "C:\Users\sunny\anaconda3\envs\myenv311test\Lib\site-packages\apscheduler\executors\base.py", line 125, in run_job
    retval = job.func(*job.args, **job.kwargs)
             ^^^^^^^^^^^^^^^^^^^^^^^^^^^^^^^^^
  File "C:\Users\sunny\Desktop\Development\python\TradePro\prices\updater.py", line 54, in run_procedure_sequence
    run_IG(ticker)
  File "C:\Users\sunny\Desktop\Development\python\TradePro\prices\IG_session\run_IG.py", line 144, in run_IG
    ig_service.create_session()
  File "C:\Users\sunny\Desktop\Development\python\TradePro\prices\IG_session\ig_service.py", line 392, in create_session
    response = requests.post(self.BASE_URL  + '/session', data=json.dumps(params), headers=self.BASIC_HEADERS)
               ^^^^^^^^^^^^^^^^^^^^^^^^^^^^^^^^^^^^^^^^^^^^^^^^^^^^^^^^^^^^^^^^^^^^^^^^^^^^^^^^^^^^^^^^^^^^^^^
  File "C:\Users\sunny\anaconda3\envs\myenv311test\Lib\site-packages\requests\api.py", line 115, in post
    return request("post", url, data=data, json=json, **kwargs)
           ^^^^^^^^^^^^^^^^^^^^^^^^^^^^^^^^^^^^^^^^^^^^^^^^^^^^
  File "C:\Users\sunny\anaconda3\envs\myenv311test\Lib\site-packages\requests\api.py", line 59, in request
    return session.request(method=method, url=url, **kwargs)
           ^^^^^^^^^^^^^^^^^^^^^^^^^^^^^^^^^^^^^^^^^^^^^^^^^
  File "C:\Users\sunny\anaconda3\envs\myenv311test\Lib\site-packages\requests\sessions.py", line 589, in request
    resp = self.send(prep, **send_kwargs)
           ^^^^^^^^^^^^^^^^^^^^^^^^^^^^^^
  File "C:\Users\sunny\anaconda3\envs\myenv311test\Lib\site-packages\requests\sessions.py", line 703, in send
    r = adapter.send(request, **kwargs)
        ^^^^^^^^^^^^^^^^^^^^^^^^^^^^^^^
  File "C:\Users\sunny\anaconda3\envs\myenv311test\Lib\site-packages\requests\adapters.py", line 519, in send
    raise ConnectionError(e, request=request)
requests.exceptions.ConnectionError: HTTPSConnectionPool(host='api.ig.com', port=443): Max retries exceeded with url: /gateway/deal/session (Caused by NameResolutionError("<urllib3.connection.HTTPSConnection object at 0x000001F59587F290>: Failed to resolve 'api.ig.com' ([Errno 11001] getaddrinfo failed)"))
2024-03-23 09:26:00,055 - INFO - Inside the procedure sequence
2024-03-23 09:26:00,091 - ERROR - Job "run_procedure_sequence (trigger: interval[0:05:00], next run at: 2024-03-23 09:31:00 GMT)" raised an exception
Traceback (most recent call last):
  File "C:\Users\sunny\anaconda3\envs\myenv311test\Lib\site-packages\urllib3\connection.py", line 203, in _new_conn
    sock = connection.create_connection(
           ^^^^^^^^^^^^^^^^^^^^^^^^^^^^^
  File "C:\Users\sunny\anaconda3\envs\myenv311test\Lib\site-packages\urllib3\util\connection.py", line 60, in create_connection
    for res in socket.getaddrinfo(host, port, family, socket.SOCK_STREAM):
               ^^^^^^^^^^^^^^^^^^^^^^^^^^^^^^^^^^^^^^^^^^^^^^^^^^^^^^^^^^
  File "C:\Users\sunny\anaconda3\envs\myenv311test\Lib\socket.py", line 962, in getaddrinfo
    for res in _socket.getaddrinfo(host, port, family, type, proto, flags):
               ^^^^^^^^^^^^^^^^^^^^^^^^^^^^^^^^^^^^^^^^^^^^^^^^^^^^^^^^^^^
socket.gaierror: [Errno 11001] getaddrinfo failed

The above exception was the direct cause of the following exception:

Traceback (most recent call last):
  File "C:\Users\sunny\anaconda3\envs\myenv311test\Lib\site-packages\urllib3\connectionpool.py", line 790, in urlopen
    response = self._make_request(
               ^^^^^^^^^^^^^^^^^^^
  File "C:\Users\sunny\anaconda3\envs\myenv311test\Lib\site-packages\urllib3\connectionpool.py", line 491, in _make_request
    raise new_e
  File "C:\Users\sunny\anaconda3\envs\myenv311test\Lib\site-packages\urllib3\connectionpool.py", line 467, in _make_request
    self._validate_conn(conn)
  File "C:\Users\sunny\anaconda3\envs\myenv311test\Lib\site-packages\urllib3\connectionpool.py", line 1096, in _validate_conn
    conn.connect()
  File "C:\Users\sunny\anaconda3\envs\myenv311test\Lib\site-packages\urllib3\connection.py", line 611, in connect
    self.sock = sock = self._new_conn()
                       ^^^^^^^^^^^^^^^^
  File "C:\Users\sunny\anaconda3\envs\myenv311test\Lib\site-packages\urllib3\connection.py", line 210, in _new_conn
    raise NameResolutionError(self.host, self, e) from e
urllib3.exceptions.NameResolutionError: <urllib3.connection.HTTPSConnection object at 0x000001FFA3369ED0>: Failed to resolve 'api.ig.com' ([Errno 11001] getaddrinfo failed)

The above exception was the direct cause of the following exception:

Traceback (most recent call last):
  File "C:\Users\sunny\anaconda3\envs\myenv311test\Lib\site-packages\requests\adapters.py", line 486, in send
    resp = conn.urlopen(
           ^^^^^^^^^^^^^
  File "C:\Users\sunny\anaconda3\envs\myenv311test\Lib\site-packages\urllib3\connectionpool.py", line 844, in urlopen
    retries = retries.increment(
              ^^^^^^^^^^^^^^^^^^
  File "C:\Users\sunny\anaconda3\envs\myenv311test\Lib\site-packages\urllib3\util\retry.py", line 515, in increment
    raise MaxRetryError(_pool, url, reason) from reason  # type: ignore[arg-type]
    ^^^^^^^^^^^^^^^^^^^^^^^^^^^^^^^^^^^^^^^^^^^^^^^^^^^
urllib3.exceptions.MaxRetryError: HTTPSConnectionPool(host='api.ig.com', port=443): Max retries exceeded with url: /gateway/deal/session (Caused by NameResolutionError("<urllib3.connection.HTTPSConnection object at 0x000001FFA3369ED0>: Failed to resolve 'api.ig.com' ([Errno 11001] getaddrinfo failed)"))

During handling of the above exception, another exception occurred:

Traceback (most recent call last):
  File "C:\Users\sunny\anaconda3\envs\myenv311test\Lib\site-packages\apscheduler\executors\base.py", line 125, in run_job
    retval = job.func(*job.args, **job.kwargs)
             ^^^^^^^^^^^^^^^^^^^^^^^^^^^^^^^^^
  File "C:\Users\sunny\Desktop\Development\python\TradePro\prices\updater.py", line 54, in run_procedure_sequence
    run_IG(ticker)
  File "C:\Users\sunny\Desktop\Development\python\TradePro\prices\IG_session\run_IG.py", line 144, in run_IG
    ig_service.create_session()
  File "C:\Users\sunny\Desktop\Development\python\TradePro\prices\IG_session\ig_service.py", line 392, in create_session
    response = requests.post(self.BASE_URL  + '/session', data=json.dumps(params), headers=self.BASIC_HEADERS)
               ^^^^^^^^^^^^^^^^^^^^^^^^^^^^^^^^^^^^^^^^^^^^^^^^^^^^^^^^^^^^^^^^^^^^^^^^^^^^^^^^^^^^^^^^^^^^^^^
  File "C:\Users\sunny\anaconda3\envs\myenv311test\Lib\site-packages\requests\api.py", line 115, in post
    return request("post", url, data=data, json=json, **kwargs)
           ^^^^^^^^^^^^^^^^^^^^^^^^^^^^^^^^^^^^^^^^^^^^^^^^^^^^
  File "C:\Users\sunny\anaconda3\envs\myenv311test\Lib\site-packages\requests\api.py", line 59, in request
    return session.request(method=method, url=url, **kwargs)
           ^^^^^^^^^^^^^^^^^^^^^^^^^^^^^^^^^^^^^^^^^^^^^^^^^
  File "C:\Users\sunny\anaconda3\envs\myenv311test\Lib\site-packages\requests\sessions.py", line 589, in request
    resp = self.send(prep, **send_kwargs)
           ^^^^^^^^^^^^^^^^^^^^^^^^^^^^^^
  File "C:\Users\sunny\anaconda3\envs\myenv311test\Lib\site-packages\requests\sessions.py", line 703, in send
    r = adapter.send(request, **kwargs)
        ^^^^^^^^^^^^^^^^^^^^^^^^^^^^^^^
  File "C:\Users\sunny\anaconda3\envs\myenv311test\Lib\site-packages\requests\adapters.py", line 519, in send
    raise ConnectionError(e, request=request)
requests.exceptions.ConnectionError: HTTPSConnectionPool(host='api.ig.com', port=443): Max retries exceeded with url: /gateway/deal/session (Caused by NameResolutionError("<urllib3.connection.HTTPSConnection object at 0x000001FFA3369ED0>: Failed to resolve 'api.ig.com' ([Errno 11001] getaddrinfo failed)"))
2024-03-23 09:28:01,756 - INFO - Starting scheduler
2024-03-23 09:28:01,757 - INFO - Updater date and time: 2024-03-23 09:28:01.757123
2024-03-23 09:28:01,758 - INFO - Adding job tentatively -- it will be properly scheduled when the scheduler starts
2024-03-23 09:28:01,758 - INFO - Added job "run_procedure_sequence" to job store "default"
2024-03-23 09:28:01,758 - INFO - Scheduler started
2024-03-23 09:28:01,759 - INFO - Ending scheduler
2024-03-23 09:28:03,558 - INFO - Starting scheduler
2024-03-23 09:28:03,558 - INFO - Updater date and time: 2024-03-23 09:28:03.558605
2024-03-23 09:28:03,558 - INFO - Adding job tentatively -- it will be properly scheduled when the scheduler starts
2024-03-23 09:28:03,558 - INFO - Added job "run_procedure_sequence" to job store "default"
2024-03-23 09:28:03,558 - INFO - Scheduler started
2024-03-23 09:28:03,558 - INFO - Ending scheduler
2024-03-23 09:28:03,574 - INFO - Watching for file changes with StatReloader
2024-03-23 09:42:25,445 - INFO - Starting scheduler
2024-03-23 09:42:25,445 - INFO - Updater date and time: 2024-03-23 09:42:25.445533
2024-03-23 09:42:25,445 - INFO - Adding job tentatively -- it will be properly scheduled when the scheduler starts
2024-03-23 09:42:25,445 - INFO - Added job "run_procedure_sequence" to job store "default"
2024-03-23 09:42:25,445 - INFO - Scheduler started
2024-03-23 09:42:25,445 - INFO - Ending scheduler
2024-03-23 09:42:27,167 - INFO - Starting scheduler
2024-03-23 09:42:27,167 - INFO - Updater date and time: 2024-03-23 09:42:27.167659
2024-03-23 09:42:27,167 - INFO - Adding job tentatively -- it will be properly scheduled when the scheduler starts
2024-03-23 09:42:27,167 - INFO - Added job "run_procedure_sequence" to job store "default"
2024-03-23 09:42:27,167 - INFO - Scheduler started
2024-03-23 09:42:27,176 - INFO - Ending scheduler
2024-03-23 09:42:27,191 - INFO - Watching for file changes with StatReloader
2024-03-23 09:42:30,433 - ERROR - Internal Server Error: /ml_models/ml-report/
Traceback (most recent call last):
  File "C:\Users\sunny\anaconda3\envs\myenv311test\Lib\site-packages\django\core\handlers\exception.py", line 55, in inner
    response = get_response(request)
               ^^^^^^^^^^^^^^^^^^^^^
  File "C:\Users\sunny\anaconda3\envs\myenv311test\Lib\site-packages\django\core\handlers\base.py", line 197, in _get_response
    response = wrapped_callback(request, *callback_args, **callback_kwargs)
               ^^^^^^^^^^^^^^^^^^^^^^^^^^^^^^^^^^^^^^^^^^^^^^^^^^^^^^^^^^^^
  File "C:\Users\sunny\Desktop\Development\python\TradePro\ml_models\views.py", line 156, in ml_report
    X_live = dp.historical_record(4)
             ^^^^^^^^^^^^^^^^^^^^
AttributeError: 'NoneType' object has no attribute 'historical_record'
2024-03-23 09:46:00,007 - INFO - Running job "run_procedure_sequence (trigger: interval[0:05:00], next run at: 2024-03-23 09:46:00 GMT)" (scheduled at 2024-03-23 09:46:00+00:00)
2024-03-23 09:46:00,007 - INFO - Running job "run_procedure_sequence (trigger: interval[0:05:00], next run at: 2024-03-23 09:46:00 GMT)" (scheduled at 2024-03-23 09:46:00+00:00)
2024-03-23 09:46:00,008 - INFO - Inside the procedure sequence
2024-03-23 09:46:00,008 - INFO - Inside the procedure sequence
2024-03-23 09:46:00,027 - ERROR - Job "run_procedure_sequence (trigger: interval[0:05:00], next run at: 2024-03-23 09:51:00 GMT)" raised an exception
Traceback (most recent call last):
  File "C:\Users\sunny\anaconda3\envs\myenv311test\Lib\site-packages\urllib3\connection.py", line 203, in _new_conn
    sock = connection.create_connection(
           ^^^^^^^^^^^^^^^^^^^^^^^^^^^^^
  File "C:\Users\sunny\anaconda3\envs\myenv311test\Lib\site-packages\urllib3\util\connection.py", line 60, in create_connection
    for res in socket.getaddrinfo(host, port, family, socket.SOCK_STREAM):
               ^^^^^^^^^^^^^^^^^^^^^^^^^^^^^^^^^^^^^^^^^^^^^^^^^^^^^^^^^^
  File "C:\Users\sunny\anaconda3\envs\myenv311test\Lib\socket.py", line 962, in getaddrinfo
    for res in _socket.getaddrinfo(host, port, family, type, proto, flags):
               ^^^^^^^^^^^^^^^^^^^^^^^^^^^^^^^^^^^^^^^^^^^^^^^^^^^^^^^^^^^
socket.gaierror: [Errno 11001] getaddrinfo failed

The above exception was the direct cause of the following exception:

Traceback (most recent call last):
  File "C:\Users\sunny\anaconda3\envs\myenv311test\Lib\site-packages\urllib3\connectionpool.py", line 790, in urlopen
    response = self._make_request(
               ^^^^^^^^^^^^^^^^^^^
  File "C:\Users\sunny\anaconda3\envs\myenv311test\Lib\site-packages\urllib3\connectionpool.py", line 491, in _make_request
    raise new_e
  File "C:\Users\sunny\anaconda3\envs\myenv311test\Lib\site-packages\urllib3\connectionpool.py", line 467, in _make_request
    self._validate_conn(conn)
  File "C:\Users\sunny\anaconda3\envs\myenv311test\Lib\site-packages\urllib3\connectionpool.py", line 1096, in _validate_conn
    conn.connect()
  File "C:\Users\sunny\anaconda3\envs\myenv311test\Lib\site-packages\urllib3\connection.py", line 611, in connect
    self.sock = sock = self._new_conn()
                       ^^^^^^^^^^^^^^^^
  File "C:\Users\sunny\anaconda3\envs\myenv311test\Lib\site-packages\urllib3\connection.py", line 210, in _new_conn
    raise NameResolutionError(self.host, self, e) from e
urllib3.exceptions.NameResolutionError: <urllib3.connection.HTTPSConnection object at 0x00000264458D2E10>: Failed to resolve 'api.ig.com' ([Errno 11001] getaddrinfo failed)

The above exception was the direct cause of the following exception:

Traceback (most recent call last):
  File "C:\Users\sunny\anaconda3\envs\myenv311test\Lib\site-packages\requests\adapters.py", line 486, in send
    resp = conn.urlopen(
           ^^^^^^^^^^^^^
  File "C:\Users\sunny\anaconda3\envs\myenv311test\Lib\site-packages\urllib3\connectionpool.py", line 844, in urlopen
    retries = retries.increment(
              ^^^^^^^^^^^^^^^^^^
  File "C:\Users\sunny\anaconda3\envs\myenv311test\Lib\site-packages\urllib3\util\retry.py", line 515, in increment
    raise MaxRetryError(_pool, url, reason) from reason  # type: ignore[arg-type]
    ^^^^^^^^^^^^^^^^^^^^^^^^^^^^^^^^^^^^^^^^^^^^^^^^^^^
urllib3.exceptions.MaxRetryError: HTTPSConnectionPool(host='api.ig.com', port=443): Max retries exceeded with url: /gateway/deal/session (Caused by NameResolutionError("<urllib3.connection.HTTPSConnection object at 0x00000264458D2E10>: Failed to resolve 'api.ig.com' ([Errno 11001] getaddrinfo failed)"))

During handling of the above exception, another exception occurred:

Traceback (most recent call last):
  File "C:\Users\sunny\anaconda3\envs\myenv311test\Lib\site-packages\apscheduler\executors\base.py", line 125, in run_job
    retval = job.func(*job.args, **job.kwargs)
             ^^^^^^^^^^^^^^^^^^^^^^^^^^^^^^^^^
  File "C:\Users\sunny\Desktop\Development\python\TradePro\prices\updater.py", line 54, in run_procedure_sequence
    run_IG(ticker)
  File "C:\Users\sunny\Desktop\Development\python\TradePro\prices\IG_session\run_IG.py", line 144, in run_IG
    ig_service.create_session()
  File "C:\Users\sunny\Desktop\Development\python\TradePro\prices\IG_session\ig_service.py", line 392, in create_session
    response = requests.post(self.BASE_URL  + '/session', data=json.dumps(params), headers=self.BASIC_HEADERS)
               ^^^^^^^^^^^^^^^^^^^^^^^^^^^^^^^^^^^^^^^^^^^^^^^^^^^^^^^^^^^^^^^^^^^^^^^^^^^^^^^^^^^^^^^^^^^^^^^
  File "C:\Users\sunny\anaconda3\envs\myenv311test\Lib\site-packages\requests\api.py", line 115, in post
    return request("post", url, data=data, json=json, **kwargs)
           ^^^^^^^^^^^^^^^^^^^^^^^^^^^^^^^^^^^^^^^^^^^^^^^^^^^^
  File "C:\Users\sunny\anaconda3\envs\myenv311test\Lib\site-packages\requests\api.py", line 59, in request
    return session.request(method=method, url=url, **kwargs)
           ^^^^^^^^^^^^^^^^^^^^^^^^^^^^^^^^^^^^^^^^^^^^^^^^^
  File "C:\Users\sunny\anaconda3\envs\myenv311test\Lib\site-packages\requests\sessions.py", line 589, in request
    resp = self.send(prep, **send_kwargs)
           ^^^^^^^^^^^^^^^^^^^^^^^^^^^^^^
  File "C:\Users\sunny\anaconda3\envs\myenv311test\Lib\site-packages\requests\sessions.py", line 703, in send
    r = adapter.send(request, **kwargs)
        ^^^^^^^^^^^^^^^^^^^^^^^^^^^^^^^
  File "C:\Users\sunny\anaconda3\envs\myenv311test\Lib\site-packages\requests\adapters.py", line 519, in send
    raise ConnectionError(e, request=request)
requests.exceptions.ConnectionError: HTTPSConnectionPool(host='api.ig.com', port=443): Max retries exceeded with url: /gateway/deal/session (Caused by NameResolutionError("<urllib3.connection.HTTPSConnection object at 0x00000264458D2E10>: Failed to resolve 'api.ig.com' ([Errno 11001] getaddrinfo failed)"))
2024-03-23 09:46:00,027 - ERROR - Job "run_procedure_sequence (trigger: interval[0:05:00], next run at: 2024-03-23 09:51:00 GMT)" raised an exception
Traceback (most recent call last):
  File "C:\Users\sunny\anaconda3\envs\myenv311test\Lib\site-packages\urllib3\connection.py", line 203, in _new_conn
    sock = connection.create_connection(
           ^^^^^^^^^^^^^^^^^^^^^^^^^^^^^
  File "C:\Users\sunny\anaconda3\envs\myenv311test\Lib\site-packages\urllib3\util\connection.py", line 60, in create_connection
    for res in socket.getaddrinfo(host, port, family, socket.SOCK_STREAM):
               ^^^^^^^^^^^^^^^^^^^^^^^^^^^^^^^^^^^^^^^^^^^^^^^^^^^^^^^^^^
  File "C:\Users\sunny\anaconda3\envs\myenv311test\Lib\socket.py", line 962, in getaddrinfo
    for res in _socket.getaddrinfo(host, port, family, type, proto, flags):
               ^^^^^^^^^^^^^^^^^^^^^^^^^^^^^^^^^^^^^^^^^^^^^^^^^^^^^^^^^^^
socket.gaierror: [Errno 11001] getaddrinfo failed

The above exception was the direct cause of the following exception:

Traceback (most recent call last):
  File "C:\Users\sunny\anaconda3\envs\myenv311test\Lib\site-packages\urllib3\connectionpool.py", line 790, in urlopen
    response = self._make_request(
               ^^^^^^^^^^^^^^^^^^^
  File "C:\Users\sunny\anaconda3\envs\myenv311test\Lib\site-packages\urllib3\connectionpool.py", line 491, in _make_request
    raise new_e
  File "C:\Users\sunny\anaconda3\envs\myenv311test\Lib\site-packages\urllib3\connectionpool.py", line 467, in _make_request
    self._validate_conn(conn)
  File "C:\Users\sunny\anaconda3\envs\myenv311test\Lib\site-packages\urllib3\connectionpool.py", line 1096, in _validate_conn
    conn.connect()
  File "C:\Users\sunny\anaconda3\envs\myenv311test\Lib\site-packages\urllib3\connection.py", line 611, in connect
    self.sock = sock = self._new_conn()
                       ^^^^^^^^^^^^^^^^
  File "C:\Users\sunny\anaconda3\envs\myenv311test\Lib\site-packages\urllib3\connection.py", line 210, in _new_conn
    raise NameResolutionError(self.host, self, e) from e
urllib3.exceptions.NameResolutionError: <urllib3.connection.HTTPSConnection object at 0x000002EB791661D0>: Failed to resolve 'api.ig.com' ([Errno 11001] getaddrinfo failed)

The above exception was the direct cause of the following exception:

Traceback (most recent call last):
  File "C:\Users\sunny\anaconda3\envs\myenv311test\Lib\site-packages\requests\adapters.py", line 486, in send
    resp = conn.urlopen(
           ^^^^^^^^^^^^^
  File "C:\Users\sunny\anaconda3\envs\myenv311test\Lib\site-packages\urllib3\connectionpool.py", line 844, in urlopen
    retries = retries.increment(
              ^^^^^^^^^^^^^^^^^^
  File "C:\Users\sunny\anaconda3\envs\myenv311test\Lib\site-packages\urllib3\util\retry.py", line 515, in increment
    raise MaxRetryError(_pool, url, reason) from reason  # type: ignore[arg-type]
    ^^^^^^^^^^^^^^^^^^^^^^^^^^^^^^^^^^^^^^^^^^^^^^^^^^^
urllib3.exceptions.MaxRetryError: HTTPSConnectionPool(host='api.ig.com', port=443): Max retries exceeded with url: /gateway/deal/session (Caused by NameResolutionError("<urllib3.connection.HTTPSConnection object at 0x000002EB791661D0>: Failed to resolve 'api.ig.com' ([Errno 11001] getaddrinfo failed)"))

During handling of the above exception, another exception occurred:

Traceback (most recent call last):
  File "C:\Users\sunny\anaconda3\envs\myenv311test\Lib\site-packages\apscheduler\executors\base.py", line 125, in run_job
    retval = job.func(*job.args, **job.kwargs)
             ^^^^^^^^^^^^^^^^^^^^^^^^^^^^^^^^^
  File "C:\Users\sunny\Desktop\Development\python\TradePro\prices\updater.py", line 54, in run_procedure_sequence
    run_IG(ticker)
  File "C:\Users\sunny\Desktop\Development\python\TradePro\prices\IG_session\run_IG.py", line 144, in run_IG
    ig_service.create_session()
  File "C:\Users\sunny\Desktop\Development\python\TradePro\prices\IG_session\ig_service.py", line 392, in create_session
    response = requests.post(self.BASE_URL  + '/session', data=json.dumps(params), headers=self.BASIC_HEADERS)
               ^^^^^^^^^^^^^^^^^^^^^^^^^^^^^^^^^^^^^^^^^^^^^^^^^^^^^^^^^^^^^^^^^^^^^^^^^^^^^^^^^^^^^^^^^^^^^^^
  File "C:\Users\sunny\anaconda3\envs\myenv311test\Lib\site-packages\requests\api.py", line 115, in post
    return request("post", url, data=data, json=json, **kwargs)
           ^^^^^^^^^^^^^^^^^^^^^^^^^^^^^^^^^^^^^^^^^^^^^^^^^^^^
  File "C:\Users\sunny\anaconda3\envs\myenv311test\Lib\site-packages\requests\api.py", line 59, in request
    return session.request(method=method, url=url, **kwargs)
           ^^^^^^^^^^^^^^^^^^^^^^^^^^^^^^^^^^^^^^^^^^^^^^^^^
  File "C:\Users\sunny\anaconda3\envs\myenv311test\Lib\site-packages\requests\sessions.py", line 589, in request
    resp = self.send(prep, **send_kwargs)
           ^^^^^^^^^^^^^^^^^^^^^^^^^^^^^^
  File "C:\Users\sunny\anaconda3\envs\myenv311test\Lib\site-packages\requests\sessions.py", line 703, in send
    r = adapter.send(request, **kwargs)
        ^^^^^^^^^^^^^^^^^^^^^^^^^^^^^^^
  File "C:\Users\sunny\anaconda3\envs\myenv311test\Lib\site-packages\requests\adapters.py", line 519, in send
    raise ConnectionError(e, request=request)
requests.exceptions.ConnectionError: HTTPSConnectionPool(host='api.ig.com', port=443): Max retries exceeded with url: /gateway/deal/session (Caused by NameResolutionError("<urllib3.connection.HTTPSConnection object at 0x000002EB791661D0>: Failed to resolve 'api.ig.com' ([Errno 11001] getaddrinfo failed)"))
2024-03-23 09:46:29,246 - INFO - C:\Users\sunny\Desktop\Development\python\TradePro\ml_models\views.py changed, reloading.
2024-03-23 09:46:31,314 - INFO - Starting scheduler
2024-03-23 09:46:31,314 - INFO - Updater date and time: 2024-03-23 09:46:31.314236
2024-03-23 09:46:31,314 - INFO - Adding job tentatively -- it will be properly scheduled when the scheduler starts
2024-03-23 09:46:31,314 - INFO - Added job "run_procedure_sequence" to job store "default"
2024-03-23 09:46:31,314 - INFO - Scheduler started
2024-03-23 09:46:31,314 - INFO - Ending scheduler
2024-03-23 09:46:31,329 - INFO - Watching for file changes with StatReloader
2024-03-23 09:46:46,837 - INFO - C:\Users\sunny\Desktop\Development\python\TradePro\ml_models\views.py changed, reloading.
2024-03-23 09:46:48,952 - INFO - Starting scheduler
2024-03-23 09:46:48,953 - INFO - Updater date and time: 2024-03-23 09:46:48.953186
2024-03-23 09:46:48,954 - INFO - Adding job tentatively -- it will be properly scheduled when the scheduler starts
2024-03-23 09:46:48,954 - INFO - Added job "run_procedure_sequence" to job store "default"
2024-03-23 09:46:48,954 - INFO - Scheduler started
2024-03-23 09:46:48,955 - INFO - Ending scheduler
2024-03-23 09:46:48,973 - INFO - Watching for file changes with StatReloader
2024-03-23 09:46:52,885 - ERROR - Internal Server Error: /ml_models/ml-report/
Traceback (most recent call last):
  File "C:\Users\sunny\anaconda3\envs\myenv311test\Lib\site-packages\django\core\handlers\exception.py", line 55, in inner
    response = get_response(request)
               ^^^^^^^^^^^^^^^^^^^^^
  File "C:\Users\sunny\anaconda3\envs\myenv311test\Lib\site-packages\django\core\handlers\base.py", line 197, in _get_response
    response = wrapped_callback(request, *callback_args, **callback_kwargs)
               ^^^^^^^^^^^^^^^^^^^^^^^^^^^^^^^^^^^^^^^^^^^^^^^^^^^^^^^^^^^^
  File "C:\Users\sunny\Desktop\Development\python\TradePro\ml_models\views.py", line 158, in ml_report
    X_live = dp.historical_record(4)
             ^^^^^^^^^^^^^^^^^^^^
AttributeError: 'NoneType' object has no attribute 'historical_record'
2024-03-23 11:35:25,373 - INFO - Starting scheduler
2024-03-23 11:35:25,373 - INFO - Updater date and time: 2024-03-23 11:35:25.373951
2024-03-23 11:35:25,373 - INFO - Adding job tentatively -- it will be properly scheduled when the scheduler starts
2024-03-23 11:35:25,373 - INFO - Added job "run_procedure_sequence" to job store "default"
2024-03-23 11:35:25,373 - INFO - Scheduler started
2024-03-23 11:35:25,373 - INFO - Ending scheduler
2024-03-23 11:35:27,167 - INFO - Starting scheduler
2024-03-23 11:35:27,167 - INFO - Updater date and time: 2024-03-23 11:35:27.167510
2024-03-23 11:35:27,183 - INFO - Adding job tentatively -- it will be properly scheduled when the scheduler starts
2024-03-23 11:35:27,183 - INFO - Added job "run_procedure_sequence" to job store "default"
2024-03-23 11:35:27,183 - INFO - Scheduler started
2024-03-23 11:35:27,183 - INFO - Ending scheduler
2024-03-23 11:35:27,204 - INFO - Watching for file changes with StatReloader
2024-03-23 11:35:29,292 - WARNING - Not Found: /images/favicon.ico
2024-03-23 11:35:36,921 - WARNING - Not Found: /ml_models/ml-report/images/favicon.ico
2024-03-23 11:36:00,004 - INFO - Running job "run_procedure_sequence (trigger: interval[0:05:00], next run at: 2024-03-23 11:36:00 GMT)" (scheduled at 2024-03-23 11:36:00+00:00)
2024-03-23 11:36:00,004 - INFO - Inside the procedure sequence
2024-03-23 11:36:00,011 - INFO - Running job "run_procedure_sequence (trigger: interval[0:05:00], next run at: 2024-03-23 11:36:00 GMT)" (scheduled at 2024-03-23 11:36:00+00:00)
2024-03-23 11:36:00,011 - INFO - Inside the procedure sequence
2024-03-23 11:36:00,014 - ERROR - Job "run_procedure_sequence (trigger: interval[0:05:00], next run at: 2024-03-23 11:41:00 GMT)" raised an exception
Traceback (most recent call last):
  File "C:\Users\sunny\anaconda3\envs\myenv311test\Lib\site-packages\urllib3\connection.py", line 203, in _new_conn
    sock = connection.create_connection(
           ^^^^^^^^^^^^^^^^^^^^^^^^^^^^^
  File "C:\Users\sunny\anaconda3\envs\myenv311test\Lib\site-packages\urllib3\util\connection.py", line 60, in create_connection
    for res in socket.getaddrinfo(host, port, family, socket.SOCK_STREAM):
               ^^^^^^^^^^^^^^^^^^^^^^^^^^^^^^^^^^^^^^^^^^^^^^^^^^^^^^^^^^
  File "C:\Users\sunny\anaconda3\envs\myenv311test\Lib\socket.py", line 962, in getaddrinfo
    for res in _socket.getaddrinfo(host, port, family, type, proto, flags):
               ^^^^^^^^^^^^^^^^^^^^^^^^^^^^^^^^^^^^^^^^^^^^^^^^^^^^^^^^^^^
socket.gaierror: [Errno 11001] getaddrinfo failed

The above exception was the direct cause of the following exception:

Traceback (most recent call last):
  File "C:\Users\sunny\anaconda3\envs\myenv311test\Lib\site-packages\urllib3\connectionpool.py", line 790, in urlopen
    response = self._make_request(
               ^^^^^^^^^^^^^^^^^^^
  File "C:\Users\sunny\anaconda3\envs\myenv311test\Lib\site-packages\urllib3\connectionpool.py", line 491, in _make_request
    raise new_e
  File "C:\Users\sunny\anaconda3\envs\myenv311test\Lib\site-packages\urllib3\connectionpool.py", line 467, in _make_request
    self._validate_conn(conn)
  File "C:\Users\sunny\anaconda3\envs\myenv311test\Lib\site-packages\urllib3\connectionpool.py", line 1096, in _validate_conn
    conn.connect()
  File "C:\Users\sunny\anaconda3\envs\myenv311test\Lib\site-packages\urllib3\connection.py", line 611, in connect
    self.sock = sock = self._new_conn()
                       ^^^^^^^^^^^^^^^^
  File "C:\Users\sunny\anaconda3\envs\myenv311test\Lib\site-packages\urllib3\connection.py", line 210, in _new_conn
    raise NameResolutionError(self.host, self, e) from e
urllib3.exceptions.NameResolutionError: <urllib3.connection.HTTPSConnection object at 0x0000028B9CEE1E10>: Failed to resolve 'api.ig.com' ([Errno 11001] getaddrinfo failed)

The above exception was the direct cause of the following exception:

Traceback (most recent call last):
  File "C:\Users\sunny\anaconda3\envs\myenv311test\Lib\site-packages\requests\adapters.py", line 486, in send
    resp = conn.urlopen(
           ^^^^^^^^^^^^^
  File "C:\Users\sunny\anaconda3\envs\myenv311test\Lib\site-packages\urllib3\connectionpool.py", line 844, in urlopen
    retries = retries.increment(
              ^^^^^^^^^^^^^^^^^^
  File "C:\Users\sunny\anaconda3\envs\myenv311test\Lib\site-packages\urllib3\util\retry.py", line 515, in increment
    raise MaxRetryError(_pool, url, reason) from reason  # type: ignore[arg-type]
    ^^^^^^^^^^^^^^^^^^^^^^^^^^^^^^^^^^^^^^^^^^^^^^^^^^^
urllib3.exceptions.MaxRetryError: HTTPSConnectionPool(host='api.ig.com', port=443): Max retries exceeded with url: /gateway/deal/session (Caused by NameResolutionError("<urllib3.connection.HTTPSConnection object at 0x0000028B9CEE1E10>: Failed to resolve 'api.ig.com' ([Errno 11001] getaddrinfo failed)"))

During handling of the above exception, another exception occurred:

Traceback (most recent call last):
  File "C:\Users\sunny\anaconda3\envs\myenv311test\Lib\site-packages\apscheduler\executors\base.py", line 125, in run_job
    retval = job.func(*job.args, **job.kwargs)
             ^^^^^^^^^^^^^^^^^^^^^^^^^^^^^^^^^
  File "C:\Users\sunny\Desktop\Development\python\TradePro\prices\updater.py", line 54, in run_procedure_sequence
    run_IG(ticker)
  File "C:\Users\sunny\Desktop\Development\python\TradePro\prices\IG_session\run_IG.py", line 144, in run_IG
    ig_service.create_session()
  File "C:\Users\sunny\Desktop\Development\python\TradePro\prices\IG_session\ig_service.py", line 392, in create_session
    response = requests.post(self.BASE_URL  + '/session', data=json.dumps(params), headers=self.BASIC_HEADERS)
               ^^^^^^^^^^^^^^^^^^^^^^^^^^^^^^^^^^^^^^^^^^^^^^^^^^^^^^^^^^^^^^^^^^^^^^^^^^^^^^^^^^^^^^^^^^^^^^^
  File "C:\Users\sunny\anaconda3\envs\myenv311test\Lib\site-packages\requests\api.py", line 115, in post
    return request("post", url, data=data, json=json, **kwargs)
           ^^^^^^^^^^^^^^^^^^^^^^^^^^^^^^^^^^^^^^^^^^^^^^^^^^^^
  File "C:\Users\sunny\anaconda3\envs\myenv311test\Lib\site-packages\requests\api.py", line 59, in request
    return session.request(method=method, url=url, **kwargs)
           ^^^^^^^^^^^^^^^^^^^^^^^^^^^^^^^^^^^^^^^^^^^^^^^^^
  File "C:\Users\sunny\anaconda3\envs\myenv311test\Lib\site-packages\requests\sessions.py", line 589, in request
    resp = self.send(prep, **send_kwargs)
           ^^^^^^^^^^^^^^^^^^^^^^^^^^^^^^
  File "C:\Users\sunny\anaconda3\envs\myenv311test\Lib\site-packages\requests\sessions.py", line 703, in send
    r = adapter.send(request, **kwargs)
        ^^^^^^^^^^^^^^^^^^^^^^^^^^^^^^^
  File "C:\Users\sunny\anaconda3\envs\myenv311test\Lib\site-packages\requests\adapters.py", line 519, in send
    raise ConnectionError(e, request=request)
requests.exceptions.ConnectionError: HTTPSConnectionPool(host='api.ig.com', port=443): Max retries exceeded with url: /gateway/deal/session (Caused by NameResolutionError("<urllib3.connection.HTTPSConnection object at 0x0000028B9CEE1E10>: Failed to resolve 'api.ig.com' ([Errno 11001] getaddrinfo failed)"))
2024-03-23 11:36:00,021 - ERROR - Job "run_procedure_sequence (trigger: interval[0:05:00], next run at: 2024-03-23 11:41:00 GMT)" raised an exception
Traceback (most recent call last):
  File "C:\Users\sunny\anaconda3\envs\myenv311test\Lib\site-packages\urllib3\connection.py", line 203, in _new_conn
    sock = connection.create_connection(
           ^^^^^^^^^^^^^^^^^^^^^^^^^^^^^
  File "C:\Users\sunny\anaconda3\envs\myenv311test\Lib\site-packages\urllib3\util\connection.py", line 60, in create_connection
    for res in socket.getaddrinfo(host, port, family, socket.SOCK_STREAM):
               ^^^^^^^^^^^^^^^^^^^^^^^^^^^^^^^^^^^^^^^^^^^^^^^^^^^^^^^^^^
  File "C:\Users\sunny\anaconda3\envs\myenv311test\Lib\socket.py", line 962, in getaddrinfo
    for res in _socket.getaddrinfo(host, port, family, type, proto, flags):
               ^^^^^^^^^^^^^^^^^^^^^^^^^^^^^^^^^^^^^^^^^^^^^^^^^^^^^^^^^^^
socket.gaierror: [Errno 11001] getaddrinfo failed

The above exception was the direct cause of the following exception:

Traceback (most recent call last):
  File "C:\Users\sunny\anaconda3\envs\myenv311test\Lib\site-packages\urllib3\connectionpool.py", line 790, in urlopen
    response = self._make_request(
               ^^^^^^^^^^^^^^^^^^^
  File "C:\Users\sunny\anaconda3\envs\myenv311test\Lib\site-packages\urllib3\connectionpool.py", line 491, in _make_request
    raise new_e
  File "C:\Users\sunny\anaconda3\envs\myenv311test\Lib\site-packages\urllib3\connectionpool.py", line 467, in _make_request
    self._validate_conn(conn)
  File "C:\Users\sunny\anaconda3\envs\myenv311test\Lib\site-packages\urllib3\connectionpool.py", line 1096, in _validate_conn
    conn.connect()
  File "C:\Users\sunny\anaconda3\envs\myenv311test\Lib\site-packages\urllib3\connection.py", line 611, in connect
    self.sock = sock = self._new_conn()
                       ^^^^^^^^^^^^^^^^
  File "C:\Users\sunny\anaconda3\envs\myenv311test\Lib\site-packages\urllib3\connection.py", line 210, in _new_conn
    raise NameResolutionError(self.host, self, e) from e
urllib3.exceptions.NameResolutionError: <urllib3.connection.HTTPSConnection object at 0x0000021D46702FD0>: Failed to resolve 'api.ig.com' ([Errno 11001] getaddrinfo failed)

The above exception was the direct cause of the following exception:

Traceback (most recent call last):
  File "C:\Users\sunny\anaconda3\envs\myenv311test\Lib\site-packages\requests\adapters.py", line 486, in send
    resp = conn.urlopen(
           ^^^^^^^^^^^^^
  File "C:\Users\sunny\anaconda3\envs\myenv311test\Lib\site-packages\urllib3\connectionpool.py", line 844, in urlopen
    retries = retries.increment(
              ^^^^^^^^^^^^^^^^^^
  File "C:\Users\sunny\anaconda3\envs\myenv311test\Lib\site-packages\urllib3\util\retry.py", line 515, in increment
    raise MaxRetryError(_pool, url, reason) from reason  # type: ignore[arg-type]
    ^^^^^^^^^^^^^^^^^^^^^^^^^^^^^^^^^^^^^^^^^^^^^^^^^^^
urllib3.exceptions.MaxRetryError: HTTPSConnectionPool(host='api.ig.com', port=443): Max retries exceeded with url: /gateway/deal/session (Caused by NameResolutionError("<urllib3.connection.HTTPSConnection object at 0x0000021D46702FD0>: Failed to resolve 'api.ig.com' ([Errno 11001] getaddrinfo failed)"))

During handling of the above exception, another exception occurred:

Traceback (most recent call last):
  File "C:\Users\sunny\anaconda3\envs\myenv311test\Lib\site-packages\apscheduler\executors\base.py", line 125, in run_job
    retval = job.func(*job.args, **job.kwargs)
             ^^^^^^^^^^^^^^^^^^^^^^^^^^^^^^^^^
  File "C:\Users\sunny\Desktop\Development\python\TradePro\prices\updater.py", line 54, in run_procedure_sequence
    run_IG(ticker)
  File "C:\Users\sunny\Desktop\Development\python\TradePro\prices\IG_session\run_IG.py", line 144, in run_IG
    ig_service.create_session()
  File "C:\Users\sunny\Desktop\Development\python\TradePro\prices\IG_session\ig_service.py", line 392, in create_session
    response = requests.post(self.BASE_URL  + '/session', data=json.dumps(params), headers=self.BASIC_HEADERS)
               ^^^^^^^^^^^^^^^^^^^^^^^^^^^^^^^^^^^^^^^^^^^^^^^^^^^^^^^^^^^^^^^^^^^^^^^^^^^^^^^^^^^^^^^^^^^^^^^
  File "C:\Users\sunny\anaconda3\envs\myenv311test\Lib\site-packages\requests\api.py", line 115, in post
    return request("post", url, data=data, json=json, **kwargs)
           ^^^^^^^^^^^^^^^^^^^^^^^^^^^^^^^^^^^^^^^^^^^^^^^^^^^^
  File "C:\Users\sunny\anaconda3\envs\myenv311test\Lib\site-packages\requests\api.py", line 59, in request
    return session.request(method=method, url=url, **kwargs)
           ^^^^^^^^^^^^^^^^^^^^^^^^^^^^^^^^^^^^^^^^^^^^^^^^^
  File "C:\Users\sunny\anaconda3\envs\myenv311test\Lib\site-packages\requests\sessions.py", line 589, in request
    resp = self.send(prep, **send_kwargs)
           ^^^^^^^^^^^^^^^^^^^^^^^^^^^^^^
  File "C:\Users\sunny\anaconda3\envs\myenv311test\Lib\site-packages\requests\sessions.py", line 703, in send
    r = adapter.send(request, **kwargs)
        ^^^^^^^^^^^^^^^^^^^^^^^^^^^^^^^
  File "C:\Users\sunny\anaconda3\envs\myenv311test\Lib\site-packages\requests\adapters.py", line 519, in send
    raise ConnectionError(e, request=request)
requests.exceptions.ConnectionError: HTTPSConnectionPool(host='api.ig.com', port=443): Max retries exceeded with url: /gateway/deal/session (Caused by NameResolutionError("<urllib3.connection.HTTPSConnection object at 0x0000021D46702FD0>: Failed to resolve 'api.ig.com' ([Errno 11001] getaddrinfo failed)"))
2024-03-23 11:36:58,046 - INFO - Starting scheduler
2024-03-23 11:36:58,046 - INFO - Updater date and time: 2024-03-23 11:36:58.046799
2024-03-23 11:36:58,046 - INFO - Adding job tentatively -- it will be properly scheduled when the scheduler starts
2024-03-23 11:36:58,046 - INFO - Added job "run_procedure_sequence" to job store "default"
2024-03-23 11:36:58,046 - INFO - Scheduler started
2024-03-23 11:36:58,046 - INFO - Ending scheduler
2024-03-23 11:36:59,816 - INFO - Starting scheduler
2024-03-23 11:36:59,816 - INFO - Updater date and time: 2024-03-23 11:36:59.816129
2024-03-23 11:36:59,816 - INFO - Adding job tentatively -- it will be properly scheduled when the scheduler starts
2024-03-23 11:36:59,816 - INFO - Added job "run_procedure_sequence" to job store "default"
2024-03-23 11:36:59,816 - INFO - Scheduler started
2024-03-23 11:36:59,823 - INFO - Ending scheduler
2024-03-23 11:36:59,823 - INFO - Watching for file changes with StatReloader
2024-03-23 11:37:12,905 - WARNING - Not Found: /ml_models/ml-variability/images/favicon.ico
2024-03-23 11:37:22,741 - WARNING - Not Found: /tickers/images/favicon.ico
2024-03-23 11:37:24,055 - WARNING - Not Found: /profile/images/favicon.ico
2024-03-23 11:37:25,472 - ERROR - Internal Server Error: /ml_models/ml-manual/
Traceback (most recent call last):
  File "C:\Users\sunny\anaconda3\envs\myenv311test\Lib\site-packages\django\core\handlers\exception.py", line 55, in inner
    response = get_response(request)
               ^^^^^^^^^^^^^^^^^^^^^
  File "C:\Users\sunny\anaconda3\envs\myenv311test\Lib\site-packages\django\core\handlers\base.py", line 197, in _get_response
    response = wrapped_callback(request, *callback_args, **callback_kwargs)
               ^^^^^^^^^^^^^^^^^^^^^^^^^^^^^^^^^^^^^^^^^^^^^^^^^^^^^^^^^^^^
  File "C:\Users\sunny\Desktop\Development\python\TradePro\ml_models\views.py", line 337, in ml_manual
    last_price_stats = dp.stats_df_gen(prices_df,2)
                       ^^^^^^^^^^^^^^^
AttributeError: 'NoneType' object has no attribute 'stats_df_gen'
2024-03-23 11:37:25,579 - WARNING - Not Found: /favicon.ico
2024-03-23 16:19:16,767 - INFO - Starting scheduler
2024-03-23 16:19:16,767 - INFO - Updater date and time: 2024-03-23 16:19:16.767168
2024-03-23 16:19:16,768 - INFO - Adding job tentatively -- it will be properly scheduled when the scheduler starts
2024-03-23 16:19:16,768 - INFO - Added job "run_procedure_sequence" to job store "default"
2024-03-23 16:19:16,768 - INFO - Scheduler started
2024-03-23 16:19:16,768 - INFO - Ending scheduler
2024-03-23 16:19:18,546 - INFO - Starting scheduler
2024-03-23 16:19:18,546 - INFO - Updater date and time: 2024-03-23 16:19:18.546944
2024-03-23 16:19:18,546 - INFO - Adding job tentatively -- it will be properly scheduled when the scheduler starts
2024-03-23 16:19:18,546 - INFO - Added job "run_procedure_sequence" to job store "default"
2024-03-23 16:19:18,546 - INFO - Scheduler started
2024-03-23 16:19:18,546 - INFO - Ending scheduler
2024-03-23 16:19:18,575 - INFO - Watching for file changes with StatReloader
2024-03-23 16:19:40,570 - WARNING - Not Found: /ml_models/ml-predictions/images/favicon.ico
2024-03-23 16:23:47,096 - INFO - Starting scheduler
2024-03-23 16:23:47,096 - INFO - Updater date and time: 2024-03-23 16:23:47.096448
2024-03-23 16:23:47,096 - INFO - Adding job tentatively -- it will be properly scheduled when the scheduler starts
2024-03-23 16:23:47,096 - INFO - Added job "run_procedure_sequence" to job store "default"
2024-03-23 16:23:47,096 - INFO - Scheduler started
2024-03-23 16:23:47,096 - INFO - Ending scheduler
2024-03-23 16:23:48,864 - INFO - Starting scheduler
2024-03-23 16:23:48,864 - INFO - Updater date and time: 2024-03-23 16:23:48.864164
2024-03-23 16:23:48,864 - INFO - Adding job tentatively -- it will be properly scheduled when the scheduler starts
2024-03-23 16:23:48,864 - INFO - Added job "run_procedure_sequence" to job store "default"
2024-03-23 16:23:48,864 - INFO - Scheduler started
2024-03-23 16:23:48,864 - INFO - Ending scheduler
2024-03-23 16:23:48,889 - INFO - Watching for file changes with StatReloader
2024-03-23 16:24:07,190 - WARNING - Not Found: /tickers/update-ticker/9f53d106-491e-43bc-8f19-f91352ee4426/images/favicon.ico
2024-03-23 16:28:42,478 - INFO - Starting scheduler
2024-03-23 16:28:42,479 - INFO - Updater date and time: 2024-03-23 16:28:42.479270
2024-03-23 16:28:42,480 - INFO - Adding job tentatively -- it will be properly scheduled when the scheduler starts
2024-03-23 16:28:42,480 - INFO - Added job "run_procedure_sequence" to job store "default"
2024-03-23 16:28:42,480 - INFO - Scheduler started
2024-03-23 16:28:42,482 - INFO - Ending scheduler
2024-03-23 16:28:44,190 - INFO - Starting scheduler
2024-03-23 16:28:44,190 - INFO - Updater date and time: 2024-03-23 16:28:44.190363
2024-03-23 16:28:44,190 - INFO - Adding job tentatively -- it will be properly scheduled when the scheduler starts
2024-03-23 16:28:44,190 - INFO - Added job "run_procedure_sequence" to job store "default"
2024-03-23 16:28:44,190 - INFO - Scheduler started
2024-03-23 16:28:44,190 - INFO - Ending scheduler
2024-03-23 16:28:44,211 - INFO - Watching for file changes with StatReloader
2024-03-23 16:37:38,942 - INFO - Starting scheduler
2024-03-23 16:37:38,942 - INFO - Updater date and time: 2024-03-23 16:37:38.942828
2024-03-23 16:37:38,942 - INFO - Adding job tentatively -- it will be properly scheduled when the scheduler starts
2024-03-23 16:37:38,942 - INFO - Added job "run_procedure_sequence" to job store "default"
2024-03-23 16:37:38,942 - INFO - Scheduler started
2024-03-23 16:37:38,942 - INFO - Ending scheduler
2024-03-23 16:37:40,689 - INFO - Starting scheduler
2024-03-23 16:37:40,690 - INFO - Updater date and time: 2024-03-23 16:37:40.690669
2024-03-23 16:37:40,691 - INFO - Adding job tentatively -- it will be properly scheduled when the scheduler starts
2024-03-23 16:37:40,691 - INFO - Added job "run_procedure_sequence" to job store "default"
2024-03-23 16:37:40,691 - INFO - Scheduler started
2024-03-23 16:37:40,692 - INFO - Ending scheduler
2024-03-23 16:37:40,702 - INFO - Watching for file changes with StatReloader
2024-03-23 16:37:45,462 - WARNING - Not Found: /prices/get-IG-prices/images/favicon.ico
2024-03-23 16:37:58,884 - ERROR - Internal Server Error: /prices/get-IG-prices/
Traceback (most recent call last):
  File "C:\Users\sunny\anaconda3\envs\myenv311test\Lib\site-packages\django\core\handlers\exception.py", line 55, in inner
    response = get_response(request)
               ^^^^^^^^^^^^^^^^^^^^^
  File "C:\Users\sunny\anaconda3\envs\myenv311test\Lib\site-packages\django\core\handlers\base.py", line 197, in _get_response
    response = wrapped_callback(request, *callback_args, **callback_kwargs)
               ^^^^^^^^^^^^^^^^^^^^^^^^^^^^^^^^^^^^^^^^^^^^^^^^^^^^^^^^^^^^
  File "C:\Users\sunny\Desktop\Development\python\TradePro\prices\views.py", line 155, in get_IG_prices
    run_IG(ticker_symbol, start_date, end_date)
  File "C:\Users\sunny\Desktop\Development\python\TradePro\prices\IG_session\run_IG.py", line 109, in run_IG
    ticker_definitions = read_json()['ticker_definitions']
                         ^^^^^^^^^^^
TypeError: 'module' object is not callable
2024-03-23 16:39:34,708 - INFO - C:\Users\sunny\Desktop\Development\python\TradePro\prices\IG_session\run_IG.py changed, reloading.
2024-03-23 16:39:36,819 - INFO - Starting scheduler
2024-03-23 16:39:36,819 - INFO - Updater date and time: 2024-03-23 16:39:36.819143
2024-03-23 16:39:36,819 - INFO - Adding job tentatively -- it will be properly scheduled when the scheduler starts
2024-03-23 16:39:36,819 - INFO - Added job "run_procedure_sequence" to job store "default"
2024-03-23 16:39:36,819 - INFO - Scheduler started
2024-03-23 16:39:36,819 - INFO - Ending scheduler
2024-03-23 16:39:36,848 - INFO - Watching for file changes with StatReloader
2024-03-23 16:40:35,040 - INFO - C:\Users\sunny\Desktop\Development\python\TradePro\prices\IG_session\run_IG.py changed, reloading.
2024-03-23 16:40:37,000 - INFO - Starting scheduler
2024-03-23 16:40:37,000 - INFO - Updater date and time: 2024-03-23 16:40:37.000101
2024-03-23 16:40:37,000 - INFO - Adding job tentatively -- it will be properly scheduled when the scheduler starts
2024-03-23 16:40:37,000 - INFO - Added job "run_procedure_sequence" to job store "default"
2024-03-23 16:40:37,000 - INFO - Scheduler started
2024-03-23 16:40:37,000 - INFO - Ending scheduler
2024-03-23 16:40:37,020 - INFO - Watching for file changes with StatReloader
2024-03-23 16:45:01,520 - INFO - Starting scheduler
2024-03-23 16:45:01,520 - INFO - Updater date and time: 2024-03-23 16:45:01.520036
2024-03-23 16:45:01,520 - INFO - Adding job tentatively -- it will be properly scheduled when the scheduler starts
2024-03-23 16:45:01,520 - INFO - Added job "run_procedure_sequence" to job store "default"
2024-03-23 16:45:01,520 - INFO - Scheduler started
2024-03-23 16:45:01,520 - INFO - Ending scheduler
2024-03-23 16:45:03,202 - INFO - Starting scheduler
2024-03-23 16:45:03,202 - INFO - Updater date and time: 2024-03-23 16:45:03.202183
2024-03-23 16:45:03,203 - INFO - Adding job tentatively -- it will be properly scheduled when the scheduler starts
2024-03-23 16:45:03,204 - INFO - Added job "run_procedure_sequence" to job store "default"
2024-03-23 16:45:03,204 - INFO - Scheduler started
2024-03-23 16:45:03,205 - INFO - Ending scheduler
2024-03-23 16:45:03,223 - INFO - Watching for file changes with StatReloader
2024-03-23 16:45:23,203 - ERROR - Internal Server Error: /prices/get-IG-prices/
Traceback (most recent call last):
  File "C:\Users\sunny\anaconda3\envs\myenv311test\Lib\site-packages\django\core\handlers\exception.py", line 55, in inner
    response = get_response(request)
               ^^^^^^^^^^^^^^^^^^^^^
  File "C:\Users\sunny\anaconda3\envs\myenv311test\Lib\site-packages\django\core\handlers\base.py", line 197, in _get_response
    response = wrapped_callback(request, *callback_args, **callback_kwargs)
               ^^^^^^^^^^^^^^^^^^^^^^^^^^^^^^^^^^^^^^^^^^^^^^^^^^^^^^^^^^^^
  File "C:\Users\sunny\Desktop\Development\python\TradePro\prices\views.py", line 155, in get_IG_prices
    run_IG(ticker_symbol, start_date, end_date)
  File "C:\Users\sunny\Desktop\Development\python\TradePro\prices\IG_session\run_IG.py", line 109, in run_IG
    full_list = read_json()['ticker_definitions']
                ^^^^^^^^^^^
TypeError: 'module' object is not callable
2024-03-23 16:45:48,797 - INFO - C:\Users\sunny\Desktop\Development\python\TradePro\prices\IG_session\run_IG.py changed, reloading.
2024-03-23 16:45:50,675 - INFO - Starting scheduler
2024-03-23 16:45:50,675 - INFO - Updater date and time: 2024-03-23 16:45:50.675765
2024-03-23 16:45:50,691 - INFO - Adding job tentatively -- it will be properly scheduled when the scheduler starts
2024-03-23 16:45:50,691 - INFO - Added job "run_procedure_sequence" to job store "default"
2024-03-23 16:45:50,691 - INFO - Scheduler started
2024-03-23 16:45:50,691 - INFO - Ending scheduler
2024-03-23 16:45:50,691 - INFO - Watching for file changes with StatReloader
2024-03-23 16:46:00,017 - INFO - Running job "run_procedure_sequence (trigger: interval[0:05:00], next run at: 2024-03-23 16:46:00 GMT)" (scheduled at 2024-03-23 16:46:00+00:00)
2024-03-23 16:46:00,017 - INFO - Running job "run_procedure_sequence (trigger: interval[0:05:00], next run at: 2024-03-23 16:51:00 GMT)" (scheduled at 2024-03-23 16:46:00+00:00)
2024-03-23 16:46:00,018 - INFO - Inside the procedure sequence
2024-03-23 16:46:00,018 - INFO - Inside the procedure sequence
2024-03-23 16:46:00,020 - ERROR - Job "run_procedure_sequence (trigger: interval[0:05:00], next run at: 2024-03-23 16:51:00 GMT)" raised an exception
Traceback (most recent call last):
  File "C:\Users\sunny\anaconda3\envs\myenv311test\Lib\site-packages\apscheduler\executors\base.py", line 125, in run_job
    retval = job.func(*job.args, **job.kwargs)
             ^^^^^^^^^^^^^^^^^^^^^^^^^^^^^^^^^
  File "C:\Users\sunny\Desktop\Development\python\TradePro\prices\updater.py", line 55, in run_procedure_sequence
    tickers = read_json()['tickers']
              ^^^^^^^^^^^
TypeError: 'module' object is not callable
2024-03-23 16:46:00,020 - ERROR - Job "run_procedure_sequence (trigger: interval[0:05:00], next run at: 2024-03-23 16:51:00 GMT)" raised an exception
Traceback (most recent call last):
  File "C:\Users\sunny\anaconda3\envs\myenv311test\Lib\site-packages\apscheduler\executors\base.py", line 125, in run_job
    retval = job.func(*job.args, **job.kwargs)
             ^^^^^^^^^^^^^^^^^^^^^^^^^^^^^^^^^
  File "C:\Users\sunny\Desktop\Development\python\TradePro\prices\updater.py", line 55, in run_procedure_sequence
    tickers = read_json()['tickers']
              ^^^^^^^^^^^
TypeError: 'module' object is not callable
2024-03-23 16:46:09,065 - ERROR - Internal Server Error: /prices/get-IG-prices/
Traceback (most recent call last):
  File "C:\Users\sunny\anaconda3\envs\myenv311test\Lib\site-packages\django\core\handlers\exception.py", line 55, in inner
    response = get_response(request)
               ^^^^^^^^^^^^^^^^^^^^^
  File "C:\Users\sunny\anaconda3\envs\myenv311test\Lib\site-packages\django\core\handlers\base.py", line 197, in _get_response
    response = wrapped_callback(request, *callback_args, **callback_kwargs)
               ^^^^^^^^^^^^^^^^^^^^^^^^^^^^^^^^^^^^^^^^^^^^^^^^^^^^^^^^^^^^
  File "C:\Users\sunny\Desktop\Development\python\TradePro\prices\views.py", line 155, in get_IG_prices
    run_IG(ticker_symbol, start_date, end_date)
  File "C:\Users\sunny\Desktop\Development\python\TradePro\prices\IG_session\run_IG.py", line 109, in run_IG
    full_list = read_json()
                ^^^^^^^^^^^
TypeError: 'module' object is not callable
2024-03-23 16:47:00,528 - INFO - C:\Users\sunny\Desktop\Development\python\TradePro\prices\IG_session\run_IG.py changed, reloading.
2024-03-23 16:48:39,905 - INFO - Starting scheduler
2024-03-23 16:48:39,905 - INFO - Updater date and time: 2024-03-23 16:48:39.905500
2024-03-23 16:48:39,921 - INFO - Adding job tentatively -- it will be properly scheduled when the scheduler starts
2024-03-23 16:48:39,921 - INFO - Added job "run_procedure_sequence" to job store "default"
2024-03-23 16:48:39,921 - INFO - Scheduler started
2024-03-23 16:48:39,921 - INFO - Ending scheduler
2024-03-23 16:48:39,938 - INFO - Watching for file changes with StatReloader
2024-03-23 16:49:11,212 - INFO - C:\Users\sunny\Desktop\Development\python\TradePro\prices\IG_session\run_IG.py changed, reloading.
2024-03-23 16:49:13,262 - INFO - Starting scheduler
2024-03-23 16:49:13,277 - INFO - Updater date and time: 2024-03-23 16:49:13.277741
2024-03-23 16:49:13,277 - INFO - Adding job tentatively -- it will be properly scheduled when the scheduler starts
2024-03-23 16:49:13,277 - INFO - Added job "run_procedure_sequence" to job store "default"
2024-03-23 16:49:13,277 - INFO - Scheduler started
2024-03-23 16:49:13,277 - INFO - Ending scheduler
2024-03-23 16:49:13,298 - INFO - Watching for file changes with StatReloader
2024-03-23 16:49:17,755 - ERROR - Internal Server Error: /ml_models/ml-manual/
Traceback (most recent call last):
  File "C:\Users\sunny\anaconda3\envs\myenv311test\Lib\site-packages\django\core\handlers\exception.py", line 55, in inner
    response = get_response(request)
               ^^^^^^^^^^^^^^^^^^^^^
  File "C:\Users\sunny\anaconda3\envs\myenv311test\Lib\site-packages\django\core\handlers\base.py", line 197, in _get_response
    response = wrapped_callback(request, *callback_args, **callback_kwargs)
               ^^^^^^^^^^^^^^^^^^^^^^^^^^^^^^^^^^^^^^^^^^^^^^^^^^^^^^^^^^^^
  File "C:\Users\sunny\Desktop\Development\python\TradePro\ml_models\views.py", line 337, in ml_manual
    last_price_stats = dp.stats_df_gen(prices_df,2)
                       ^^^^^^^^^^^^^^^
AttributeError: 'NoneType' object has no attribute 'stats_df_gen'
2024-03-23 20:42:32,868 - INFO - Starting scheduler
2024-03-23 20:42:32,868 - INFO - Updater date and time: 2024-03-23 20:42:32.868589
2024-03-23 20:42:32,868 - INFO - Adding job tentatively -- it will be properly scheduled when the scheduler starts
2024-03-23 20:42:32,868 - INFO - Added job "run_procedure_sequence" to job store "default"
2024-03-23 20:42:32,875 - INFO - Scheduler started
2024-03-23 20:42:32,875 - INFO - Ending scheduler
2024-03-23 20:42:34,561 - INFO - Starting scheduler
2024-03-23 20:42:34,561 - INFO - Updater date and time: 2024-03-23 20:42:34.561811
2024-03-23 20:42:34,561 - INFO - Adding job tentatively -- it will be properly scheduled when the scheduler starts
2024-03-23 20:42:34,561 - INFO - Added job "run_procedure_sequence" to job store "default"
2024-03-23 20:42:34,561 - INFO - Scheduler started
2024-03-23 20:42:34,561 - INFO - Ending scheduler
2024-03-23 20:42:34,582 - INFO - Watching for file changes with StatReloader
2024-03-23 20:42:35,899 - WARNING - Not Found: /images/favicon.ico
2024-03-23 20:42:40,359 - ERROR - Internal Server Error: /ml_models/ml-report/
Traceback (most recent call last):
  File "C:\Users\sunny\anaconda3\envs\myenv311test\Lib\site-packages\django\core\handlers\exception.py", line 55, in inner
    response = get_response(request)
               ^^^^^^^^^^^^^^^^^^^^^
  File "C:\Users\sunny\anaconda3\envs\myenv311test\Lib\site-packages\django\core\handlers\base.py", line 197, in _get_response
    response = wrapped_callback(request, *callback_args, **callback_kwargs)
               ^^^^^^^^^^^^^^^^^^^^^^^^^^^^^^^^^^^^^^^^^^^^^^^^^^^^^^^^^^^^
  File "C:\Users\sunny\Desktop\Development\python\TradePro\ml_models\views.py", line 288, in ml_report
    pred_var_pos, pred_var_neg = variability_analysis(model_ticker, 0.1)
                                 ^^^^^^^^^^^^^^^^^^^^^^^^^^^^^^^^^^^^^^^
  File "C:\Users\sunny\Desktop\Development\python\TradePro\ml_models\utils\predictive_analysis.py", line 387, in variability_analysis
    pred_variability_results[model_version]  = format_model_results(
                                               ^^^^^^^^^^^^^^^^^^^^^
TypeError: format_model_results() missing 1 required positional argument: 'model_input_data'
2024-03-23 20:42:40,486 - WARNING - Not Found: /favicon.ico
2024-03-23 20:43:55,549 - INFO - C:\Users\sunny\Desktop\Development\python\TradePro\ml_models\utils\predictive_analysis.py changed, reloading.
2024-03-23 20:45:14,182 - INFO - Starting scheduler
2024-03-23 20:45:14,182 - INFO - Updater date and time: 2024-03-23 20:45:14.182162
2024-03-23 20:45:14,182 - INFO - Adding job tentatively -- it will be properly scheduled when the scheduler starts
2024-03-23 20:45:14,182 - INFO - Added job "run_procedure_sequence" to job store "default"
2024-03-23 20:45:14,182 - INFO - Scheduler started
2024-03-23 20:45:14,182 - INFO - Ending scheduler
2024-03-23 20:45:14,206 - INFO - Watching for file changes with StatReloader
2024-03-23 20:45:19,629 - ERROR - Internal Server Error: /ml_models/ml-report/
Traceback (most recent call last):
  File "C:\Users\sunny\anaconda3\envs\myenv311test\Lib\site-packages\django\core\handlers\exception.py", line 55, in inner
    response = get_response(request)
               ^^^^^^^^^^^^^^^^^^^^^
  File "C:\Users\sunny\anaconda3\envs\myenv311test\Lib\site-packages\django\core\handlers\base.py", line 197, in _get_response
    response = wrapped_callback(request, *callback_args, **callback_kwargs)
               ^^^^^^^^^^^^^^^^^^^^^^^^^^^^^^^^^^^^^^^^^^^^^^^^^^^^^^^^^^^^
  File "C:\Users\sunny\Desktop\Development\python\TradePro\ml_models\views.py", line 288, in ml_report
    pred_var_pos, pred_var_neg = variability_analysis(model_ticker, 0.1)
                                 ^^^^^^^^^^^^^^^^^^^^^^^^^^^^^^^^^^^^^^^
  File "C:\Users\sunny\Desktop\Development\python\TradePro\ml_models\utils\predictive_analysis.py", line 388, in variability_analysis
    pred_variability_results[model_version]  = format_model_results(
                                               ^^^^^^^^^^^^^^^^^^^^^
  File "C:\Users\sunny\Desktop\Development\python\TradePro\ml_models\utils\predictive_analysis.py", line 66, in format_model_results
    input_bb.append(data['upper_bb20_4'])
                    ~~~~^^^^^^^^^^^^^^^^
TypeError: string indices must be integers, not 'str'
2024-03-23 20:46:00,008 - INFO - Running job "run_procedure_sequence (trigger: interval[0:05:00], next run at: 2024-03-23 20:46:00 GMT)" (scheduled at 2024-03-23 20:46:00+00:00)
2024-03-23 20:46:00,008 - INFO - Inside the procedure sequence
2024-03-23 20:46:00,008 - INFO - Inside the procedure sequence
2024-03-23 20:46:04,088 - ERROR - Job "run_procedure_sequence (trigger: interval[0:05:00], next run at: 2024-03-23 20:51:00 GMT)" raised an exception
Traceback (most recent call last):
  File "C:\Users\sunny\anaconda3\envs\myenv311test\Lib\site-packages\apscheduler\executors\base.py", line 125, in run_job
    retval = job.func(*job.args, **job.kwargs)
             ^^^^^^^^^^^^^^^^^^^^^^^^^^^^^^^^^
  File "C:\Users\sunny\Desktop\Development\python\TradePro\prices\updater.py", line 60, in run_procedure_sequence
    comparison_comment, general_ticker_info, send_email_enabled = run_model_predictions(ticker)
                                                                  ^^^^^^^^^^^^^^^^^^^^^^^^^^^^^
  File "C:\Users\sunny\Desktop\Development\python\TradePro\ml_models\utils\predictive_analysis.py", line 341, in run_model_predictions
    pred_reverse_v4, _, _, _ = standard_analysis(model_ticker, "v4")
                               ^^^^^^^^^^^^^^^^^^^^^^^^^^^^^^^^^^^^^
  File "C:\Users\sunny\Desktop\Development\python\TradePro\ml_models\utils\predictive_analysis.py", line 216, in standard_analysis
    pred_reverse = format_model_results(
                   ^^^^^^^^^^^^^^^^^^^^^
  File "C:\Users\sunny\Desktop\Development\python\TradePro\ml_models\utils\predictive_analysis.py", line 66, in format_model_results
    input_bb.append(data['upper_bb20_4'])
                    ~~~~^^^^^^^^^^^^^^^^
TypeError: string indices must be integers, not 'str'
2024-03-23 20:46:04,127 - ERROR - Job "run_procedure_sequence (trigger: interval[0:05:00], next run at: 2024-03-23 20:51:00 GMT)" raised an exception
Traceback (most recent call last):
  File "C:\Users\sunny\anaconda3\envs\myenv311test\Lib\site-packages\apscheduler\executors\base.py", line 125, in run_job
    retval = job.func(*job.args, **job.kwargs)
             ^^^^^^^^^^^^^^^^^^^^^^^^^^^^^^^^^
  File "C:\Users\sunny\Desktop\Development\python\TradePro\prices\updater.py", line 60, in run_procedure_sequence
    comparison_comment, general_ticker_info, send_email_enabled = run_model_predictions(ticker)
                                                                  ^^^^^^^^^^^^^^^^^^^^^^^^^^^^^
  File "C:\Users\sunny\Desktop\Development\python\TradePro\ml_models\utils\predictive_analysis.py", line 340, in run_model_predictions
  File "C:\Users\sunny\Desktop\Development\python\TradePro\ml_models\utils\predictive_analysis.py", line 216, in standard_analysis
    pred_reverse = format_model_results(
                   ^^^^^^^^^^^^^^^^^^^^^
TypeError: format_model_results() got an unexpected keyword argument 'input_data'
2024-03-23 20:46:40,750 - INFO - C:\Users\sunny\Desktop\Development\python\TradePro\ml_models\utils\predictive_analysis.py changed, reloading.
2024-03-23 20:46:45,918 - INFO - Starting scheduler
2024-03-23 20:46:45,918 - INFO - Updater date and time: 2024-03-23 20:46:45.918596
2024-03-23 20:46:45,918 - INFO - Adding job tentatively -- it will be properly scheduled when the scheduler starts
2024-03-23 20:46:45,918 - INFO - Added job "run_procedure_sequence" to job store "default"
2024-03-23 20:46:45,918 - INFO - Scheduler started
2024-03-23 20:46:45,918 - INFO - Ending scheduler
2024-03-23 20:46:47,654 - INFO - Starting scheduler
2024-03-23 20:46:47,654 - INFO - Updater date and time: 2024-03-23 20:46:47.654323
2024-03-23 20:46:47,654 - INFO - Adding job tentatively -- it will be properly scheduled when the scheduler starts
2024-03-23 20:46:47,654 - INFO - Added job "run_procedure_sequence" to job store "default"
2024-03-23 20:46:47,654 - INFO - Scheduler started
2024-03-23 20:46:47,654 - INFO - Ending scheduler
2024-03-23 20:46:47,675 - INFO - Watching for file changes with StatReloader
2024-03-23 20:46:56,282 - ERROR - Internal Server Error: /ml_models/ml-report/
Traceback (most recent call last):
  File "C:\Users\sunny\anaconda3\envs\myenv311test\Lib\site-packages\django\core\handlers\exception.py", line 55, in inner
    response = get_response(request)
               ^^^^^^^^^^^^^^^^^^^^^
  File "C:\Users\sunny\anaconda3\envs\myenv311test\Lib\site-packages\django\core\handlers\base.py", line 197, in _get_response
    response = wrapped_callback(request, *callback_args, **callback_kwargs)
               ^^^^^^^^^^^^^^^^^^^^^^^^^^^^^^^^^^^^^^^^^^^^^^^^^^^^^^^^^^^^
  File "C:\Users\sunny\Desktop\Development\python\TradePro\ml_models\views.py", line 288, in ml_report
    pred_var_pos, pred_var_neg = variability_analysis(model_ticker, 0.1)
                                 ^^^^^^^^^^^^^^^^^^^^^^^^^^^^^^^^^^^^^^^
  File "C:\Users\sunny\Desktop\Development\python\TradePro\ml_models\utils\predictive_analysis.py", line 388, in variability_analysis
    pred_variability_results[model_version]  = format_model_results(
                                               ^^^^^^^^^^^^^^^^^^^^^
  File "C:\Users\sunny\Desktop\Development\python\TradePro\ml_models\utils\predictive_analysis.py", line 66, in format_model_results
    print(data['upper_bb20_4'])
          ~~~~^^^^^^^^^^^^^^^^
TypeError: string indices must be integers, not 'str'
2024-03-23 20:47:40,533 - INFO - C:\Users\sunny\Desktop\Development\python\TradePro\ml_models\utils\predictive_analysis.py changed, reloading.
2024-03-23 20:47:42,556 - INFO - Starting scheduler
2024-03-23 20:47:42,556 - INFO - Updater date and time: 2024-03-23 20:47:42.556220
2024-03-23 20:47:42,557 - INFO - Adding job tentatively -- it will be properly scheduled when the scheduler starts
2024-03-23 20:47:42,557 - INFO - Added job "run_procedure_sequence" to job store "default"
2024-03-23 20:47:42,558 - INFO - Scheduler started
2024-03-23 20:47:42,558 - INFO - Ending scheduler
2024-03-23 20:47:42,576 - INFO - Watching for file changes with StatReloader
2024-03-23 20:47:44,294 - INFO - C:\Users\sunny\Desktop\Development\python\TradePro\ml_models\utils\predictive_analysis.py changed, reloading.
2024-03-23 20:47:46,343 - INFO - Starting scheduler
2024-03-23 20:47:46,343 - INFO - Updater date and time: 2024-03-23 20:47:46.343915
2024-03-23 20:47:46,343 - INFO - Adding job tentatively -- it will be properly scheduled when the scheduler starts
2024-03-23 20:47:46,343 - INFO - Added job "run_procedure_sequence" to job store "default"
2024-03-23 20:47:46,343 - INFO - Scheduler started
2024-03-23 20:47:46,343 - INFO - Ending scheduler
2024-03-23 20:47:46,365 - INFO - Watching for file changes with StatReloader
2024-03-23 20:47:49,699 - WARNING - Not Found: /ml_models/ml-report/images/favicon.ico
2024-03-23 20:48:19,775 - INFO - C:\Users\sunny\Desktop\Development\python\TradePro\ml_models\utils\predictive_analysis.py changed, reloading.
2024-03-23 20:48:21,842 - INFO - Starting scheduler
2024-03-23 20:48:21,842 - INFO - Updater date and time: 2024-03-23 20:48:21.842781
2024-03-23 20:48:21,842 - INFO - Adding job tentatively -- it will be properly scheduled when the scheduler starts
2024-03-23 20:48:21,842 - INFO - Added job "run_procedure_sequence" to job store "default"
2024-03-23 20:48:21,842 - INFO - Scheduler started
2024-03-23 20:48:21,842 - INFO - Ending scheduler
2024-03-23 20:48:21,880 - INFO - Watching for file changes with StatReloader
2024-03-23 20:52:59,345 - INFO - Starting scheduler
2024-03-23 20:52:59,345 - INFO - Updater date and time: 2024-03-23 20:52:59.345636
2024-03-23 20:52:59,345 - INFO - Adding job tentatively -- it will be properly scheduled when the scheduler starts
2024-03-23 20:52:59,345 - INFO - Added job "run_procedure_sequence" to job store "default"
2024-03-23 20:52:59,345 - INFO - Scheduler started
2024-03-23 20:52:59,345 - INFO - Ending scheduler
2024-03-23 20:53:01,110 - INFO - Starting scheduler
2024-03-23 20:53:01,110 - INFO - Updater date and time: 2024-03-23 20:53:01.110880
2024-03-23 20:53:01,110 - INFO - Adding job tentatively -- it will be properly scheduled when the scheduler starts
2024-03-23 20:53:01,110 - INFO - Added job "run_procedure_sequence" to job store "default"
2024-03-23 20:53:01,110 - INFO - Scheduler started
2024-03-23 20:53:01,110 - INFO - Ending scheduler
2024-03-23 20:53:01,128 - INFO - Watching for file changes with StatReloader
2024-03-23 20:53:07,805 - ERROR - Internal Server Error: /ml_models/ml-report/
Traceback (most recent call last):
  File "C:\Users\sunny\anaconda3\envs\myenv311test\Lib\site-packages\django\core\handlers\exception.py", line 55, in inner
    response = get_response(request)
               ^^^^^^^^^^^^^^^^^^^^^
  File "C:\Users\sunny\anaconda3\envs\myenv311test\Lib\site-packages\django\core\handlers\base.py", line 197, in _get_response
    response = wrapped_callback(request, *callback_args, **callback_kwargs)
               ^^^^^^^^^^^^^^^^^^^^^^^^^^^^^^^^^^^^^^^^^^^^^^^^^^^^^^^^^^^^
  File "C:\Users\sunny\Desktop\Development\python\TradePro\ml_models\views.py", line 288, in ml_report
    pred_var_pos, pred_var_neg = variability_analysis(model_ticker, 0.1)
                                 ^^^^^^^^^^^^^^^^^^^^^^^^^^^^^^^^^^^^^^^
  File "C:\Users\sunny\Desktop\Development\python\TradePro\ml_models\utils\predictive_analysis.py", line 389, in variability_analysis
    pred_variability_results[model_version]  = format_model_results(
                                               ^^^^^^^^^^^^^^^^^^^^^
  File "C:\Users\sunny\Desktop\Development\python\TradePro\ml_models\utils\predictive_analysis.py", line 65, in format_model_results
    for index, row in model_input_data:
        ^^^^^^^^^^
ValueError: too many values to unpack (expected 2)
2024-03-23 20:53:57,945 - INFO - C:\Users\sunny\Desktop\Development\python\TradePro\ml_models\utils\predictive_analysis.py changed, reloading.
2024-03-23 20:54:00,061 - INFO - Starting scheduler
2024-03-23 20:54:00,061 - INFO - Updater date and time: 2024-03-23 20:54:00.061745
2024-03-23 20:54:00,061 - INFO - Adding job tentatively -- it will be properly scheduled when the scheduler starts
2024-03-23 20:54:00,061 - INFO - Added job "run_procedure_sequence" to job store "default"
2024-03-23 20:54:00,061 - INFO - Scheduler started
2024-03-23 20:54:00,077 - INFO - Ending scheduler
2024-03-23 20:54:00,077 - INFO - Watching for file changes with StatReloader
2024-03-23 20:54:02,433 - ERROR - Internal Server Error: /ml_models/ml-report/
Traceback (most recent call last):
  File "C:\Users\sunny\anaconda3\envs\myenv311test\Lib\site-packages\django\core\handlers\exception.py", line 55, in inner
    response = get_response(request)
               ^^^^^^^^^^^^^^^^^^^^^
  File "C:\Users\sunny\anaconda3\envs\myenv311test\Lib\site-packages\django\core\handlers\base.py", line 197, in _get_response
    response = wrapped_callback(request, *callback_args, **callback_kwargs)
               ^^^^^^^^^^^^^^^^^^^^^^^^^^^^^^^^^^^^^^^^^^^^^^^^^^^^^^^^^^^^
  File "C:\Users\sunny\Desktop\Development\python\TradePro\ml_models\views.py", line 288, in ml_report
    pred_var_pos, pred_var_neg = variability_analysis(model_ticker, 0.1)
                                 ^^^^^^^^^^^^^^^^^^^^^^^^^^^^^^^^^^^^^^^
  File "C:\Users\sunny\Desktop\Development\python\TradePro\ml_models\utils\predictive_analysis.py", line 389, in variability_analysis
    pred_variability_results[model_version]  = format_model_results(
                                               ^^^^^^^^^^^^^^^^^^^^^
  File "C:\Users\sunny\Desktop\Development\python\TradePro\ml_models\utils\predictive_analysis.py", line 65, in format_model_results
    for index, row in model_input_data:
        ^^^^^^^^^^
ValueError: too many values to unpack (expected 2)
2024-03-23 20:58:12,376 - INFO - Starting scheduler
2024-03-23 20:58:12,376 - INFO - Updater date and time: 2024-03-23 20:58:12.376785
2024-03-23 20:58:12,376 - INFO - Adding job tentatively -- it will be properly scheduled when the scheduler starts
2024-03-23 20:58:12,376 - INFO - Added job "run_procedure_sequence" to job store "default"
2024-03-23 20:58:12,376 - INFO - Scheduler started
2024-03-23 20:58:12,376 - INFO - Ending scheduler
2024-03-23 20:58:14,253 - INFO - Starting scheduler
2024-03-23 20:58:14,253 - INFO - Updater date and time: 2024-03-23 20:58:14.253172
2024-03-23 20:58:14,253 - INFO - Adding job tentatively -- it will be properly scheduled when the scheduler starts
2024-03-23 20:58:14,253 - INFO - Added job "run_procedure_sequence" to job store "default"
2024-03-23 20:58:14,253 - INFO - Scheduler started
2024-03-23 20:58:14,253 - INFO - Ending scheduler
2024-03-23 20:58:14,280 - INFO - Watching for file changes with StatReloader
2024-03-23 20:58:18,471 - ERROR - Internal Server Error: /ml_models/ml-report/
Traceback (most recent call last):
  File "C:\Users\sunny\anaconda3\envs\myenv311test\Lib\site-packages\django\core\handlers\exception.py", line 55, in inner
    response = get_response(request)
               ^^^^^^^^^^^^^^^^^^^^^
  File "C:\Users\sunny\anaconda3\envs\myenv311test\Lib\site-packages\django\core\handlers\base.py", line 197, in _get_response
    response = wrapped_callback(request, *callback_args, **callback_kwargs)
               ^^^^^^^^^^^^^^^^^^^^^^^^^^^^^^^^^^^^^^^^^^^^^^^^^^^^^^^^^^^^
  File "C:\Users\sunny\Desktop\Development\python\TradePro\ml_models\views.py", line 288, in ml_report
    pred_var_pos, pred_var_neg = variability_analysis(model_ticker, 0.1)
                                 ^^^^^^^^^^^^^^^^^^^^^^^^^^^^^^^^^^^^^^^
  File "C:\Users\sunny\Desktop\Development\python\TradePro\ml_models\utils\predictive_analysis.py", line 390, in variability_analysis
    pred_variability_results[model_version]  = format_model_results(
                                               ^^^^^^^^^^^^^^^^^^^^^
  File "C:\Users\sunny\Desktop\Development\python\TradePro\ml_models\utils\predictive_analysis.py", line 65, in format_model_results
    for index, row in model_input_data:
        ^^^^^^^^^^
ValueError: too many values to unpack (expected 2)
2024-03-23 20:58:51,219 - INFO - C:\Users\sunny\Desktop\Development\python\TradePro\ml_models\utils\predictive_analysis.py changed, reloading.
2024-03-23 20:58:53,259 - INFO - Starting scheduler
2024-03-23 20:58:53,275 - INFO - Updater date and time: 2024-03-23 20:58:53.259784
2024-03-23 20:58:53,276 - INFO - Adding job tentatively -- it will be properly scheduled when the scheduler starts
2024-03-23 20:58:53,276 - INFO - Added job "run_procedure_sequence" to job store "default"
2024-03-23 20:58:53,276 - INFO - Scheduler started
2024-03-23 20:58:53,277 - INFO - Ending scheduler
2024-03-23 20:58:53,296 - INFO - Watching for file changes with StatReloader
2024-03-23 20:59:00,825 - ERROR - Internal Server Error: /ml_models/ml-report/
Traceback (most recent call last):
  File "C:\Users\sunny\anaconda3\envs\myenv311test\Lib\site-packages\django\core\handlers\exception.py", line 55, in inner
    response = get_response(request)
               ^^^^^^^^^^^^^^^^^^^^^
  File "C:\Users\sunny\anaconda3\envs\myenv311test\Lib\site-packages\django\core\handlers\base.py", line 197, in _get_response
    response = wrapped_callback(request, *callback_args, **callback_kwargs)
               ^^^^^^^^^^^^^^^^^^^^^^^^^^^^^^^^^^^^^^^^^^^^^^^^^^^^^^^^^^^^
  File "C:\Users\sunny\Desktop\Development\python\TradePro\ml_models\views.py", line 288, in ml_report
    pred_var_pos, pred_var_neg = variability_analysis(model_ticker, 0.1)
                                 ^^^^^^^^^^^^^^^^^^^^^^^^^^^^^^^^^^^^^^^
  File "C:\Users\sunny\Desktop\Development\python\TradePro\ml_models\utils\predictive_analysis.py", line 390, in variability_analysis
    pred_variability_results[model_version]  = format_model_results(
                                               ^^^^^^^^^^^^^^^^^^^^^
  File "C:\Users\sunny\Desktop\Development\python\TradePro\ml_models\utils\predictive_analysis.py", line 65, in format_model_results
    for index, row in model_input_data:
        ^^^^^^^^^^
ValueError: too many values to unpack (expected 2)
2024-03-23 20:59:09,311 - INFO - C:\Users\sunny\Desktop\Development\python\TradePro\ml_models\utils\predictive_analysis.py changed, reloading.
2024-03-23 20:59:11,495 - INFO - Starting scheduler
2024-03-23 20:59:11,495 - INFO - Updater date and time: 2024-03-23 20:59:11.495040
2024-03-23 20:59:11,495 - INFO - Adding job tentatively -- it will be properly scheduled when the scheduler starts
2024-03-23 20:59:11,495 - INFO - Added job "run_procedure_sequence" to job store "default"
2024-03-23 20:59:11,495 - INFO - Scheduler started
2024-03-23 20:59:11,495 - INFO - Ending scheduler
2024-03-23 20:59:11,513 - INFO - Watching for file changes with StatReloader
2024-03-23 21:10:12,993 - INFO - Starting scheduler
2024-03-23 21:10:12,994 - INFO - Updater date and time: 2024-03-23 21:10:12.994346
2024-03-23 21:10:12,995 - INFO - Adding job tentatively -- it will be properly scheduled when the scheduler starts
2024-03-23 21:10:12,995 - INFO - Added job "run_procedure_sequence" to job store "default"
2024-03-23 21:10:12,995 - INFO - Scheduler started
2024-03-23 21:10:12,996 - INFO - Ending scheduler
2024-03-23 21:10:14,690 - INFO - Starting scheduler
2024-03-23 21:10:14,690 - INFO - Updater date and time: 2024-03-23 21:10:14.690310
2024-03-23 21:10:14,690 - INFO - Adding job tentatively -- it will be properly scheduled when the scheduler starts
2024-03-23 21:10:14,690 - INFO - Added job "run_procedure_sequence" to job store "default"
2024-03-23 21:10:14,690 - INFO - Scheduler started
2024-03-23 21:10:14,690 - INFO - Ending scheduler
2024-03-23 21:10:14,708 - INFO - Watching for file changes with StatReloader
2024-03-23 21:10:58,213 - INFO - Starting scheduler
2024-03-23 21:10:58,213 - INFO - Updater date and time: 2024-03-23 21:10:58.213036
2024-03-23 21:10:58,213 - INFO - Adding job tentatively -- it will be properly scheduled when the scheduler starts
2024-03-23 21:10:58,213 - INFO - Added job "run_procedure_sequence" to job store "default"
2024-03-23 21:10:58,213 - INFO - Scheduler started
2024-03-23 21:10:58,213 - INFO - Ending scheduler
2024-03-23 21:11:00,027 - INFO - Running job "run_procedure_sequence (trigger: interval[0:05:00], next run at: 2024-03-23 21:11:00 GMT)" (scheduled at 2024-03-23 21:11:00+00:00)
2024-03-23 21:11:00,028 - INFO - Inside the procedure sequence
2024-03-23 21:11:00,053 - INFO - Starting scheduler
2024-03-23 21:11:00,053 - INFO - Updater date and time: 2024-03-23 21:11:00.053865
2024-03-23 21:11:00,055 - INFO - Adding job tentatively -- it will be properly scheduled when the scheduler starts
2024-03-23 21:11:00,055 - INFO - Added job "run_procedure_sequence" to job store "default"
2024-03-23 21:11:00,055 - INFO - Scheduler started
2024-03-23 21:11:00,056 - INFO - Ending scheduler
2024-03-23 21:11:00,079 - INFO - Watching for file changes with StatReloader
2024-03-23 21:11:03,810 - ERROR - Job "run_procedure_sequence (trigger: interval[0:05:00], next run at: 2024-03-23 21:16:00 GMT)" raised an exception
Traceback (most recent call last):
  File "C:\Users\sunny\anaconda3\envs\myenv311test\Lib\site-packages\apscheduler\executors\base.py", line 125, in run_job
    retval = job.func(*job.args, **job.kwargs)
             ^^^^^^^^^^^^^^^^^^^^^^^^^^^^^^^^^
  File "C:\Users\sunny\Desktop\Development\python\TradePro\prices\updater.py", line 60, in run_procedure_sequence
    comparison_comment, general_ticker_info, send_email_enabled = run_model_predictions(ticker)
                                                                  ^^^^^^^^^^^^^^^^^^^^^^^^^^^^^
  File "C:\Users\sunny\Desktop\Development\python\TradePro\ml_models\utils\predictive_analysis.py", line 343, in run_model_predictions
    pred_reverse_v4, _, _, _ = standard_analysis(model_ticker, "v4")
                               ^^^^^^^^^^^^^^^^^^^^^^^^^^^^^^^^^^^^^
  File "C:\Users\sunny\Desktop\Development\python\TradePro\ml_models\utils\predictive_analysis.py", line 218, in standard_analysis
    pred_reverse = format_model_results(
                   ^^^^^^^^^^^^^^^^^^^^^
  File "C:\Users\sunny\Desktop\Development\python\TradePro\ml_models\utils\predictive_analysis.py", line 65, in format_model_results
    for index, row in model_input_data:
        ^^^^^^^^^^
ValueError: too many values to unpack (expected 2)
2024-03-23 21:11:07,833 - ERROR - Internal Server Error: /ml_models/ml-report/
Traceback (most recent call last):
  File "C:\Users\sunny\anaconda3\envs\myenv311test\Lib\site-packages\django\core\handlers\exception.py", line 55, in inner
    response = get_response(request)
               ^^^^^^^^^^^^^^^^^^^^^
  File "C:\Users\sunny\anaconda3\envs\myenv311test\Lib\site-packages\django\core\handlers\base.py", line 197, in _get_response
    response = wrapped_callback(request, *callback_args, **callback_kwargs)
               ^^^^^^^^^^^^^^^^^^^^^^^^^^^^^^^^^^^^^^^^^^^^^^^^^^^^^^^^^^^^
  File "C:\Users\sunny\Desktop\Development\python\TradePro\ml_models\views.py", line 288, in ml_report
    pred_var_pos, pred_var_neg = variability_analysis(model_ticker, 0.1)
                                 ^^^^^^^^^^^^^^^^^^^^^^^^^^^^^^^^^^^^^^^
  File "C:\Users\sunny\Desktop\Development\python\TradePro\ml_models\utils\predictive_analysis.py", line 390, in variability_analysis
    pred_variability_results[model_version]  = format_model_results(
                                               ^^^^^^^^^^^^^^^^^^^^^
  File "C:\Users\sunny\Desktop\Development\python\TradePro\ml_models\utils\predictive_analysis.py", line 65, in format_model_results
    for index, row in model_input_data:
        ^^^^^^^^^^
ValueError: too many values to unpack (expected 2)
2024-03-23 21:12:43,059 - INFO - Starting scheduler
2024-03-23 21:12:43,059 - INFO - Updater date and time: 2024-03-23 21:12:43.059320
2024-03-23 21:12:43,059 - INFO - Adding job tentatively -- it will be properly scheduled when the scheduler starts
2024-03-23 21:12:43,059 - INFO - Added job "run_procedure_sequence" to job store "default"
2024-03-23 21:12:43,059 - INFO - Scheduler started
2024-03-23 21:12:43,059 - INFO - Ending scheduler
2024-03-23 21:12:44,807 - INFO - Starting scheduler
2024-03-23 21:12:44,807 - INFO - Updater date and time: 2024-03-23 21:12:44.807033
2024-03-23 21:12:44,807 - INFO - Adding job tentatively -- it will be properly scheduled when the scheduler starts
2024-03-23 21:12:44,807 - INFO - Added job "run_procedure_sequence" to job store "default"
2024-03-23 21:12:44,807 - INFO - Scheduler started
2024-03-23 21:12:44,807 - INFO - Ending scheduler
2024-03-23 21:12:44,850 - INFO - Watching for file changes with StatReloader
2024-03-23 21:13:35,477 - INFO - C:\Users\sunny\Desktop\Development\python\TradePro\ml_models\utils\predictive_analysis.py changed, reloading.
2024-03-23 21:13:37,589 - INFO - Starting scheduler
2024-03-23 21:13:37,590 - INFO - Updater date and time: 2024-03-23 21:13:37.590953
2024-03-23 21:13:37,592 - INFO - Adding job tentatively -- it will be properly scheduled when the scheduler starts
2024-03-23 21:13:37,592 - INFO - Added job "run_procedure_sequence" to job store "default"
2024-03-23 21:13:37,592 - INFO - Scheduler started
2024-03-23 21:13:37,593 - INFO - Ending scheduler
2024-03-23 21:13:37,611 - INFO - Watching for file changes with StatReloader
2024-03-23 21:45:54,993 - INFO - Starting scheduler
2024-03-23 21:45:54,993 - INFO - Updater date and time: 2024-03-23 21:45:54.993609
2024-03-23 21:45:54,993 - INFO - Adding job tentatively -- it will be properly scheduled when the scheduler starts
2024-03-23 21:45:54,993 - INFO - Added job "run_procedure_sequence" to job store "default"
2024-03-23 21:45:54,993 - INFO - Scheduler started
2024-03-23 21:45:54,993 - INFO - Ending scheduler
2024-03-23 21:45:56,932 - INFO - Starting scheduler
2024-03-23 21:45:56,932 - INFO - Updater date and time: 2024-03-23 21:45:56.932040
2024-03-23 21:45:56,948 - INFO - Adding job tentatively -- it will be properly scheduled when the scheduler starts
2024-03-23 21:45:56,948 - INFO - Added job "run_procedure_sequence" to job store "default"
2024-03-23 21:45:56,948 - INFO - Scheduler started
2024-03-23 21:45:56,948 - INFO - Ending scheduler
2024-03-23 21:45:56,965 - INFO - Watching for file changes with StatReloader
2024-03-23 21:46:00,013 - INFO - Running job "run_procedure_sequence (trigger: interval[0:05:00], next run at: 2024-03-23 21:51:00 GMT)" (scheduled at 2024-03-23 21:46:00+00:00)
2024-03-23 21:46:00,013 - INFO - Inside the procedure sequence
2024-03-23 21:46:00,034 - INFO - Running job "run_procedure_sequence (trigger: interval[0:05:00], next run at: 2024-03-23 21:46:00 GMT)" (scheduled at 2024-03-23 21:46:00+00:00)
2024-03-23 21:46:00,034 - INFO - Inside the procedure sequence
2024-03-23 21:46:00,618 - ERROR - Job "run_procedure_sequence (trigger: interval[0:05:00], next run at: 2024-03-23 21:51:00 GMT)" raised an exception
Traceback (most recent call last):
  File "C:\Users\sunny\anaconda3\envs\myenv311test\Lib\site-packages\apscheduler\executors\base.py", line 125, in run_job
    retval = job.func(*job.args, **job.kwargs)
             ^^^^^^^^^^^^^^^^^^^^^^^^^^^^^^^^^
  File "C:\Users\sunny\Desktop\Development\python\TradePro\prices\updater.py", line 59, in run_procedure_sequence
    run_IG(ticker)
  File "C:\Users\sunny\Desktop\Development\python\TradePro\prices\IG_session\run_IG.py", line 149, in run_IG
    ig_service.create_session()
  File "C:\Users\sunny\Desktop\Development\python\TradePro\prices\IG_session\ig_service.py", line 393, in create_session
    self._set_headers(response.headers, True)
  File "C:\Users\sunny\Desktop\Development\python\TradePro\prices\IG_session\ig_service.py", line 450, in _set_headers
    self.CLIENT_TOKEN = response_headers['CST']
                        ~~~~~~~~~~~~~~~~^^^^^^^
  File "C:\Users\sunny\anaconda3\envs\myenv311test\Lib\site-packages\requests\structures.py", line 52, in __getitem__
    return self._store[key.lower()][1]
           ~~~~~~~~~~~^^^^^^^^^^^^^
KeyError: 'cst'
2024-03-23 21:46:08,445 - INFO - Job "run_procedure_sequence (trigger: interval[0:05:00], next run at: 2024-03-23 21:51:00 GMT)" executed successfully
2024-03-23 21:56:59,255 - INFO - Starting scheduler
2024-03-23 21:56:59,255 - INFO - Updater date and time: 2024-03-23 21:56:59.255283
2024-03-23 21:56:59,255 - INFO - Adding job tentatively -- it will be properly scheduled when the scheduler starts
2024-03-23 21:56:59,255 - INFO - Added job "run_procedure_sequence" to job store "default"
2024-03-23 21:56:59,255 - INFO - Scheduler started
2024-03-23 21:56:59,255 - INFO - Ending scheduler
2024-03-23 21:57:00,945 - INFO - Starting scheduler
2024-03-23 21:57:00,945 - INFO - Updater date and time: 2024-03-23 21:57:00.945911
2024-03-23 21:57:00,945 - INFO - Adding job tentatively -- it will be properly scheduled when the scheduler starts
2024-03-23 21:57:00,945 - INFO - Added job "run_procedure_sequence" to job store "default"
2024-03-23 21:57:00,945 - INFO - Scheduler started
2024-03-23 21:57:00,945 - INFO - Ending scheduler
2024-03-23 21:57:00,974 - INFO - Watching for file changes with StatReloader
2024-03-23 21:59:56,569 - INFO - Starting scheduler
2024-03-23 21:59:56,569 - INFO - Updater date and time: 2024-03-23 21:59:56.569920
2024-03-23 21:59:56,569 - INFO - Adding job tentatively -- it will be properly scheduled when the scheduler starts
2024-03-23 21:59:56,569 - INFO - Added job "run_procedure_sequence" to job store "default"
2024-03-23 21:59:56,569 - INFO - Scheduler started
2024-03-23 21:59:56,569 - INFO - Ending scheduler
2024-03-23 21:59:58,407 - INFO - Starting scheduler
2024-03-23 21:59:58,408 - INFO - Updater date and time: 2024-03-23 21:59:58.408802
2024-03-23 21:59:58,409 - INFO - Adding job tentatively -- it will be properly scheduled when the scheduler starts
2024-03-23 21:59:58,409 - INFO - Added job "run_procedure_sequence" to job store "default"
2024-03-23 21:59:58,409 - INFO - Scheduler started
2024-03-23 21:59:58,411 - INFO - Ending scheduler
2024-03-23 21:59:58,424 - INFO - Watching for file changes with StatReloader
2024-03-23 22:04:42,831 - INFO - Starting scheduler
2024-03-23 22:04:42,847 - INFO - Updater date and time: 2024-03-23 22:04:42.847560
2024-03-23 22:04:42,847 - INFO - Adding job tentatively -- it will be properly scheduled when the scheduler starts
2024-03-23 22:04:42,847 - INFO - Added job "run_procedure_sequence" to job store "default"
2024-03-23 22:04:42,847 - INFO - Scheduler started
2024-03-23 22:04:42,847 - INFO - Ending scheduler
2024-03-23 22:04:44,540 - INFO - Starting scheduler
2024-03-23 22:04:44,540 - INFO - Updater date and time: 2024-03-23 22:04:44.540695
2024-03-23 22:04:44,540 - INFO - Adding job tentatively -- it will be properly scheduled when the scheduler starts
2024-03-23 22:04:44,540 - INFO - Added job "run_procedure_sequence" to job store "default"
2024-03-23 22:04:44,540 - INFO - Scheduler started
2024-03-23 22:04:44,540 - INFO - Ending scheduler
2024-03-23 22:04:44,560 - INFO - Watching for file changes with StatReloader
2024-03-23 22:06:00,008 - INFO - Running job "run_procedure_sequence (trigger: interval[0:05:00], next run at: 2024-03-23 22:06:00 GMT)" (scheduled at 2024-03-23 22:06:00+00:00)
2024-03-23 22:06:00,008 - INFO - Running job "run_procedure_sequence (trigger: interval[0:05:00], next run at: 2024-03-23 22:11:00 GMT)" (scheduled at 2024-03-23 22:06:00+00:00)
2024-03-23 22:06:00,008 - INFO - Inside the procedure sequence
2024-03-23 22:06:00,008 - INFO - Inside the procedure sequence
2024-03-23 22:06:09,271 - INFO - Job "run_procedure_sequence (trigger: interval[0:05:00], next run at: 2024-03-23 22:11:00 GMT)" executed successfully
2024-03-23 22:06:09,348 - INFO - Job "run_procedure_sequence (trigger: interval[0:05:00], next run at: 2024-03-23 22:11:00 GMT)" executed successfully
2024-03-23 22:08:23,833 - INFO - Starting scheduler
2024-03-23 22:08:23,833 - INFO - Updater date and time: 2024-03-23 22:08:23.833217
2024-03-23 22:08:23,833 - INFO - Adding job tentatively -- it will be properly scheduled when the scheduler starts
2024-03-23 22:08:23,833 - INFO - Added job "run_procedure_sequence" to job store "default"
2024-03-23 22:08:23,833 - INFO - Scheduler started
2024-03-23 22:08:23,837 - INFO - Ending scheduler
2024-03-23 22:08:25,540 - INFO - Starting scheduler
2024-03-23 22:08:25,540 - INFO - Updater date and time: 2024-03-23 22:08:25.540183
2024-03-23 22:08:25,540 - INFO - Adding job tentatively -- it will be properly scheduled when the scheduler starts
2024-03-23 22:08:25,540 - INFO - Added job "run_procedure_sequence" to job store "default"
2024-03-23 22:08:25,540 - INFO - Scheduler started
2024-03-23 22:08:25,556 - INFO - Ending scheduler
2024-03-23 22:08:25,572 - INFO - Watching for file changes with StatReloader
2024-03-23 22:08:29,321 - WARNING - Not Found: /tickers/images/favicon.ico
2024-03-23 22:08:32,428 - WARNING - Not Found: /tickers/ticker/9f53d106-491e-43bc-8f19-f91352ee4426/images/favicon.ico
2024-03-23 22:11:23,278 - INFO - Starting scheduler
2024-03-23 22:11:23,278 - INFO - Updater date and time: 2024-03-23 22:11:23.278825
2024-03-23 22:11:23,278 - INFO - Adding job tentatively -- it will be properly scheduled when the scheduler starts
2024-03-23 22:11:23,278 - INFO - Added job "run_procedure_sequence" to job store "default"
2024-03-23 22:11:23,278 - INFO - Scheduler started
2024-03-23 22:11:23,295 - INFO - Ending scheduler
2024-03-23 22:11:25,054 - INFO - Starting scheduler
2024-03-23 22:11:25,055 - INFO - Updater date and time: 2024-03-23 22:11:25.055446
2024-03-23 22:11:25,055 - INFO - Adding job tentatively -- it will be properly scheduled when the scheduler starts
2024-03-23 22:11:25,056 - INFO - Added job "run_procedure_sequence" to job store "default"
2024-03-23 22:11:25,056 - INFO - Scheduler started
2024-03-23 22:11:25,057 - INFO - Ending scheduler
2024-03-23 22:11:25,073 - INFO - Watching for file changes with StatReloader
2024-03-23 22:15:03,294 - INFO - Starting scheduler
2024-03-23 22:15:03,294 - INFO - Updater date and time: 2024-03-23 22:15:03.294548
2024-03-23 22:15:03,294 - INFO - Adding job tentatively -- it will be properly scheduled when the scheduler starts
2024-03-23 22:15:03,294 - INFO - Added job "run_procedure_sequence" to job store "default"
2024-03-23 22:15:03,294 - INFO - Scheduler started
2024-03-23 22:15:03,294 - INFO - Ending scheduler
2024-03-23 22:15:05,042 - INFO - Starting scheduler
2024-03-23 22:15:05,043 - INFO - Updater date and time: 2024-03-23 22:15:05.043357
2024-03-23 22:15:05,044 - INFO - Adding job tentatively -- it will be properly scheduled when the scheduler starts
2024-03-23 22:15:05,045 - INFO - Added job "run_procedure_sequence" to job store "default"
2024-03-23 22:15:05,045 - INFO - Scheduler started
2024-03-23 22:15:05,045 - INFO - Ending scheduler
2024-03-23 22:15:05,059 - INFO - Watching for file changes with StatReloader
2024-03-23 22:15:41,793 - WARNING - Not Found: /prices/update-price/2fb07161-915b-4c3e-9556-0f3a88223d86/images/favicon.ico
2024-03-23 22:16:00,004 - INFO - Running job "run_procedure_sequence (trigger: interval[0:05:00], next run at: 2024-03-23 22:16:00 GMT)" (scheduled at 2024-03-23 22:16:00+00:00)
2024-03-23 22:16:00,004 - INFO - Inside the procedure sequence
2024-03-23 22:16:00,013 - INFO - Running job "run_procedure_sequence (trigger: interval[0:05:00], next run at: 2024-03-23 22:16:00 GMT)" (scheduled at 2024-03-23 22:16:00+00:00)
2024-03-23 22:16:00,013 - INFO - Inside the procedure sequence
2024-03-23 22:16:10,390 - INFO - Job "run_procedure_sequence (trigger: interval[0:05:00], next run at: 2024-03-23 22:21:00 GMT)" executed successfully
2024-03-23 22:16:10,452 - INFO - Job "run_procedure_sequence (trigger: interval[0:05:00], next run at: 2024-03-23 22:21:00 GMT)" executed successfully
2024-03-23 22:30:34,883 - INFO - Starting scheduler
2024-03-23 22:30:34,884 - INFO - Updater date and time: 2024-03-23 22:30:34.884801
2024-03-23 22:30:34,885 - INFO - Adding job tentatively -- it will be properly scheduled when the scheduler starts
2024-03-23 22:30:34,885 - INFO - Added job "run_procedure_sequence" to job store "default"
2024-03-23 22:30:34,885 - INFO - Scheduler started
2024-03-23 22:30:34,886 - INFO - Ending scheduler
2024-03-23 22:30:36,626 - INFO - Starting scheduler
2024-03-23 22:30:36,627 - INFO - Updater date and time: 2024-03-23 22:30:36.627964
2024-03-23 22:30:36,628 - INFO - Adding job tentatively -- it will be properly scheduled when the scheduler starts
2024-03-23 22:30:36,628 - INFO - Added job "run_procedure_sequence" to job store "default"
2024-03-23 22:30:36,628 - INFO - Scheduler started
2024-03-23 22:30:36,629 - INFO - Ending scheduler
2024-03-23 22:30:36,640 - INFO - Watching for file changes with StatReloader
2024-03-23 22:31:00,005 - INFO - Running job "run_procedure_sequence (trigger: interval[0:05:00], next run at: 2024-03-23 22:31:00 GMT)" (scheduled at 2024-03-23 22:31:00+00:00)
2024-03-23 22:31:00,005 - INFO - Running job "run_procedure_sequence (trigger: interval[0:05:00], next run at: 2024-03-23 22:36:00 GMT)" (scheduled at 2024-03-23 22:31:00+00:00)
2024-03-23 22:31:00,005 - INFO - Inside the procedure sequence
2024-03-23 22:31:00,005 - INFO - Inside the procedure sequence
2024-03-23 22:31:10,084 - INFO - Job "run_procedure_sequence (trigger: interval[0:05:00], next run at: 2024-03-23 22:36:00 GMT)" executed successfully
2024-03-23 22:31:10,152 - INFO - Job "run_procedure_sequence (trigger: interval[0:05:00], next run at: 2024-03-23 22:36:00 GMT)" executed successfully
2024-03-23 22:48:12,584 - INFO - Starting scheduler
2024-03-23 22:48:12,585 - INFO - Updater date and time: 2024-03-23 22:48:12.585627
2024-03-23 22:48:12,586 - INFO - Adding job tentatively -- it will be properly scheduled when the scheduler starts
2024-03-23 22:48:12,586 - INFO - Added job "run_procedure_sequence" to job store "default"
2024-03-23 22:48:12,586 - INFO - Scheduler started
2024-03-23 22:48:12,587 - INFO - Ending scheduler
2024-03-23 22:48:14,240 - INFO - Starting scheduler
2024-03-23 22:48:14,241 - INFO - Updater date and time: 2024-03-23 22:48:14.241523
2024-03-23 22:48:14,242 - INFO - Adding job tentatively -- it will be properly scheduled when the scheduler starts
2024-03-23 22:48:14,243 - INFO - Added job "run_procedure_sequence" to job store "default"
2024-03-23 22:48:14,243 - INFO - Scheduler started
2024-03-23 22:48:14,244 - INFO - Ending scheduler
2024-03-23 22:48:14,258 - INFO - Watching for file changes with StatReloader
2024-03-23 22:48:15,537 - WARNING - Not Found: /images/favicon.ico
2024-03-23 22:48:20,048 - WARNING - Not Found: /ml_models/ml-report/images/favicon.ico
2024-03-23 22:51:00,015 - INFO - Running job "run_procedure_sequence (trigger: interval[0:05:00], next run at: 2024-03-23 22:51:00 GMT)" (scheduled at 2024-03-23 22:51:00+00:00)
2024-03-23 22:51:00,016 - INFO - Inside the procedure sequence
2024-03-23 22:51:00,016 - INFO - Running job "run_procedure_sequence (trigger: interval[0:05:00], next run at: 2024-03-23 22:51:00 GMT)" (scheduled at 2024-03-23 22:51:00+00:00)
2024-03-23 22:51:00,016 - INFO - Inside the procedure sequence
2024-03-23 22:51:10,801 - INFO - Job "run_procedure_sequence (trigger: interval[0:05:00], next run at: 2024-03-23 22:56:00 GMT)" executed successfully
2024-03-23 22:51:10,852 - INFO - Job "run_procedure_sequence (trigger: interval[0:05:00], next run at: 2024-03-23 22:56:00 GMT)" executed successfully
2024-03-23 23:04:48,490 - INFO - Starting scheduler
2024-03-23 23:04:48,490 - INFO - Updater date and time: 2024-03-23 23:04:48.490132
2024-03-23 23:04:48,490 - INFO - Adding job tentatively -- it will be properly scheduled when the scheduler starts
2024-03-23 23:04:48,490 - INFO - Added job "run_procedure_sequence" to job store "default"
2024-03-23 23:04:48,490 - INFO - Scheduler started
2024-03-23 23:04:48,490 - INFO - Ending scheduler
2024-03-23 23:04:50,266 - INFO - Starting scheduler
2024-03-23 23:04:50,266 - INFO - Updater date and time: 2024-03-23 23:04:50.266041
2024-03-23 23:04:50,266 - INFO - Adding job tentatively -- it will be properly scheduled when the scheduler starts
2024-03-23 23:04:50,266 - INFO - Added job "run_procedure_sequence" to job store "default"
2024-03-23 23:04:50,266 - INFO - Scheduler started
2024-03-23 23:04:50,266 - INFO - Ending scheduler
2024-03-23 23:04:50,287 - INFO - Watching for file changes with StatReloader
2024-03-23 23:06:00,011 - INFO - Running job "run_procedure_sequence (trigger: interval[0:05:00], next run at: 2024-03-23 23:06:00 GMT)" (scheduled at 2024-03-23 23:06:00+00:00)
2024-03-23 23:06:00,011 - INFO - Running job "run_procedure_sequence (trigger: interval[0:05:00], next run at: 2024-03-23 23:11:00 GMT)" (scheduled at 2024-03-23 23:06:00+00:00)
2024-03-23 23:06:00,011 - INFO - Inside the procedure sequence
2024-03-23 23:06:00,011 - INFO - Inside the procedure sequence
2024-03-23 23:06:02,027 - ERROR - Job "run_procedure_sequence (trigger: interval[0:05:00], next run at: 2024-03-23 23:11:00 GMT)" raised an exception
Traceback (most recent call last):
  File "C:\Users\sunny\anaconda3\envs\myenv311test\Lib\site-packages\apscheduler\executors\base.py", line 125, in run_job
    retval = job.func(*job.args, **job.kwargs)
             ^^^^^^^^^^^^^^^^^^^^^^^^^^^^^^^^^
  File "C:\Users\sunny\Desktop\Development\python\TradePro\prices\updater.py", line 59, in run_procedure_sequence
    run_IG(ticker)
  File "C:\Users\sunny\Desktop\Development\python\TradePro\prices\IG_session\run_IG.py", line 149, in run_IG
    ig_service.create_session()
  File "C:\Users\sunny\Desktop\Development\python\TradePro\prices\IG_session\ig_service.py", line 393, in create_session
    self._set_headers(response.headers, True)
  File "C:\Users\sunny\Desktop\Development\python\TradePro\prices\IG_session\ig_service.py", line 450, in _set_headers
    self.CLIENT_TOKEN = response_headers['CST']
                        ~~~~~~~~~~~~~~~~^^^^^^^
  File "C:\Users\sunny\anaconda3\envs\myenv311test\Lib\site-packages\requests\structures.py", line 52, in __getitem__
    return self._store[key.lower()][1]
           ~~~~~~~~~~~^^^^^^^^^^^^^
KeyError: 'cst'
2024-03-23 23:06:11,045 - INFO - Job "run_procedure_sequence (trigger: interval[0:05:00], next run at: 2024-03-23 23:11:00 GMT)" executed successfully
2024-03-23 23:21:33,770 - INFO - Starting scheduler
2024-03-23 23:21:33,770 - INFO - Updater date and time: 2024-03-23 23:21:33.770618
2024-03-23 23:21:33,770 - INFO - Adding job tentatively -- it will be properly scheduled when the scheduler starts
2024-03-23 23:21:33,770 - INFO - Added job "run_procedure_sequence" to job store "default"
2024-03-23 23:21:33,770 - INFO - Scheduler started
2024-03-23 23:21:33,770 - INFO - Ending scheduler
2024-03-23 23:21:35,462 - INFO - Starting scheduler
2024-03-23 23:21:35,462 - INFO - Updater date and time: 2024-03-23 23:21:35.462499
2024-03-23 23:21:35,462 - INFO - Adding job tentatively -- it will be properly scheduled when the scheduler starts
2024-03-23 23:21:35,462 - INFO - Added job "run_procedure_sequence" to job store "default"
2024-03-23 23:21:35,462 - INFO - Scheduler started
2024-03-23 23:21:35,462 - INFO - Ending scheduler
2024-03-23 23:21:35,492 - INFO - Watching for file changes with StatReloader
2024-03-23 23:21:40,974 - ERROR - Internal Server Error: /ml_models/ml-manual/
Traceback (most recent call last):
  File "C:\Users\sunny\anaconda3\envs\myenv311test\Lib\site-packages\django\core\handlers\exception.py", line 55, in inner
    response = get_response(request)
               ^^^^^^^^^^^^^^^^^^^^^
  File "C:\Users\sunny\anaconda3\envs\myenv311test\Lib\site-packages\django\core\handlers\base.py", line 197, in _get_response
    response = wrapped_callback(request, *callback_args, **callback_kwargs)
               ^^^^^^^^^^^^^^^^^^^^^^^^^^^^^^^^^^^^^^^^^^^^^^^^^^^^^^^^^^^^
  File "C:\Users\sunny\Desktop\Development\python\TradePro\ml_models\views.py", line 339, in ml_manual
    last_price_stats = dp.stats_df_gen(prices_df,2)
                       ^^^^^^^^^^^^^^^
AttributeError: 'NoneType' object has no attribute 'stats_df_gen'
2024-03-23 23:21:41,081 - WARNING - Not Found: /favicon.ico
2024-03-23 23:23:07,079 - INFO - C:\Users\sunny\Desktop\Development\python\TradePro\ml_models\views.py changed, reloading.
2024-03-23 23:23:09,117 - INFO - Starting scheduler
2024-03-23 23:23:09,117 - INFO - Updater date and time: 2024-03-23 23:23:09.117242
2024-03-23 23:23:09,117 - INFO - Adding job tentatively -- it will be properly scheduled when the scheduler starts
2024-03-23 23:23:09,117 - INFO - Added job "run_procedure_sequence" to job store "default"
2024-03-23 23:23:09,117 - INFO - Scheduler started
2024-03-23 23:23:09,117 - INFO - Ending scheduler
2024-03-23 23:23:09,137 - INFO - Watching for file changes with StatReloader
2024-03-23 23:23:20,333 - INFO - C:\Users\sunny\Desktop\Development\python\TradePro\ml_models\views.py changed, reloading.
2024-03-23 23:23:22,350 - INFO - Starting scheduler
2024-03-23 23:23:22,351 - INFO - Updater date and time: 2024-03-23 23:23:22.351590
2024-03-23 23:23:22,352 - INFO - Adding job tentatively -- it will be properly scheduled when the scheduler starts
2024-03-23 23:23:22,353 - INFO - Added job "run_procedure_sequence" to job store "default"
2024-03-23 23:23:22,353 - INFO - Scheduler started
2024-03-23 23:23:22,354 - INFO - Ending scheduler
2024-03-23 23:23:22,370 - INFO - Watching for file changes with StatReloader
2024-03-23 23:24:29,657 - INFO - C:\Users\sunny\Desktop\Development\python\TradePro\ml_models\views.py changed, reloading.
2024-03-23 23:24:31,864 - INFO - Starting scheduler
2024-03-23 23:24:31,864 - INFO - Updater date and time: 2024-03-23 23:24:31.864083
2024-03-23 23:24:31,871 - INFO - Adding job tentatively -- it will be properly scheduled when the scheduler starts
2024-03-23 23:24:31,871 - INFO - Added job "run_procedure_sequence" to job store "default"
2024-03-23 23:24:31,871 - INFO - Scheduler started
2024-03-23 23:24:31,872 - INFO - Ending scheduler
2024-03-23 23:24:31,887 - INFO - Watching for file changes with StatReloader
2024-03-23 23:30:50,544 - INFO - Starting scheduler
2024-03-23 23:30:50,544 - INFO - Updater date and time: 2024-03-23 23:30:50.544671
2024-03-23 23:30:50,544 - INFO - Adding job tentatively -- it will be properly scheduled when the scheduler starts
2024-03-23 23:30:50,544 - INFO - Added job "run_procedure_sequence" to job store "default"
2024-03-23 23:30:50,544 - INFO - Scheduler started
2024-03-23 23:30:50,544 - INFO - Ending scheduler
2024-03-23 23:30:52,289 - INFO - Starting scheduler
2024-03-23 23:30:52,290 - INFO - Updater date and time: 2024-03-23 23:30:52.290465
2024-03-23 23:30:52,291 - INFO - Adding job tentatively -- it will be properly scheduled when the scheduler starts
2024-03-23 23:30:52,291 - INFO - Added job "run_procedure_sequence" to job store "default"
2024-03-23 23:30:52,291 - INFO - Scheduler started
2024-03-23 23:30:52,292 - INFO - Ending scheduler
2024-03-23 23:30:52,303 - INFO - Watching for file changes with StatReloader
2024-03-23 23:30:56,502 - WARNING - Not Found: /ml_models/ml-manual/images/favicon.ico
2024-03-23 23:31:00,008 - INFO - Running job "run_procedure_sequence (trigger: interval[0:05:00], next run at: 2024-03-23 23:31:00 GMT)" (scheduled at 2024-03-23 23:31:00+00:00)
2024-03-23 23:31:00,009 - INFO - Inside the procedure sequence
2024-03-23 23:31:00,011 - INFO - Running job "run_procedure_sequence (trigger: interval[0:05:00], next run at: 2024-03-23 23:31:00 GMT)" (scheduled at 2024-03-23 23:31:00+00:00)
2024-03-23 23:31:00,012 - INFO - Inside the procedure sequence
2024-03-23 23:31:11,340 - INFO - Job "run_procedure_sequence (trigger: interval[0:05:00], next run at: 2024-03-23 23:36:00 GMT)" executed successfully
2024-03-23 23:31:12,734 - INFO - Job "run_procedure_sequence (trigger: interval[0:05:00], next run at: 2024-03-23 23:36:00 GMT)" executed successfully
2024-03-23 23:36:47,065 - INFO - Starting scheduler
2024-03-23 23:36:47,080 - INFO - Updater date and time: 2024-03-23 23:36:47.080982
2024-03-23 23:36:47,080 - INFO - Adding job tentatively -- it will be properly scheduled when the scheduler starts
2024-03-23 23:36:47,080 - INFO - Added job "run_procedure_sequence" to job store "default"
2024-03-23 23:36:47,080 - INFO - Scheduler started
2024-03-23 23:36:47,080 - INFO - Ending scheduler
2024-03-23 23:36:48,786 - INFO - Starting scheduler
2024-03-23 23:36:48,786 - INFO - Updater date and time: 2024-03-23 23:36:48.786783
2024-03-23 23:36:48,788 - INFO - Adding job tentatively -- it will be properly scheduled when the scheduler starts
2024-03-23 23:36:48,788 - INFO - Added job "run_procedure_sequence" to job store "default"
2024-03-23 23:36:48,788 - INFO - Scheduler started
2024-03-23 23:36:48,788 - INFO - Ending scheduler
2024-03-23 23:36:48,807 - INFO - Watching for file changes with StatReloader
2024-03-23 23:53:20,219 - INFO - Starting scheduler
2024-03-23 23:53:20,219 - INFO - Updater date and time: 2024-03-23 23:53:20.219303
2024-03-23 23:53:20,219 - INFO - Adding job tentatively -- it will be properly scheduled when the scheduler starts
2024-03-23 23:53:20,219 - INFO - Added job "run_procedure_sequence" to job store "default"
2024-03-23 23:53:20,219 - INFO - Scheduler started
2024-03-23 23:53:20,219 - INFO - Ending scheduler
2024-03-23 23:53:21,936 - INFO - Starting scheduler
2024-03-23 23:53:21,936 - INFO - Updater date and time: 2024-03-23 23:53:21.936480
2024-03-23 23:53:21,936 - INFO - Adding job tentatively -- it will be properly scheduled when the scheduler starts
2024-03-23 23:53:21,936 - INFO - Added job "run_procedure_sequence" to job store "default"
2024-03-23 23:53:21,936 - INFO - Scheduler started
2024-03-23 23:53:21,936 - INFO - Ending scheduler
2024-03-23 23:53:21,958 - INFO - Watching for file changes with StatReloader
2024-03-23 23:53:25,750 - ERROR - Internal Server Error: /ml_models/ml-report/
Traceback (most recent call last):
  File "C:\Users\sunny\anaconda3\envs\myenv311test\Lib\site-packages\django\core\handlers\exception.py", line 55, in inner
    response = get_response(request)
               ^^^^^^^^^^^^^^^^^^^^^
  File "C:\Users\sunny\anaconda3\envs\myenv311test\Lib\site-packages\django\core\handlers\base.py", line 197, in _get_response
    response = wrapped_callback(request, *callback_args, **callback_kwargs)
               ^^^^^^^^^^^^^^^^^^^^^^^^^^^^^^^^^^^^^^^^^^^^^^^^^^^^^^^^^^^^
  File "C:\Users\sunny\Desktop\Development\python\TradePro\ml_models\views.py", line 236, in ml_report
    model_comparer = ModelComparer(pred_historical_v4, pred_historical_v5, pred_historical_1h_v5, 3, 1 )
                     ^^^^^^^^^^^^^^^^^^^^^^^^^^^^^^^^^^^^^^^^^^^^^^^^^^^^^^^^^^^^^^^^^^^^^^^^^^^^^^^^^^^
  File "C:\Users\sunny\Desktop\Development\python\TradePro\ml_models\utils\analysis_comments.py", line 58, in __init__
    self.compare_versions()  # Call the comparison method during initialization
    ^^^^^^^^^^^^^^^^^^^^^^^
  File "C:\Users\sunny\Desktop\Development\python\TradePro\ml_models\utils\analysis_comments.py", line 129, in compare_versions
    self.bb_entry()
  File "C:\Users\sunny\Desktop\Development\python\TradePro\ml_models\utils\analysis_comments.py", line 133, in bb_entry
    upper_bb = self.model_dict1[key_label1][2]['bb4_results']['upper_bb4']
               ~~~~~~~~~~~~~~~~~~~~~~~~~~~~~~~^^^^^^^^^^^^^^^
KeyError: 'bb4_results'
2024-03-23 23:53:56,040 - INFO - C:\Users\sunny\Desktop\Development\python\TradePro\ml_models\utils\analysis_comments.py changed, reloading.
2024-03-23 23:53:58,323 - INFO - Starting scheduler
2024-03-23 23:53:58,323 - INFO - Updater date and time: 2024-03-23 23:53:58.323430
2024-03-23 23:53:58,323 - INFO - Adding job tentatively -- it will be properly scheduled when the scheduler starts
2024-03-23 23:53:58,323 - INFO - Added job "run_procedure_sequence" to job store "default"
2024-03-23 23:53:58,323 - INFO - Scheduler started
2024-03-23 23:53:58,323 - INFO - Ending scheduler
2024-03-23 23:53:58,344 - INFO - Watching for file changes with StatReloader
2024-03-23 23:54:06,076 - ERROR - Internal Server Error: /ml_models/ml-report/
Traceback (most recent call last):
  File "C:\Users\sunny\anaconda3\envs\myenv311test\Lib\site-packages\django\core\handlers\exception.py", line 55, in inner
    response = get_response(request)
               ^^^^^^^^^^^^^^^^^^^^^
  File "C:\Users\sunny\anaconda3\envs\myenv311test\Lib\site-packages\django\core\handlers\base.py", line 197, in _get_response
    response = wrapped_callback(request, *callback_args, **callback_kwargs)
               ^^^^^^^^^^^^^^^^^^^^^^^^^^^^^^^^^^^^^^^^^^^^^^^^^^^^^^^^^^^^
  File "C:\Users\sunny\Desktop\Development\python\TradePro\ml_models\views.py", line 236, in ml_report
    model_comparer = ModelComparer(pred_historical_v4, pred_historical_v5, pred_historical_1h_v5, 3, 1 )
                     ^^^^^^^^^^^^^^^^^^^^^^^^^^^^^^^^^^^^^^^^^^^^^^^^^^^^^^^^^^^^^^^^^^^^^^^^^^^^^^^^^^^
  File "C:\Users\sunny\Desktop\Development\python\TradePro\ml_models\utils\analysis_comments.py", line 58, in __init__
    self.compare_versions()  # Call the comparison method during initialization
    ^^^^^^^^^^^^^^^^^^^^^^^
  File "C:\Users\sunny\Desktop\Development\python\TradePro\ml_models\utils\analysis_comments.py", line 129, in compare_versions
    self.bb_entry()
  File "C:\Users\sunny\Desktop\Development\python\TradePro\ml_models\utils\analysis_comments.py", line 133, in bb_entry
    upper_bb = self.model_dict1[key_label1][3]['bb4_results']['upper_bb4']
               ~~~~~~~~~~~~~~~~~~~~~~~~~~~~~~~^^^^^^^^^^^^^^^
KeyError: 'bb4_results'
2024-03-23 23:54:36,722 - INFO - Starting scheduler
2024-03-23 23:54:36,722 - INFO - Updater date and time: 2024-03-23 23:54:36.722938
2024-03-23 23:54:36,722 - INFO - Adding job tentatively -- it will be properly scheduled when the scheduler starts
2024-03-23 23:54:36,722 - INFO - Added job "run_procedure_sequence" to job store "default"
2024-03-23 23:54:36,722 - INFO - Scheduler started
2024-03-23 23:54:36,722 - INFO - Ending scheduler
2024-03-23 23:54:38,616 - INFO - Starting scheduler
2024-03-23 23:54:38,617 - INFO - Updater date and time: 2024-03-23 23:54:38.617059
2024-03-23 23:54:38,618 - INFO - Adding job tentatively -- it will be properly scheduled when the scheduler starts
2024-03-23 23:54:38,618 - INFO - Added job "run_procedure_sequence" to job store "default"
2024-03-23 23:54:38,618 - INFO - Scheduler started
2024-03-23 23:54:38,619 - INFO - Ending scheduler
2024-03-23 23:54:38,649 - INFO - Watching for file changes with StatReloader
2024-03-23 23:54:40,096 - WARNING - Not Found: /images/favicon.ico
2024-03-23 23:54:44,651 - WARNING - Not Found: /ml_models/ml-report/images/favicon.ico
2024-03-23 23:59:02,748 - INFO - Starting scheduler
2024-03-23 23:59:02,748 - INFO - Updater date and time: 2024-03-23 23:59:02.748510
2024-03-23 23:59:02,748 - INFO - Adding job tentatively -- it will be properly scheduled when the scheduler starts
2024-03-23 23:59:02,748 - INFO - Added job "run_procedure_sequence" to job store "default"
2024-03-23 23:59:02,748 - INFO - Scheduler started
2024-03-23 23:59:02,748 - INFO - Ending scheduler
2024-03-23 23:59:04,494 - INFO - Starting scheduler
2024-03-23 23:59:04,495 - INFO - Updater date and time: 2024-03-23 23:59:04.495460
2024-03-23 23:59:04,496 - INFO - Adding job tentatively -- it will be properly scheduled when the scheduler starts
2024-03-23 23:59:04,496 - INFO - Added job "run_procedure_sequence" to job store "default"
2024-03-23 23:59:04,496 - INFO - Scheduler started
2024-03-23 23:59:04,497 - INFO - Ending scheduler
2024-03-23 23:59:04,515 - INFO - Watching for file changes with StatReloader
2024-03-23 23:59:06,449 - WARNING - Not Found: /images/favicon.ico
2024-03-23 23:59:12,340 - WARNING - Not Found: /ml_models/ml-report/images/favicon.ico
2024-03-24 00:06:38,253 - INFO - Starting scheduler
2024-03-24 00:06:38,254 - INFO - Updater date and time: 2024-03-24 00:06:38.254512
2024-03-24 00:06:38,255 - INFO - Adding job tentatively -- it will be properly scheduled when the scheduler starts
2024-03-24 00:06:38,255 - INFO - Added job "run_procedure_sequence" to job store "default"
2024-03-24 00:06:38,255 - INFO - Scheduler started
2024-03-24 00:06:38,257 - INFO - Ending scheduler
2024-03-24 00:06:39,992 - INFO - Starting scheduler
2024-03-24 00:06:39,992 - INFO - Updater date and time: 2024-03-24 00:06:39.992053
2024-03-24 00:06:39,992 - INFO - Adding job tentatively -- it will be properly scheduled when the scheduler starts
2024-03-24 00:06:39,992 - INFO - Added job "run_procedure_sequence" to job store "default"
2024-03-24 00:06:39,992 - INFO - Scheduler started
2024-03-24 00:06:39,992 - INFO - Ending scheduler
2024-03-24 00:06:40,017 - INFO - Watching for file changes with StatReloader
2024-03-24 00:06:41,389 - WARNING - Not Found: /images/favicon.ico
2024-03-24 00:06:45,770 - WARNING - Not Found: /ml_models/ml-report/images/favicon.ico
2024-03-24 00:07:40,055 - ERROR - Internal Server Error: /ml_models/ml-report/
Traceback (most recent call last):
  File "C:\Users\sunny\anaconda3\envs\myenv311test\Lib\site-packages\django\core\handlers\exception.py", line 55, in inner
    response = get_response(request)
               ^^^^^^^^^^^^^^^^^^^^^
  File "C:\Users\sunny\anaconda3\envs\myenv311test\Lib\site-packages\django\core\handlers\base.py", line 197, in _get_response
    response = wrapped_callback(request, *callback_args, **callback_kwargs)
               ^^^^^^^^^^^^^^^^^^^^^^^^^^^^^^^^^^^^^^^^^^^^^^^^^^^^^^^^^^^^
  File "C:\Users\sunny\Desktop\Development\python\TradePro\ml_models\views.py", line 236, in ml_report
    model_comparer = ModelComparer(pred_historical_v4, pred_historical_v5, pred_historical_1h_v5, 3, 1 )
                     ^^^^^^^^^^^^^^^^^^^^^^^^^^^^^^^^^^^^^^^^^^^^^^^^^^^^^^^^^^^^^^^^^^^^^^^^^^^^^^^^^^^
  File "C:\Users\sunny\Desktop\Development\python\TradePro\ml_models\utils\analysis_comments.py", line 58, in __init__
    self.compare_versions()  # Call the comparison method during initialization
    ^^^^^^^^^^^^^^^^^^^^^^^
  File "C:\Users\sunny\Desktop\Development\python\TradePro\ml_models\utils\analysis_comments.py", line 129, in compare_versions
    self.bb_entry()
  File "C:\Users\sunny\Desktop\Development\python\TradePro\ml_models\utils\analysis_comments.py", line 133, in bb_entry
    upper_bb = self.model_dict1[key_label1][4]['bb4_results']['upper_bb4']
               ~~~~~~~~~~~~~~~~~~~~~~~~~~~~^^^
IndexError: list index out of range
2024-03-24 00:07:40,159 - WARNING - Not Found: /favicon.ico
2024-03-24 08:22:03,288 - INFO - Starting scheduler
2024-03-24 08:22:03,288 - INFO - Updater date and time: 2024-03-24 08:22:03.288408
2024-03-24 08:22:03,288 - INFO - Adding job tentatively -- it will be properly scheduled when the scheduler starts
2024-03-24 08:22:03,288 - INFO - Added job "run_procedure_sequence" to job store "default"
2024-03-24 08:22:03,288 - INFO - Scheduler started
2024-03-24 08:22:03,288 - INFO - Ending scheduler
2024-03-24 08:22:05,170 - INFO - Starting scheduler
2024-03-24 08:22:05,170 - INFO - Updater date and time: 2024-03-24 08:22:05.170894
2024-03-24 08:22:05,170 - INFO - Adding job tentatively -- it will be properly scheduled when the scheduler starts
2024-03-24 08:22:05,170 - INFO - Added job "run_procedure_sequence" to job store "default"
2024-03-24 08:22:05,170 - INFO - Scheduler started
2024-03-24 08:22:05,170 - INFO - Ending scheduler
2024-03-24 08:22:05,194 - INFO - Watching for file changes with StatReloader
2024-03-24 08:22:10,275 - WARNING - Not Found: /images/favicon.ico
2024-03-24 08:22:26,262 - WARNING - Not Found: /ml_models/ml-predictions/images/favicon.ico
2024-03-24 08:22:29,634 - WARNING - Not Found: /ml_models/export-model-results/images/favicon.ico
2024-03-24 08:30:15,846 - INFO - Starting scheduler
2024-03-24 08:30:15,846 - INFO - Updater date and time: 2024-03-24 08:30:15.846716
2024-03-24 08:30:15,846 - INFO - Adding job tentatively -- it will be properly scheduled when the scheduler starts
2024-03-24 08:30:15,846 - INFO - Added job "run_procedure_sequence" to job store "default"
2024-03-24 08:30:15,846 - INFO - Scheduler started
2024-03-24 08:30:15,862 - INFO - Ending scheduler
2024-03-24 08:30:15,885 - INFO - Watching for file changes with StatReloader
2024-03-24 08:30:44,166 - ERROR - Internal Server Error: /ml_models/export-model-results/
Traceback (most recent call last):
  File "C:\Users\sunny\anaconda3\envs\myenv311test\Lib\site-packages\django\core\handlers\exception.py", line 55, in inner
    response = get_response(request)
               ^^^^^^^^^^^^^^^^^^^^^
  File "C:\Users\sunny\anaconda3\envs\myenv311test\Lib\site-packages\django\core\handlers\base.py", line 197, in _get_response
    response = wrapped_callback(request, *callback_args, **callback_kwargs)
               ^^^^^^^^^^^^^^^^^^^^^^^^^^^^^^^^^^^^^^^^^^^^^^^^^^^^^^^^^^^^
  File "C:\Users\sunny\Desktop\Development\python\TradePro\ml_models\views.py", line 380, in export_model_results
    model_results = trade_forecast_assessment(model_version)
                    ^^^^^^^^^^^^^^^^^^^^^^^^^^^^^^^^^^^^^^^^
  File "C:\Users\sunny\Desktop\Development\python\TradePro\ml_models\utils\predictive_analysis.py", line 280, in trade_forecast_assessment
    dp = StandardPriceProcessing(ticker=ticker)
                                        ^^^^^^
NameError: name 'ticker' is not defined
2024-03-24 08:30:44,275 - WARNING - Not Found: /favicon.ico
2024-03-24 08:31:00,002 - INFO - Running job "run_procedure_sequence (trigger: interval[0:05:00], next run at: 2024-03-24 08:31:00 GMT)" (scheduled at 2024-03-24 08:31:00+00:00)
2024-03-24 08:31:00,002 - INFO - Inside the procedure sequence
2024-03-24 08:31:08,756 - INFO - Job "run_procedure_sequence (trigger: interval[0:05:00], next run at: 2024-03-24 08:36:00 GMT)" executed successfully
2024-03-24 08:38:08,064 - INFO - Starting scheduler
2024-03-24 08:38:08,064 - INFO - Updater date and time: 2024-03-24 08:38:08.064897
2024-03-24 08:38:08,064 - INFO - Adding job tentatively -- it will be properly scheduled when the scheduler starts
2024-03-24 08:38:08,064 - INFO - Added job "run_procedure_sequence" to job store "default"
2024-03-24 08:38:08,064 - INFO - Scheduler started
2024-03-24 08:38:08,080 - INFO - Ending scheduler
2024-03-24 08:38:09,963 - INFO - Starting scheduler
2024-03-24 08:38:09,964 - INFO - Updater date and time: 2024-03-24 08:38:09.964252
2024-03-24 08:38:09,964 - INFO - Adding job tentatively -- it will be properly scheduled when the scheduler starts
2024-03-24 08:38:09,964 - INFO - Added job "run_procedure_sequence" to job store "default"
2024-03-24 08:38:09,964 - INFO - Scheduler started
2024-03-24 08:38:09,967 - INFO - Ending scheduler
2024-03-24 08:38:09,984 - INFO - Watching for file changes with StatReloader
2024-03-24 08:38:26,556 - ERROR - Internal Server Error: /ml_models/ml-predictions/
Traceback (most recent call last):
  File "C:\Users\sunny\anaconda3\envs\myenv311test\Lib\site-packages\django\core\handlers\exception.py", line 55, in inner
    response = get_response(request)
               ^^^^^^^^^^^^^^^^^^^^^
  File "C:\Users\sunny\anaconda3\envs\myenv311test\Lib\site-packages\django\core\handlers\base.py", line 197, in _get_response
    response = wrapped_callback(request, *callback_args, **callback_kwargs)
               ^^^^^^^^^^^^^^^^^^^^^^^^^^^^^^^^^^^^^^^^^^^^^^^^^^^^^^^^^^^^
  File "C:\Users\sunny\Desktop\Development\python\TradePro\ml_models\views.py", line 100, in ml_predictions
    return render(request, 'ml_models/ml_predictions.html', context)
           ^^^^^^^^^^^^^^^^^^^^^^^^^^^^^^^^^^^^^^^^^^^^^^^^^^^^^^^^^
  File "C:\Users\sunny\anaconda3\envs\myenv311test\Lib\site-packages\django\shortcuts.py", line 24, in render
    content = loader.render_to_string(template_name, context, request, using=using)
              ^^^^^^^^^^^^^^^^^^^^^^^^^^^^^^^^^^^^^^^^^^^^^^^^^^^^^^^^^^^^^^^^^^^^^
  File "C:\Users\sunny\anaconda3\envs\myenv311test\Lib\site-packages\django\template\loader.py", line 62, in render_to_string
    return template.render(context, request)
           ^^^^^^^^^^^^^^^^^^^^^^^^^^^^^^^^^
  File "C:\Users\sunny\anaconda3\envs\myenv311test\Lib\site-packages\django\template\backends\django.py", line 61, in render
    return self.template.render(context)
           ^^^^^^^^^^^^^^^^^^^^^^^^^^^^^
  File "C:\Users\sunny\anaconda3\envs\myenv311test\Lib\site-packages\django\template\base.py", line 175, in render
    return self._render(context)
           ^^^^^^^^^^^^^^^^^^^^^
  File "C:\Users\sunny\anaconda3\envs\myenv311test\Lib\site-packages\django\template\base.py", line 167, in _render
    return self.nodelist.render(context)
           ^^^^^^^^^^^^^^^^^^^^^^^^^^^^^
  File "C:\Users\sunny\anaconda3\envs\myenv311test\Lib\site-packages\django\template\base.py", line 1005, in render
    return SafeString("".join([node.render_annotated(context) for node in self]))
                              ^^^^^^^^^^^^^^^^^^^^^^^^^^^^^^^^^^^^^^^^^^^^^^^^^
  File "C:\Users\sunny\anaconda3\envs\myenv311test\Lib\site-packages\django\template\base.py", line 1005, in <listcomp>
    return SafeString("".join([node.render_annotated(context) for node in self]))
                               ^^^^^^^^^^^^^^^^^^^^^^^^^^^^^^
  File "C:\Users\sunny\anaconda3\envs\myenv311test\Lib\site-packages\django\template\base.py", line 966, in render_annotated
    return self.render(context)
           ^^^^^^^^^^^^^^^^^^^^
  File "C:\Users\sunny\anaconda3\envs\myenv311test\Lib\site-packages\django\template\loader_tags.py", line 157, in render
    return compiled_parent._render(context)
           ^^^^^^^^^^^^^^^^^^^^^^^^^^^^^^^^
  File "C:\Users\sunny\anaconda3\envs\myenv311test\Lib\site-packages\django\template\base.py", line 167, in _render
    return self.nodelist.render(context)
           ^^^^^^^^^^^^^^^^^^^^^^^^^^^^^
  File "C:\Users\sunny\anaconda3\envs\myenv311test\Lib\site-packages\django\template\base.py", line 1005, in render
    return SafeString("".join([node.render_annotated(context) for node in self]))
                              ^^^^^^^^^^^^^^^^^^^^^^^^^^^^^^^^^^^^^^^^^^^^^^^^^
  File "C:\Users\sunny\anaconda3\envs\myenv311test\Lib\site-packages\django\template\base.py", line 1005, in <listcomp>
    return SafeString("".join([node.render_annotated(context) for node in self]))
                               ^^^^^^^^^^^^^^^^^^^^^^^^^^^^^^
  File "C:\Users\sunny\anaconda3\envs\myenv311test\Lib\site-packages\django\template\base.py", line 966, in render_annotated
    return self.render(context)
           ^^^^^^^^^^^^^^^^^^^^
  File "C:\Users\sunny\anaconda3\envs\myenv311test\Lib\site-packages\django\template\loader_tags.py", line 63, in render
    result = block.nodelist.render(context)
             ^^^^^^^^^^^^^^^^^^^^^^^^^^^^^^
  File "C:\Users\sunny\anaconda3\envs\myenv311test\Lib\site-packages\django\template\base.py", line 1005, in render
    return SafeString("".join([node.render_annotated(context) for node in self]))
                              ^^^^^^^^^^^^^^^^^^^^^^^^^^^^^^^^^^^^^^^^^^^^^^^^^
  File "C:\Users\sunny\anaconda3\envs\myenv311test\Lib\site-packages\django\template\base.py", line 1005, in <listcomp>
    return SafeString("".join([node.render_annotated(context) for node in self]))
                               ^^^^^^^^^^^^^^^^^^^^^^^^^^^^^^
  File "C:\Users\sunny\anaconda3\envs\myenv311test\Lib\site-packages\django\template\base.py", line 966, in render_annotated
    return self.render(context)
           ^^^^^^^^^^^^^^^^^^^^
  File "C:\Users\sunny\anaconda3\envs\myenv311test\Lib\site-packages\django\template\base.py", line 1064, in render
    output = self.filter_expression.resolve(context)
             ^^^^^^^^^^^^^^^^^^^^^^^^^^^^^^^^^^^^^^^
  File "C:\Users\sunny\anaconda3\envs\myenv311test\Lib\site-packages\django\template\base.py", line 715, in resolve
    obj = self.var.resolve(context)
          ^^^^^^^^^^^^^^^^^^^^^^^^^
  File "C:\Users\sunny\anaconda3\envs\myenv311test\Lib\site-packages\django\template\base.py", line 847, in resolve
    value = self._resolve_lookup(context)
            ^^^^^^^^^^^^^^^^^^^^^^^^^^^^^
  File "C:\Users\sunny\anaconda3\envs\myenv311test\Lib\site-packages\django\template\base.py", line 914, in _resolve_lookup
    current = current()
              ^^^^^^^^^
  File "C:\Users\sunny\anaconda3\envs\myenv311test\Lib\site-packages\django\forms\utils.py", line 84, in as_p
    return self.render(self.template_name_p)
           ^^^^^^^^^^^^^^^^^^^^^^^^^^^^^^^^^
  File "C:\Users\sunny\anaconda3\envs\myenv311test\Lib\site-packages\django\forms\utils.py", line 75, in render
    return mark_safe(renderer.render(template, context))
                     ^^^^^^^^^^^^^^^^^^^^^^^^^^^^^^^^^^
  File "C:\Users\sunny\anaconda3\envs\myenv311test\Lib\site-packages\django\forms\renderers.py", line 29, in render
    return template.render(context, request=request).strip()
           ^^^^^^^^^^^^^^^^^^^^^^^^^^^^^^^^^^^^^^^^^
  File "C:\Users\sunny\anaconda3\envs\myenv311test\Lib\site-packages\django\template\backends\django.py", line 61, in render
    return self.template.render(context)
           ^^^^^^^^^^^^^^^^^^^^^^^^^^^^^
  File "C:\Users\sunny\anaconda3\envs\myenv311test\Lib\site-packages\django\template\base.py", line 175, in render
    return self._render(context)
           ^^^^^^^^^^^^^^^^^^^^^
  File "C:\Users\sunny\anaconda3\envs\myenv311test\Lib\site-packages\django\template\base.py", line 167, in _render
    return self.nodelist.render(context)
           ^^^^^^^^^^^^^^^^^^^^^^^^^^^^^
  File "C:\Users\sunny\anaconda3\envs\myenv311test\Lib\site-packages\django\template\base.py", line 1005, in render
    return SafeString("".join([node.render_annotated(context) for node in self]))
                              ^^^^^^^^^^^^^^^^^^^^^^^^^^^^^^^^^^^^^^^^^^^^^^^^^
  File "C:\Users\sunny\anaconda3\envs\myenv311test\Lib\site-packages\django\template\base.py", line 1005, in <listcomp>
    return SafeString("".join([node.render_annotated(context) for node in self]))
                               ^^^^^^^^^^^^^^^^^^^^^^^^^^^^^^
  File "C:\Users\sunny\anaconda3\envs\myenv311test\Lib\site-packages\django\template\base.py", line 966, in render_annotated
    return self.render(context)
           ^^^^^^^^^^^^^^^^^^^^
  File "C:\Users\sunny\anaconda3\envs\myenv311test\Lib\site-packages\django\template\defaulttags.py", line 238, in render
    nodelist.append(node.render_annotated(context))
                    ^^^^^^^^^^^^^^^^^^^^^^^^^^^^^^
  File "C:\Users\sunny\anaconda3\envs\myenv311test\Lib\site-packages\django\template\base.py", line 966, in render_annotated
    return self.render(context)
           ^^^^^^^^^^^^^^^^^^^^
  File "C:\Users\sunny\anaconda3\envs\myenv311test\Lib\site-packages\django\template\base.py", line 1070, in render
    return render_value_in_context(output, context)
           ^^^^^^^^^^^^^^^^^^^^^^^^^^^^^^^^^^^^^^^^
  File "C:\Users\sunny\anaconda3\envs\myenv311test\Lib\site-packages\django\template\base.py", line 1047, in render_value_in_context
    value = str(value)
            ^^^^^^^^^^
  File "C:\Users\sunny\anaconda3\envs\myenv311test\Lib\site-packages\django\utils\html.py", line 420, in <lambda>
    klass.__str__ = lambda self: mark_safe(klass_str(self))
                                           ^^^^^^^^^^^^^^^
  File "C:\Users\sunny\anaconda3\envs\myenv311test\Lib\site-packages\django\forms\boundfield.py", line 34, in __str__
    return self.as_widget()
           ^^^^^^^^^^^^^^^^
  File "C:\Users\sunny\anaconda3\envs\myenv311test\Lib\site-packages\django\forms\boundfield.py", line 94, in as_widget
    attrs = self.build_widget_attrs(attrs, widget)
            ^^^^^^^^^^^^^^^^^^^^^^^^^^^^^^^^^^^^^^
  File "C:\Users\sunny\anaconda3\envs\myenv311test\Lib\site-packages\django\forms\boundfield.py", line 269, in build_widget_attrs
    widget.use_required_attribute(self.initial)
  File "C:\Users\sunny\anaconda3\envs\myenv311test\Lib\site-packages\django\forms\widgets.py", line 783, in use_required_attribute
    and self._choice_has_empty_value(first_choice)
        ^^^^^^^^^^^^^^^^^^^^^^^^^^^^^^^^^^^^^^^^^^
  File "C:\Users\sunny\anaconda3\envs\myenv311test\Lib\site-packages\django\forms\widgets.py", line 766, in _choice_has_empty_value
    value, _ = choice
    ^^^^^^^^
ValueError: too many values to unpack (expected 2)
2024-03-24 08:41:00,007 - INFO - Running job "run_procedure_sequence (trigger: interval[0:05:00], next run at: 2024-03-24 08:41:00 GMT)" (scheduled at 2024-03-24 08:41:00+00:00)
2024-03-24 08:41:00,008 - INFO - Inside the procedure sequence
2024-03-24 08:41:00,030 - INFO - Running job "run_procedure_sequence (trigger: interval[0:05:00], next run at: 2024-03-24 08:41:00 GMT)" (scheduled at 2024-03-24 08:41:00+00:00)
2024-03-24 08:41:00,030 - INFO - Inside the procedure sequence
2024-03-24 08:41:08,064 - INFO - Job "run_procedure_sequence (trigger: interval[0:05:00], next run at: 2024-03-24 08:46:00 GMT)" executed successfully
2024-03-24 08:41:08,371 - INFO - Job "run_procedure_sequence (trigger: interval[0:05:00], next run at: 2024-03-24 08:46:00 GMT)" executed successfully
2024-03-24 08:41:42,962 - INFO - C:\Users\sunny\Desktop\Development\python\TradePro\ml_models\views.py changed, reloading.
2024-03-24 08:41:49,252 - INFO - Starting scheduler
2024-03-24 08:41:49,252 - INFO - Updater date and time: 2024-03-24 08:41:49.252238
2024-03-24 08:41:49,252 - INFO - Adding job tentatively -- it will be properly scheduled when the scheduler starts
2024-03-24 08:41:49,252 - INFO - Added job "run_procedure_sequence" to job store "default"
2024-03-24 08:41:49,252 - INFO - Scheduler started
2024-03-24 08:41:49,252 - INFO - Ending scheduler
2024-03-24 08:41:51,120 - INFO - Starting scheduler
2024-03-24 08:41:51,121 - INFO - Updater date and time: 2024-03-24 08:41:51.121454
2024-03-24 08:41:51,122 - INFO - Adding job tentatively -- it will be properly scheduled when the scheduler starts
2024-03-24 08:41:51,122 - INFO - Added job "run_procedure_sequence" to job store "default"
2024-03-24 08:41:51,122 - INFO - Scheduler started
2024-03-24 08:41:51,123 - INFO - Ending scheduler
2024-03-24 08:41:51,140 - INFO - Watching for file changes with StatReloader
2024-03-24 08:42:08,476 - ERROR - Internal Server Error: /ml_models/ml-predictions/
Traceback (most recent call last):
  File "C:\Users\sunny\anaconda3\envs\myenv311test\Lib\site-packages\django\core\handlers\exception.py", line 55, in inner
    response = get_response(request)
               ^^^^^^^^^^^^^^^^^^^^^
  File "C:\Users\sunny\anaconda3\envs\myenv311test\Lib\site-packages\django\core\handlers\base.py", line 197, in _get_response
    response = wrapped_callback(request, *callback_args, **callback_kwargs)
               ^^^^^^^^^^^^^^^^^^^^^^^^^^^^^^^^^^^^^^^^^^^^^^^^^^^^^^^^^^^^
  File "C:\Users\sunny\Desktop\Development\python\TradePro\ml_models\views.py", line 100, in ml_predictions
    return render(request, 'ml_models/ml_predictions.html', context)
           ^^^^^^^^^^^^^^^^^^^^^^^^^^^^^^^^^^^^^^^^^^^^^^^^^^^^^^^^^
  File "C:\Users\sunny\anaconda3\envs\myenv311test\Lib\site-packages\django\shortcuts.py", line 24, in render
    content = loader.render_to_string(template_name, context, request, using=using)
              ^^^^^^^^^^^^^^^^^^^^^^^^^^^^^^^^^^^^^^^^^^^^^^^^^^^^^^^^^^^^^^^^^^^^^
  File "C:\Users\sunny\anaconda3\envs\myenv311test\Lib\site-packages\django\template\loader.py", line 62, in render_to_string
    return template.render(context, request)
           ^^^^^^^^^^^^^^^^^^^^^^^^^^^^^^^^^
  File "C:\Users\sunny\anaconda3\envs\myenv311test\Lib\site-packages\django\template\backends\django.py", line 61, in render
    return self.template.render(context)
           ^^^^^^^^^^^^^^^^^^^^^^^^^^^^^
  File "C:\Users\sunny\anaconda3\envs\myenv311test\Lib\site-packages\django\template\base.py", line 175, in render
    return self._render(context)
           ^^^^^^^^^^^^^^^^^^^^^
  File "C:\Users\sunny\anaconda3\envs\myenv311test\Lib\site-packages\django\template\base.py", line 167, in _render
    return self.nodelist.render(context)
           ^^^^^^^^^^^^^^^^^^^^^^^^^^^^^
  File "C:\Users\sunny\anaconda3\envs\myenv311test\Lib\site-packages\django\template\base.py", line 1005, in render
    return SafeString("".join([node.render_annotated(context) for node in self]))
                              ^^^^^^^^^^^^^^^^^^^^^^^^^^^^^^^^^^^^^^^^^^^^^^^^^
  File "C:\Users\sunny\anaconda3\envs\myenv311test\Lib\site-packages\django\template\base.py", line 1005, in <listcomp>
    return SafeString("".join([node.render_annotated(context) for node in self]))
                               ^^^^^^^^^^^^^^^^^^^^^^^^^^^^^^
  File "C:\Users\sunny\anaconda3\envs\myenv311test\Lib\site-packages\django\template\base.py", line 966, in render_annotated
    return self.render(context)
           ^^^^^^^^^^^^^^^^^^^^
  File "C:\Users\sunny\anaconda3\envs\myenv311test\Lib\site-packages\django\template\loader_tags.py", line 157, in render
    return compiled_parent._render(context)
           ^^^^^^^^^^^^^^^^^^^^^^^^^^^^^^^^
  File "C:\Users\sunny\anaconda3\envs\myenv311test\Lib\site-packages\django\template\base.py", line 167, in _render
    return self.nodelist.render(context)
           ^^^^^^^^^^^^^^^^^^^^^^^^^^^^^
  File "C:\Users\sunny\anaconda3\envs\myenv311test\Lib\site-packages\django\template\base.py", line 1005, in render
    return SafeString("".join([node.render_annotated(context) for node in self]))
                              ^^^^^^^^^^^^^^^^^^^^^^^^^^^^^^^^^^^^^^^^^^^^^^^^^
  File "C:\Users\sunny\anaconda3\envs\myenv311test\Lib\site-packages\django\template\base.py", line 1005, in <listcomp>
    return SafeString("".join([node.render_annotated(context) for node in self]))
                               ^^^^^^^^^^^^^^^^^^^^^^^^^^^^^^
  File "C:\Users\sunny\anaconda3\envs\myenv311test\Lib\site-packages\django\template\base.py", line 966, in render_annotated
    return self.render(context)
           ^^^^^^^^^^^^^^^^^^^^
  File "C:\Users\sunny\anaconda3\envs\myenv311test\Lib\site-packages\django\template\loader_tags.py", line 63, in render
    result = block.nodelist.render(context)
             ^^^^^^^^^^^^^^^^^^^^^^^^^^^^^^
  File "C:\Users\sunny\anaconda3\envs\myenv311test\Lib\site-packages\django\template\base.py", line 1005, in render
    return SafeString("".join([node.render_annotated(context) for node in self]))
                              ^^^^^^^^^^^^^^^^^^^^^^^^^^^^^^^^^^^^^^^^^^^^^^^^^
  File "C:\Users\sunny\anaconda3\envs\myenv311test\Lib\site-packages\django\template\base.py", line 1005, in <listcomp>
    return SafeString("".join([node.render_annotated(context) for node in self]))
                               ^^^^^^^^^^^^^^^^^^^^^^^^^^^^^^
  File "C:\Users\sunny\anaconda3\envs\myenv311test\Lib\site-packages\django\template\base.py", line 966, in render_annotated
    return self.render(context)
           ^^^^^^^^^^^^^^^^^^^^
  File "C:\Users\sunny\anaconda3\envs\myenv311test\Lib\site-packages\django\template\base.py", line 1064, in render
    output = self.filter_expression.resolve(context)
             ^^^^^^^^^^^^^^^^^^^^^^^^^^^^^^^^^^^^^^^
  File "C:\Users\sunny\anaconda3\envs\myenv311test\Lib\site-packages\django\template\base.py", line 715, in resolve
    obj = self.var.resolve(context)
          ^^^^^^^^^^^^^^^^^^^^^^^^^
  File "C:\Users\sunny\anaconda3\envs\myenv311test\Lib\site-packages\django\template\base.py", line 847, in resolve
    value = self._resolve_lookup(context)
            ^^^^^^^^^^^^^^^^^^^^^^^^^^^^^
  File "C:\Users\sunny\anaconda3\envs\myenv311test\Lib\site-packages\django\template\base.py", line 914, in _resolve_lookup
    current = current()
              ^^^^^^^^^
  File "C:\Users\sunny\anaconda3\envs\myenv311test\Lib\site-packages\django\forms\utils.py", line 84, in as_p
    return self.render(self.template_name_p)
           ^^^^^^^^^^^^^^^^^^^^^^^^^^^^^^^^^
  File "C:\Users\sunny\anaconda3\envs\myenv311test\Lib\site-packages\django\forms\utils.py", line 75, in render
    return mark_safe(renderer.render(template, context))
                     ^^^^^^^^^^^^^^^^^^^^^^^^^^^^^^^^^^
  File "C:\Users\sunny\anaconda3\envs\myenv311test\Lib\site-packages\django\forms\renderers.py", line 29, in render
    return template.render(context, request=request).strip()
           ^^^^^^^^^^^^^^^^^^^^^^^^^^^^^^^^^^^^^^^^^
  File "C:\Users\sunny\anaconda3\envs\myenv311test\Lib\site-packages\django\template\backends\django.py", line 61, in render
    return self.template.render(context)
           ^^^^^^^^^^^^^^^^^^^^^^^^^^^^^
  File "C:\Users\sunny\anaconda3\envs\myenv311test\Lib\site-packages\django\template\base.py", line 175, in render
    return self._render(context)
           ^^^^^^^^^^^^^^^^^^^^^
  File "C:\Users\sunny\anaconda3\envs\myenv311test\Lib\site-packages\django\template\base.py", line 167, in _render
    return self.nodelist.render(context)
           ^^^^^^^^^^^^^^^^^^^^^^^^^^^^^
  File "C:\Users\sunny\anaconda3\envs\myenv311test\Lib\site-packages\django\template\base.py", line 1005, in render
    return SafeString("".join([node.render_annotated(context) for node in self]))
                              ^^^^^^^^^^^^^^^^^^^^^^^^^^^^^^^^^^^^^^^^^^^^^^^^^
  File "C:\Users\sunny\anaconda3\envs\myenv311test\Lib\site-packages\django\template\base.py", line 1005, in <listcomp>
    return SafeString("".join([node.render_annotated(context) for node in self]))
                               ^^^^^^^^^^^^^^^^^^^^^^^^^^^^^^
  File "C:\Users\sunny\anaconda3\envs\myenv311test\Lib\site-packages\django\template\base.py", line 966, in render_annotated
    return self.render(context)
           ^^^^^^^^^^^^^^^^^^^^
  File "C:\Users\sunny\anaconda3\envs\myenv311test\Lib\site-packages\django\template\defaulttags.py", line 238, in render
    nodelist.append(node.render_annotated(context))
                    ^^^^^^^^^^^^^^^^^^^^^^^^^^^^^^
  File "C:\Users\sunny\anaconda3\envs\myenv311test\Lib\site-packages\django\template\base.py", line 966, in render_annotated
    return self.render(context)
           ^^^^^^^^^^^^^^^^^^^^
  File "C:\Users\sunny\anaconda3\envs\myenv311test\Lib\site-packages\django\template\base.py", line 1070, in render
    return render_value_in_context(output, context)
           ^^^^^^^^^^^^^^^^^^^^^^^^^^^^^^^^^^^^^^^^
  File "C:\Users\sunny\anaconda3\envs\myenv311test\Lib\site-packages\django\template\base.py", line 1047, in render_value_in_context
    value = str(value)
            ^^^^^^^^^^
  File "C:\Users\sunny\anaconda3\envs\myenv311test\Lib\site-packages\django\utils\html.py", line 420, in <lambda>
    klass.__str__ = lambda self: mark_safe(klass_str(self))
                                           ^^^^^^^^^^^^^^^
  File "C:\Users\sunny\anaconda3\envs\myenv311test\Lib\site-packages\django\forms\boundfield.py", line 34, in __str__
    return self.as_widget()
           ^^^^^^^^^^^^^^^^
  File "C:\Users\sunny\anaconda3\envs\myenv311test\Lib\site-packages\django\forms\boundfield.py", line 94, in as_widget
    attrs = self.build_widget_attrs(attrs, widget)
            ^^^^^^^^^^^^^^^^^^^^^^^^^^^^^^^^^^^^^^
  File "C:\Users\sunny\anaconda3\envs\myenv311test\Lib\site-packages\django\forms\boundfield.py", line 269, in build_widget_attrs
    widget.use_required_attribute(self.initial)
  File "C:\Users\sunny\anaconda3\envs\myenv311test\Lib\site-packages\django\forms\widgets.py", line 783, in use_required_attribute
    and self._choice_has_empty_value(first_choice)
        ^^^^^^^^^^^^^^^^^^^^^^^^^^^^^^^^^^^^^^^^^^
  File "C:\Users\sunny\anaconda3\envs\myenv311test\Lib\site-packages\django\forms\widgets.py", line 766, in _choice_has_empty_value
    value, _ = choice
    ^^^^^^^^
ValueError: too many values to unpack (expected 2)
2024-03-24 08:46:00,014 - INFO - Running job "run_procedure_sequence (trigger: interval[0:05:00], next run at: 2024-03-24 08:46:00 GMT)" (scheduled at 2024-03-24 08:46:00+00:00)
2024-03-24 08:46:00,014 - INFO - Inside the procedure sequence
2024-03-24 08:46:00,014 - INFO - Running job "run_procedure_sequence (trigger: interval[0:05:00], next run at: 2024-03-24 08:46:00 GMT)" (scheduled at 2024-03-24 08:46:00+00:00)
2024-03-24 08:46:00,015 - INFO - Inside the procedure sequence
2024-03-24 08:46:09,791 - INFO - Job "run_procedure_sequence (trigger: interval[0:05:00], next run at: 2024-03-24 08:51:00 GMT)" executed successfully
2024-03-24 08:46:09,846 - INFO - Job "run_procedure_sequence (trigger: interval[0:05:00], next run at: 2024-03-24 08:51:00 GMT)" executed successfully
2024-03-24 08:49:02,309 - INFO - Starting scheduler
2024-03-24 08:49:02,309 - INFO - Updater date and time: 2024-03-24 08:49:02.309260
2024-03-24 08:49:02,309 - INFO - Adding job tentatively -- it will be properly scheduled when the scheduler starts
2024-03-24 08:49:02,309 - INFO - Added job "run_procedure_sequence" to job store "default"
2024-03-24 08:49:02,309 - INFO - Scheduler started
2024-03-24 08:49:02,309 - INFO - Ending scheduler
2024-03-24 08:49:04,104 - INFO - Starting scheduler
2024-03-24 08:49:04,104 - INFO - Updater date and time: 2024-03-24 08:49:04.104500
2024-03-24 08:49:04,104 - INFO - Adding job tentatively -- it will be properly scheduled when the scheduler starts
2024-03-24 08:49:04,104 - INFO - Added job "run_procedure_sequence" to job store "default"
2024-03-24 08:49:04,104 - INFO - Scheduler started
2024-03-24 08:49:04,104 - INFO - Ending scheduler
2024-03-24 08:49:04,132 - INFO - Watching for file changes with StatReloader
2024-03-24 08:50:01,823 - WARNING - Not Found: /profile/images/favicon.ico
2024-03-24 08:50:02,541 - ERROR - Internal Server Error: /ml_models/ml-manual/
Traceback (most recent call last):
  File "C:\Users\sunny\anaconda3\envs\myenv311test\Lib\site-packages\django\core\handlers\exception.py", line 55, in inner
    response = get_response(request)
               ^^^^^^^^^^^^^^^^^^^^^
  File "C:\Users\sunny\anaconda3\envs\myenv311test\Lib\site-packages\django\core\handlers\base.py", line 197, in _get_response
    response = wrapped_callback(request, *callback_args, **callback_kwargs)
               ^^^^^^^^^^^^^^^^^^^^^^^^^^^^^^^^^^^^^^^^^^^^^^^^^^^^^^^^^^^^
  File "C:\Users\sunny\Desktop\Development\python\TradePro\ml_models\views.py", line 313, in ml_manual
    dp = v4Processing()
         ^^^^^^^^^^^^^^
TypeError: StandardPriceProcessing.__init__() missing 1 required positional argument: 'ticker'
2024-03-24 08:50:06,974 - ERROR - Internal Server Error: /ml_models/ml-report/
Traceback (most recent call last):
  File "C:\Users\sunny\anaconda3\envs\myenv311test\Lib\site-packages\django\core\handlers\exception.py", line 55, in inner
    response = get_response(request)
               ^^^^^^^^^^^^^^^^^^^^^
  File "C:\Users\sunny\anaconda3\envs\myenv311test\Lib\site-packages\django\core\handlers\base.py", line 197, in _get_response
    response = wrapped_callback(request, *callback_args, **callback_kwargs)
               ^^^^^^^^^^^^^^^^^^^^^^^^^^^^^^^^^^^^^^^^^^^^^^^^^^^^^^^^^^^^
  File "C:\Users\sunny\Desktop\Development\python\TradePro\ml_models\views.py", line 148, in ml_report
    dp = v4Processing()
         ^^^^^^^^^^^^^^
TypeError: StandardPriceProcessing.__init__() missing 1 required positional argument: 'ticker'
2024-03-24 08:51:00,008 - INFO - Running job "run_procedure_sequence (trigger: interval[0:05:00], next run at: 2024-03-24 08:51:00 GMT)" (scheduled at 2024-03-24 08:51:00+00:00)
2024-03-24 08:51:00,008 - INFO - Inside the procedure sequence
2024-03-24 08:51:00,013 - INFO - Running job "run_procedure_sequence (trigger: interval[0:05:00], next run at: 2024-03-24 08:51:00 GMT)" (scheduled at 2024-03-24 08:51:00+00:00)
2024-03-24 08:51:00,013 - INFO - Inside the procedure sequence
2024-03-24 08:51:00,592 - ERROR - Job "run_procedure_sequence (trigger: interval[0:05:00], next run at: 2024-03-24 08:56:00 GMT)" raised an exception
Traceback (most recent call last):
  File "C:\Users\sunny\anaconda3\envs\myenv311test\Lib\site-packages\apscheduler\executors\base.py", line 125, in run_job
    retval = job.func(*job.args, **job.kwargs)
             ^^^^^^^^^^^^^^^^^^^^^^^^^^^^^^^^^
  File "C:\Users\sunny\Desktop\Development\python\TradePro\prices\updater.py", line 59, in run_procedure_sequence
    run_IG(ticker)
  File "C:\Users\sunny\Desktop\Development\python\TradePro\prices\IG_session\run_IG.py", line 149, in run_IG
    ig_service.create_session()
  File "C:\Users\sunny\Desktop\Development\python\TradePro\prices\IG_session\ig_service.py", line 393, in create_session
    self._set_headers(response.headers, True)
  File "C:\Users\sunny\Desktop\Development\python\TradePro\prices\IG_session\ig_service.py", line 450, in _set_headers
    self.CLIENT_TOKEN = response_headers['CST']
                        ~~~~~~~~~~~~~~~~^^^^^^^
  File "C:\Users\sunny\anaconda3\envs\myenv311test\Lib\site-packages\requests\structures.py", line 52, in __getitem__
    return self._store[key.lower()][1]
           ~~~~~~~~~~~^^^^^^^^^^^^^
KeyError: 'cst'
2024-03-24 08:51:08,183 - INFO - Job "run_procedure_sequence (trigger: interval[0:05:00], next run at: 2024-03-24 08:56:00 GMT)" executed successfully
2024-03-24 08:54:32,535 - INFO - Starting scheduler
2024-03-24 08:54:32,535 - INFO - Updater date and time: 2024-03-24 08:54:32.535681
2024-03-24 08:54:32,535 - INFO - Adding job tentatively -- it will be properly scheduled when the scheduler starts
2024-03-24 08:54:32,535 - INFO - Added job "run_procedure_sequence" to job store "default"
2024-03-24 08:54:32,535 - INFO - Scheduler started
2024-03-24 08:54:32,551 - INFO - Ending scheduler
2024-03-24 08:54:34,446 - INFO - Starting scheduler
2024-03-24 08:54:34,446 - INFO - Updater date and time: 2024-03-24 08:54:34.446161
2024-03-24 08:54:34,446 - INFO - Adding job tentatively -- it will be properly scheduled when the scheduler starts
2024-03-24 08:54:34,446 - INFO - Added job "run_procedure_sequence" to job store "default"
2024-03-24 08:54:34,446 - INFO - Scheduler started
2024-03-24 08:54:34,446 - INFO - Ending scheduler
2024-03-24 08:54:34,473 - INFO - Watching for file changes with StatReloader
2024-03-24 08:54:38,743 - ERROR - Internal Server Error: /ml_models/ml-report/
Traceback (most recent call last):
  File "C:\Users\sunny\anaconda3\envs\myenv311test\Lib\site-packages\django\core\handlers\exception.py", line 55, in inner
    response = get_response(request)
               ^^^^^^^^^^^^^^^^^^^^^
  File "C:\Users\sunny\anaconda3\envs\myenv311test\Lib\site-packages\django\core\handlers\base.py", line 197, in _get_response
    response = wrapped_callback(request, *callback_args, **callback_kwargs)
               ^^^^^^^^^^^^^^^^^^^^^^^^^^^^^^^^^^^^^^^^^^^^^^^^^^^^^^^^^^^^
  File "C:\Users\sunny\Desktop\Development\python\TradePro\ml_models\views.py", line 283, in ml_report
    pred_var_pos, pred_var_neg = variability_analysis(model_ticker, 0.1)
                                 ^^^^^^^^^^^^^^^^^^^^^^^^^^^^^^^^^^^^^^^
  File "C:\Users\sunny\Desktop\Development\python\TradePro\ml_models\utils\predictive_analysis.py", line 379, in variability_analysis
    dp = v4Processing(ticker=ticker)
                             ^^^^^^
NameError: name 'ticker' is not defined
2024-03-24 08:55:35,511 - INFO - C:\Users\sunny\Desktop\Development\python\TradePro\ml_models\views.py changed, reloading.
2024-03-24 08:55:37,574 - INFO - Starting scheduler
2024-03-24 08:55:37,574 - INFO - Updater date and time: 2024-03-24 08:55:37.574921
2024-03-24 08:55:37,574 - INFO - Adding job tentatively -- it will be properly scheduled when the scheduler starts
2024-03-24 08:55:37,574 - INFO - Added job "run_procedure_sequence" to job store "default"
2024-03-24 08:55:37,574 - INFO - Scheduler started
2024-03-24 08:55:37,574 - INFO - Ending scheduler
2024-03-24 08:55:37,597 - INFO - Watching for file changes with StatReloader
2024-03-24 08:56:00,003 - INFO - Running job "run_procedure_sequence (trigger: interval[0:05:00], next run at: 2024-03-24 08:56:00 GMT)" (scheduled at 2024-03-24 08:56:00+00:00)
2024-03-24 08:56:00,003 - INFO - Inside the procedure sequence
2024-03-24 08:56:00,015 - INFO - Running job "run_procedure_sequence (trigger: interval[0:05:00], next run at: 2024-03-24 09:01:00 GMT)" (scheduled at 2024-03-24 08:56:00+00:00)
2024-03-24 08:56:00,016 - INFO - Inside the procedure sequence
2024-03-24 08:56:08,480 - INFO - Job "run_procedure_sequence (trigger: interval[0:05:00], next run at: 2024-03-24 09:01:00 GMT)" executed successfully
2024-03-24 08:56:08,885 - INFO - Job "run_procedure_sequence (trigger: interval[0:05:00], next run at: 2024-03-24 09:01:00 GMT)" executed successfully
2024-03-24 08:56:13,726 - ERROR - Internal Server Error: /ml_models/ml-report/
Traceback (most recent call last):
  File "C:\Users\sunny\anaconda3\envs\myenv311test\Lib\site-packages\django\core\handlers\exception.py", line 55, in inner
    response = get_response(request)
               ^^^^^^^^^^^^^^^^^^^^^
  File "C:\Users\sunny\anaconda3\envs\myenv311test\Lib\site-packages\django\core\handlers\base.py", line 197, in _get_response
    response = wrapped_callback(request, *callback_args, **callback_kwargs)
               ^^^^^^^^^^^^^^^^^^^^^^^^^^^^^^^^^^^^^^^^^^^^^^^^^^^^^^^^^^^^
  File "C:\Users\sunny\Desktop\Development\python\TradePro\ml_models\views.py", line 283, in ml_report
    pred_var_pos, pred_var_neg = variability_analysis(model_ticker, 0.1)
                                 ^^^^^^^^^^^^^^^^^^^^^^^^^^^^^^^^^^^^^^^
  File "C:\Users\sunny\Desktop\Development\python\TradePro\ml_models\utils\predictive_analysis.py", line 379, in variability_analysis
    dp = v4Processing(ticker=ticker)
                             ^^^^^^
NameError: name 'ticker' is not defined
2024-03-24 08:58:04,011 - INFO - C:\Users\sunny\Desktop\Development\python\TradePro\ml_models\form.py changed, reloading.
2024-03-24 08:58:40,607 - INFO - Starting scheduler
2024-03-24 08:58:40,607 - INFO - Updater date and time: 2024-03-24 08:58:40.607864
2024-03-24 08:58:40,611 - INFO - Adding job tentatively -- it will be properly scheduled when the scheduler starts
2024-03-24 08:58:40,611 - INFO - Added job "run_procedure_sequence" to job store "default"
2024-03-24 08:58:40,611 - INFO - Scheduler started
2024-03-24 08:58:40,611 - INFO - Ending scheduler
2024-03-24 08:58:42,426 - INFO - Starting scheduler
2024-03-24 08:58:42,426 - INFO - Updater date and time: 2024-03-24 08:58:42.426780
2024-03-24 08:58:42,427 - INFO - Adding job tentatively -- it will be properly scheduled when the scheduler starts
2024-03-24 08:58:42,427 - INFO - Added job "run_procedure_sequence" to job store "default"
2024-03-24 08:58:42,428 - INFO - Scheduler started
2024-03-24 08:58:42,429 - INFO - Ending scheduler
2024-03-24 08:58:42,445 - INFO - Watching for file changes with StatReloader
2024-03-24 08:58:47,691 - ERROR - Internal Server Error: /ml_models/ml-report/
Traceback (most recent call last):
  File "C:\Users\sunny\anaconda3\envs\myenv311test\Lib\site-packages\django\core\handlers\exception.py", line 55, in inner
    response = get_response(request)
               ^^^^^^^^^^^^^^^^^^^^^
  File "C:\Users\sunny\anaconda3\envs\myenv311test\Lib\site-packages\django\core\handlers\base.py", line 197, in _get_response
    response = wrapped_callback(request, *callback_args, **callback_kwargs)
               ^^^^^^^^^^^^^^^^^^^^^^^^^^^^^^^^^^^^^^^^^^^^^^^^^^^^^^^^^^^^
  File "C:\Users\sunny\Desktop\Development\python\TradePro\ml_models\views.py", line 283, in ml_report
    pred_var_pos, pred_var_neg = variability_analysis(model_ticker, 0.1)
                                 ^^^^^^^^^^^^^^^^^^^^^^^^^^^^^^^^^^^^^^^
  File "C:\Users\sunny\Desktop\Development\python\TradePro\ml_models\utils\predictive_analysis.py", line 379, in variability_analysis
    dp = v4Processing(ticker=ticker)
                             ^^^^^^
NameError: name 'ticker' is not defined
2024-03-24 09:01:00,004 - INFO - Running job "run_procedure_sequence (trigger: interval[0:05:00], next run at: 2024-03-24 09:01:00 GMT)" (scheduled at 2024-03-24 09:01:00+00:00)
2024-03-24 09:01:00,004 - INFO - Running job "run_procedure_sequence (trigger: interval[0:05:00], next run at: 2024-03-24 09:01:00 GMT)" (scheduled at 2024-03-24 09:01:00+00:00)
2024-03-24 09:01:00,004 - INFO - Inside the procedure sequence
2024-03-24 09:01:00,004 - INFO - Inside the procedure sequence
2024-03-24 09:01:08,004 - INFO - Job "run_procedure_sequence (trigger: interval[0:05:00], next run at: 2024-03-24 09:06:00 GMT)" executed successfully
2024-03-24 09:01:08,367 - INFO - Job "run_procedure_sequence (trigger: interval[0:05:00], next run at: 2024-03-24 09:06:00 GMT)" executed successfully
2024-03-24 09:01:30,565 - INFO - C:\Users\sunny\Desktop\Development\python\TradePro\ml_models\views.py changed, reloading.
2024-03-24 09:02:06,085 - INFO - Starting scheduler
2024-03-24 09:02:06,086 - INFO - Updater date and time: 2024-03-24 09:02:06.085701
2024-03-24 09:02:06,087 - INFO - Adding job tentatively -- it will be properly scheduled when the scheduler starts
2024-03-24 09:02:06,087 - INFO - Added job "run_procedure_sequence" to job store "default"
2024-03-24 09:02:06,087 - INFO - Scheduler started
2024-03-24 09:02:06,088 - INFO - Ending scheduler
2024-03-24 09:02:07,909 - INFO - Starting scheduler
2024-03-24 09:02:07,909 - INFO - Updater date and time: 2024-03-24 09:02:07.909799
2024-03-24 09:02:07,909 - INFO - Adding job tentatively -- it will be properly scheduled when the scheduler starts
2024-03-24 09:02:07,909 - INFO - Added job "run_procedure_sequence" to job store "default"
2024-03-24 09:02:07,909 - INFO - Scheduler started
2024-03-24 09:02:07,909 - INFO - Ending scheduler
2024-03-24 09:02:07,941 - INFO - Watching for file changes with StatReloader
2024-03-24 09:02:30,068 - ERROR - Internal Server Error: /ml_models/ml-report/
Traceback (most recent call last):
  File "C:\Users\sunny\anaconda3\envs\myenv311test\Lib\site-packages\django\core\handlers\exception.py", line 55, in inner
    response = get_response(request)
               ^^^^^^^^^^^^^^^^^^^^^
  File "C:\Users\sunny\anaconda3\envs\myenv311test\Lib\site-packages\django\core\handlers\base.py", line 197, in _get_response
    response = wrapped_callback(request, *callback_args, **callback_kwargs)
               ^^^^^^^^^^^^^^^^^^^^^^^^^^^^^^^^^^^^^^^^^^^^^^^^^^^^^^^^^^^^
  File "C:\Users\sunny\Desktop\Development\python\TradePro\ml_models\views.py", line 283, in ml_report
    pred_var_pos, pred_var_neg = variability_analysis(model_ticker, 0.1)
                                 ^^^^^^^^^^^^^^^^^^^^^^^^^^^^^^^^^^^^^^^
  File "C:\Users\sunny\Desktop\Development\python\TradePro\ml_models\utils\predictive_analysis.py", line 379, in variability_analysis
    dp = v4Processing(ticker=ticker)
                             ^^^^^^
NameError: name 'ticker' is not defined
2024-03-24 09:04:14,642 - INFO - Starting scheduler
2024-03-24 09:04:14,643 - INFO - Updater date and time: 2024-03-24 09:04:14.642327
2024-03-24 09:04:14,643 - INFO - Adding job tentatively -- it will be properly scheduled when the scheduler starts
2024-03-24 09:04:14,644 - INFO - Added job "run_procedure_sequence" to job store "default"
2024-03-24 09:04:14,644 - INFO - Scheduler started
2024-03-24 09:04:14,645 - INFO - Ending scheduler
2024-03-24 09:04:16,490 - INFO - Starting scheduler
2024-03-24 09:04:16,490 - INFO - Updater date and time: 2024-03-24 09:04:16.490508
2024-03-24 09:04:16,491 - INFO - Adding job tentatively -- it will be properly scheduled when the scheduler starts
2024-03-24 09:04:16,491 - INFO - Added job "run_procedure_sequence" to job store "default"
2024-03-24 09:04:16,492 - INFO - Scheduler started
2024-03-24 09:04:16,493 - INFO - Ending scheduler
2024-03-24 09:04:16,509 - INFO - Watching for file changes with StatReloader
2024-03-24 09:04:23,553 - ERROR - Internal Server Error: /ml_models/ml-report/
Traceback (most recent call last):
  File "C:\Users\sunny\anaconda3\envs\myenv311test\Lib\site-packages\django\core\handlers\exception.py", line 55, in inner
    response = get_response(request)
               ^^^^^^^^^^^^^^^^^^^^^
  File "C:\Users\sunny\anaconda3\envs\myenv311test\Lib\site-packages\django\core\handlers\base.py", line 197, in _get_response
    response = wrapped_callback(request, *callback_args, **callback_kwargs)
               ^^^^^^^^^^^^^^^^^^^^^^^^^^^^^^^^^^^^^^^^^^^^^^^^^^^^^^^^^^^^
  File "C:\Users\sunny\Desktop\Development\python\TradePro\ml_models\views.py", line 296, in ml_report
    'continue_labels': continue_labels, 'continue_trade_results': continue_trade_lists,"bb_status":bb_status}
                                                                                                   ^^^^^^^^^
NameError: name 'bb_status' is not defined
2024-03-24 09:05:01,214 - INFO - C:\Users\sunny\Desktop\Development\python\TradePro\ml_models\views.py changed, reloading.
2024-03-24 09:05:03,424 - INFO - Starting scheduler
2024-03-24 09:05:03,424 - INFO - Updater date and time: 2024-03-24 09:05:03.424488
2024-03-24 09:05:03,424 - INFO - Adding job tentatively -- it will be properly scheduled when the scheduler starts
2024-03-24 09:05:03,424 - INFO - Added job "run_procedure_sequence" to job store "default"
2024-03-24 09:05:03,424 - INFO - Scheduler started
2024-03-24 09:05:03,424 - INFO - Ending scheduler
2024-03-24 09:05:03,452 - INFO - Watching for file changes with StatReloader
2024-03-24 09:05:11,186 - WARNING - Not Found: /ml_models/ml-report/images/favicon.ico
2024-03-24 09:06:00,013 - INFO - Running job "run_procedure_sequence (trigger: interval[0:05:00], next run at: 2024-03-24 09:06:00 GMT)" (scheduled at 2024-03-24 09:06:00+00:00)
2024-03-24 09:06:00,014 - INFO - Inside the procedure sequence
2024-03-24 09:06:00,030 - INFO - Running job "run_procedure_sequence (trigger: interval[0:05:00], next run at: 2024-03-24 09:06:00 GMT)" (scheduled at 2024-03-24 09:06:00+00:00)
2024-03-24 09:06:00,030 - INFO - Inside the procedure sequence
2024-03-24 09:06:16,366 - INFO - Job "run_procedure_sequence (trigger: interval[0:05:00], next run at: 2024-03-24 09:11:00 GMT)" executed successfully
2024-03-24 09:06:26,153 - INFO - Job "run_procedure_sequence (trigger: interval[0:05:00], next run at: 2024-03-24 09:11:00 GMT)" executed successfully
2024-03-24 09:11:00,007 - INFO - Running job "run_procedure_sequence (trigger: interval[0:05:00], next run at: 2024-03-24 09:16:00 GMT)" (scheduled at 2024-03-24 09:11:00+00:00)
2024-03-24 09:11:00,007 - INFO - Inside the procedure sequence
2024-03-24 09:11:00,007 - INFO - Running job "run_procedure_sequence (trigger: interval[0:05:00], next run at: 2024-03-24 09:16:00 GMT)" (scheduled at 2024-03-24 09:11:00+00:00)
2024-03-24 09:11:00,007 - INFO - Inside the procedure sequence
2024-03-24 09:11:09,185 - INFO - Job "run_procedure_sequence (trigger: interval[0:05:00], next run at: 2024-03-24 09:16:00 GMT)" executed successfully
2024-03-24 09:11:09,324 - INFO - Job "run_procedure_sequence (trigger: interval[0:05:00], next run at: 2024-03-24 09:16:00 GMT)" executed successfully
2024-03-24 09:16:00,006 - INFO - Running job "run_procedure_sequence (trigger: interval[0:05:00], next run at: 2024-03-24 09:21:00 GMT)" (scheduled at 2024-03-24 09:16:00+00:00)
2024-03-24 09:16:00,006 - INFO - Inside the procedure sequence
2024-03-24 09:16:00,006 - INFO - Running job "run_procedure_sequence (trigger: interval[0:05:00], next run at: 2024-03-24 09:21:00 GMT)" (scheduled at 2024-03-24 09:16:00+00:00)
2024-03-24 09:16:00,007 - INFO - Inside the procedure sequence
2024-03-24 09:16:13,666 - INFO - Job "run_procedure_sequence (trigger: interval[0:05:00], next run at: 2024-03-24 09:21:00 GMT)" executed successfully
2024-03-24 09:16:13,992 - INFO - Job "run_procedure_sequence (trigger: interval[0:05:00], next run at: 2024-03-24 09:21:00 GMT)" executed successfully
2024-03-24 18:59:15,867 - INFO - Starting scheduler
2024-03-24 18:59:16,106 - INFO - Updater date and time: 2024-03-24 18:59:16.105149
2024-03-24 18:59:16,117 - INFO - Adding job tentatively -- it will be properly scheduled when the scheduler starts
2024-03-24 18:59:16,117 - INFO - Added job "run_procedure_sequence" to job store "default"
2024-03-24 18:59:16,117 - INFO - Scheduler started
2024-03-24 18:59:16,119 - INFO - Ending scheduler
2024-03-24 18:59:17,982 - INFO - Starting scheduler
2024-03-24 18:59:18,114 - INFO - Updater date and time: 2024-03-24 18:59:18.114847
2024-03-24 18:59:18,127 - INFO - Adding job tentatively -- it will be properly scheduled when the scheduler starts
2024-03-24 18:59:18,127 - INFO - Added job "run_procedure_sequence" to job store "default"
2024-03-24 18:59:18,127 - INFO - Scheduler started
2024-03-24 18:59:18,129 - INFO - Ending scheduler
2024-03-24 18:59:18,146 - INFO - Watching for file changes with StatReloader
2024-03-24 18:59:19,576 - WARNING - Not Found: /images/favicon.ico
2024-03-24 18:59:25,290 - WARNING - Not Found: /favicon.ico
2024-03-25 00:13:28,699 - INFO - Starting scheduler
2024-03-25 00:13:28,699 - INFO - Updater date and time: 2024-03-25 00:13:28.699606
2024-03-25 00:13:28,699 - INFO - Adding job tentatively -- it will be properly scheduled when the scheduler starts
2024-03-25 00:13:28,699 - INFO - Added job "run_procedure_sequence" to job store "default"
2024-03-25 00:13:28,699 - INFO - Scheduler started
2024-03-25 00:13:28,699 - INFO - Ending scheduler
2024-03-25 00:13:30,797 - INFO - Starting scheduler
2024-03-25 00:13:30,797 - INFO - Updater date and time: 2024-03-25 00:13:30.797385
2024-03-25 00:13:30,799 - INFO - Adding job tentatively -- it will be properly scheduled when the scheduler starts
2024-03-25 00:13:30,799 - INFO - Added job "run_procedure_sequence" to job store "default"
2024-03-25 00:13:30,799 - INFO - Scheduler started
2024-03-25 00:13:30,799 - INFO - Ending scheduler
2024-03-25 00:13:30,816 - INFO - Watching for file changes with StatReloader
2024-03-25 00:13:32,554 - WARNING - Not Found: /images/favicon.ico
2024-03-25 00:13:37,467 - WARNING - Not Found: /ml_models/ml-report/images/favicon.ico
2024-03-25 00:13:42,355 - WARNING - Not Found: /tickers/images/favicon.ico
2024-03-25 00:13:44,500 - WARNING - Not Found: /prices/get-IG-prices/images/favicon.ico
2024-03-25 00:15:16,929 - INFO - Starting scheduler
2024-03-25 00:15:16,932 - INFO - Updater date and time: 2024-03-25 00:15:16.931922
2024-03-25 00:15:16,933 - INFO - Adding job tentatively -- it will be properly scheduled when the scheduler starts
2024-03-25 00:15:16,933 - INFO - Added job "run_procedure_sequence" to job store "default"
2024-03-25 00:15:16,933 - INFO - Scheduler started
2024-03-25 00:15:16,935 - INFO - Ending scheduler
2024-03-25 00:15:17,938 - INFO - Running job "run_procedure_sequence (trigger: date[2024-03-25 00:15:17 GMT], next run at: 2024-03-25 00:15:17 GMT)" (scheduled at 2024-03-25 00:15:17.932241+00:00)
2024-03-25 00:15:17,938 - INFO - Removed job e5ce4c16c5374d0c8fda7c923e01df1a
2024-03-25 00:15:17,939 - INFO - Inside the procedure sequence
2024-03-25 00:15:18,517 - ERROR - Job "run_procedure_sequence (trigger: date[2024-03-25 00:15:17 GMT], next run at: 2024-03-25 00:15:17 GMT)" raised an exception
Traceback (most recent call last):
  File "C:\Users\sunny\anaconda3\envs\myenv311test\Lib\site-packages\apscheduler\executors\base.py", line 125, in run_job
    retval = job.func(*job.args, **job.kwargs)
             ^^^^^^^^^^^^^^^^^^^^^^^^^^^^^^^^^
  File "C:\Users\sunny\Desktop\Development\python\TradePro\prices\updater.py", line 60, in run_procedure_sequence
    run_IG(ticker)
  File "C:\Users\sunny\Desktop\Development\python\TradePro\prices\IG_session\run_IG.py", line 149, in run_IG
    ig_service.create_session()
  File "C:\Users\sunny\Desktop\Development\python\TradePro\prices\IG_session\ig_service.py", line 393, in create_session
    self._set_headers(response.headers, True)
  File "C:\Users\sunny\Desktop\Development\python\TradePro\prices\IG_session\ig_service.py", line 450, in _set_headers
    self.CLIENT_TOKEN = response_headers['CST']
                        ~~~~~~~~~~~~~~~~^^^^^^^
  File "C:\Users\sunny\anaconda3\envs\myenv311test\Lib\site-packages\requests\structures.py", line 52, in __getitem__
    return self._store[key.lower()][1]
           ~~~~~~~~~~~^^^^^^^^^^^^^
KeyError: 'cst'
2024-03-25 00:15:19,023 - INFO - Starting scheduler
2024-03-25 00:15:19,023 - INFO - Updater date and time: 2024-03-25 00:15:19.023853
2024-03-25 00:15:19,023 - INFO - Adding job tentatively -- it will be properly scheduled when the scheduler starts
2024-03-25 00:15:19,023 - INFO - Added job "run_procedure_sequence" to job store "default"
2024-03-25 00:15:19,023 - INFO - Scheduler started
2024-03-25 00:15:19,030 - INFO - Ending scheduler
2024-03-25 00:15:19,053 - INFO - Watching for file changes with StatReloader
2024-03-25 00:15:20,026 - INFO - Running job "run_procedure_sequence (trigger: date[2024-03-25 00:15:20 GMT], next run at: 2024-03-25 00:15:20 GMT)" (scheduled at 2024-03-25 00:15:20.023853+00:00)
2024-03-25 00:15:20,026 - INFO - Removed job 155cd0e145724abeaa8b3aea89d07c4e
2024-03-25 00:15:20,026 - INFO - Inside the procedure sequence
2024-03-25 00:15:20,617 - ERROR - Job "run_procedure_sequence (trigger: date[2024-03-25 00:15:20 GMT], next run at: 2024-03-25 00:15:20 GMT)" raised an exception
Traceback (most recent call last):
  File "C:\Users\sunny\anaconda3\envs\myenv311test\Lib\site-packages\apscheduler\executors\base.py", line 125, in run_job
    retval = job.func(*job.args, **job.kwargs)
             ^^^^^^^^^^^^^^^^^^^^^^^^^^^^^^^^^
  File "C:\Users\sunny\Desktop\Development\python\TradePro\prices\updater.py", line 60, in run_procedure_sequence
    run_IG(ticker)
  File "C:\Users\sunny\Desktop\Development\python\TradePro\prices\IG_session\run_IG.py", line 149, in run_IG
    ig_service.create_session()
  File "C:\Users\sunny\Desktop\Development\python\TradePro\prices\IG_session\ig_service.py", line 393, in create_session
    self._set_headers(response.headers, True)
  File "C:\Users\sunny\Desktop\Development\python\TradePro\prices\IG_session\ig_service.py", line 450, in _set_headers
    self.CLIENT_TOKEN = response_headers['CST']
                        ~~~~~~~~~~~~~~~~^^^^^^^
  File "C:\Users\sunny\anaconda3\envs\myenv311test\Lib\site-packages\requests\structures.py", line 52, in __getitem__
    return self._store[key.lower()][1]
           ~~~~~~~~~~~^^^^^^^^^^^^^
KeyError: 'cst'
2024-03-25 06:58:20,266 - INFO - Starting scheduler
2024-03-25 06:58:20,266 - INFO - Updater date and time: 2024-03-25 06:58:20.266366
2024-03-25 06:58:20,266 - INFO - Adding job tentatively -- it will be properly scheduled when the scheduler starts
2024-03-25 06:58:20,266 - INFO - Added job "run_procedure_sequence" to job store "default"
2024-03-25 06:58:20,266 - INFO - Scheduler started
2024-03-25 06:58:20,266 - INFO - Ending scheduler
2024-03-25 06:58:22,200 - INFO - Starting scheduler
2024-03-25 06:58:22,200 - INFO - Updater date and time: 2024-03-25 06:58:22.200320
2024-03-25 06:58:22,201 - INFO - Adding job tentatively -- it will be properly scheduled when the scheduler starts
2024-03-25 06:58:22,201 - INFO - Added job "run_procedure_sequence" to job store "default"
2024-03-25 06:58:22,201 - INFO - Scheduler started
2024-03-25 06:58:22,203 - INFO - Ending scheduler
2024-03-25 06:58:22,231 - INFO - Watching for file changes with StatReloader
2024-03-25 06:58:23,990 - WARNING - Not Found: /images/favicon.ico
2024-03-25 06:58:28,463 - WARNING - Not Found: /ml_models/ml-report/images/favicon.ico
2024-03-25 07:14:52,632 - INFO - Starting scheduler
2024-03-25 07:14:52,633 - INFO - Updater date and time: 2024-03-25 07:14:52.633329
2024-03-25 07:14:52,633 - INFO - Adding job tentatively -- it will be properly scheduled when the scheduler starts
2024-03-25 07:14:52,633 - INFO - Added job "run_procedure_sequence" to job store "default"
2024-03-25 07:14:52,633 - INFO - Scheduler started
2024-03-25 07:14:52,633 - INFO - Ending scheduler
2024-03-25 07:14:54,707 - INFO - Starting scheduler
2024-03-25 07:14:54,707 - INFO - Updater date and time: 2024-03-25 07:14:54.707371
2024-03-25 07:14:54,707 - INFO - Adding job tentatively -- it will be properly scheduled when the scheduler starts
2024-03-25 07:14:54,722 - INFO - Added job "run_procedure_sequence" to job store "default"
2024-03-25 07:14:54,722 - INFO - Scheduler started
2024-03-25 07:14:54,722 - INFO - Ending scheduler
2024-03-25 07:14:54,747 - INFO - Watching for file changes with StatReloader
